(base) tchaase@tobiaslegion:~$ docker run -it --rm -m 10gb --cpus="3" -v  /home/tchaase/Documents/Universitaet/Forschungsmodul/project/data/ds003707:/data:ro \
    -v /home/tchaase/Documents/Universitaet/Forschungsmodul/project/data/derivatives:/out -v /home/tchaase/Documents/Universitaet/Forschungsmodul/project/data/derivatives/workdir:/workdir  \
    -v  /home/tchaase/licenses/freesurfer/license.txt:/opt/freesurfer/license.txt nipreps/fmriprep:21.0.4  \
    /data /out participant --participant_label 01 --use-aroma  --ignore t2w --output-spaces MNI152NLin6Asym:res-2 T1w -w /workdir
You are using fMRIPrep-21.0.4, and a newer version of fMRIPrep is available: 22.0.2.
Please check out our documentation about how and when to upgrade:
https://fmriprep.readthedocs.io/en/latest/faq.html#upgrading
bids-validator@1.8.0

This dataset appears to be BIDS compatible.

        Summary:                Available Tasks:                      Available Modalities: 
        69 Files, 4.65GB        objects old new identification        MRI                   
        2 - Subjects            scenes old new identification                               
        1 - Session                                                                         


	If you have any questions, please post on https://neurostars.org/tags/bids.

221125-15:24:27,793 nipype.workflow IMPORTANT:
	 Running fMRIPrep version 21.0.4

         License NOTICE ##################################################
         fMRIPrep 21.0.4
         Copyright 2021 The NiPreps Developers.
         
         This product includes software developed by
         the NiPreps Community (https://nipreps.org/).
         
         Portions of this software were developed at the Department of
         Psychology at Stanford University, Stanford, CA, US.
         
         This software redistributes the versioneer Python package, which is
         Public domain source code.
         
         This software is also distributed as a Docker container image.
         The bootstraping file for the image ("Dockerfile") is licensed
         under the MIT License.
         
         This software may be distributed through an add-on package called
         "Docker Wrapper" that is under the BSD 3-clause License.
         #################################################################
221125-15:24:28,467 nipype.workflow IMPORTANT:
	 Building fMRIPrep's workflow:
           * BIDS dataset path: /data.
           * Participant list: ['01'].
           * Run identifier: 20221125-152416_68d48b50-bfdb-4a1f-b6df-c0321dd82fa8.
           * Output spaces: MNI152NLin6Asym:res-2 T1w.
           * Pre-run FreeSurfer's SUBJECTS_DIR: /out/sourcedata/freesurfer.
221125-15:24:29,922 nipype.workflow INFO:
	 B0 field inhomogeneity map will be estimated with  the following 1 estimators: [<EstimatorType.PEPOLAR: 2>].
221125-15:24:29,972 nipype.workflow INFO:
	 No single-band-reference found for sub-01_task-obj_run-02_bold.nii.gz.
221125-15:24:29,973 nipype.workflow INFO:
	 Found usable B0-map (fieldmap) estimator(s) <auto_00000> to correct </data/sub-01/func/sub-01_task-obj_run-02_bold.nii.gz> for susceptibility-derived distortions.
221125-15:24:30,63 nipype.workflow IMPORTANT:
	 BOLD series will be slice-timing corrected to an offset of 0.949s.
221125-15:24:30,208 nipype.workflow INFO:
	 No single-band-reference found for sub-01_task-obj_run-08_bold.nii.gz.
221125-15:24:30,208 nipype.workflow INFO:
	 Found usable B0-map (fieldmap) estimator(s) <auto_00000> to correct </data/sub-01/func/sub-01_task-obj_run-08_bold.nii.gz> for susceptibility-derived distortions.
221125-15:24:30,288 nipype.workflow IMPORTANT:
	 BOLD series will be slice-timing corrected to an offset of 0.949s.
221125-15:24:30,462 nipype.workflow INFO:
	 No single-band-reference found for sub-01_task-scene_run-01_bold.nii.gz.
221125-15:24:30,462 nipype.workflow INFO:
	 Found usable B0-map (fieldmap) estimator(s) <auto_00000> to correct </data/sub-01/func/sub-01_task-scene_run-01_bold.nii.gz> for susceptibility-derived distortions.
221125-15:24:30,539 nipype.workflow IMPORTANT:
	 BOLD series will be slice-timing corrected to an offset of 0.949s.
221125-15:24:30,653 nipype.workflow INFO:
	 No single-band-reference found for sub-01_task-scene_run-03_bold.nii.gz.
221125-15:24:30,653 nipype.workflow INFO:
	 Found usable B0-map (fieldmap) estimator(s) <auto_00000> to correct </data/sub-01/func/sub-01_task-scene_run-03_bold.nii.gz> for susceptibility-derived distortions.
221125-15:24:30,733 nipype.workflow IMPORTANT:
	 BOLD series will be slice-timing corrected to an offset of 0.949s.
221125-15:24:30,853 nipype.workflow INFO:
	 No single-band-reference found for sub-01_task-scene_run-04_bold.nii.gz.
221125-15:24:30,853 nipype.workflow INFO:
	 Found usable B0-map (fieldmap) estimator(s) <auto_00000> to correct </data/sub-01/func/sub-01_task-scene_run-04_bold.nii.gz> for susceptibility-derived distortions.
221125-15:24:30,929 nipype.workflow IMPORTANT:
	 BOLD series will be slice-timing corrected to an offset of 0.949s.
221125-15:24:31,44 nipype.workflow INFO:
	 No single-band-reference found for sub-01_task-scene_run-05_bold.nii.gz.
221125-15:24:31,44 nipype.workflow INFO:
	 Found usable B0-map (fieldmap) estimator(s) <auto_00000> to correct </data/sub-01/func/sub-01_task-scene_run-05_bold.nii.gz> for susceptibility-derived distortions.
221125-15:24:31,120 nipype.workflow IMPORTANT:
	 BOLD series will be slice-timing corrected to an offset of 0.949s.
221125-15:24:31,233 nipype.workflow INFO:
	 No single-band-reference found for sub-01_task-scene_run-06_bold.nii.gz.
221125-15:24:31,233 nipype.workflow INFO:
	 Found usable B0-map (fieldmap) estimator(s) <auto_00000> to correct </data/sub-01/func/sub-01_task-scene_run-06_bold.nii.gz> for susceptibility-derived distortions.
221125-15:24:31,369 nipype.workflow IMPORTANT:
	 BOLD series will be slice-timing corrected to an offset of 0.949s.
221125-15:24:31,483 nipype.workflow INFO:
	 No single-band-reference found for sub-01_task-scene_run-07_bold.nii.gz.
221125-15:24:31,483 nipype.workflow INFO:
	 Found usable B0-map (fieldmap) estimator(s) <auto_00000> to correct </data/sub-01/func/sub-01_task-scene_run-07_bold.nii.gz> for susceptibility-derived distortions.
221125-15:24:31,560 nipype.workflow IMPORTANT:
	 BOLD series will be slice-timing corrected to an offset of 0.949s.
221125-15:24:31,707 nipype.workflow INFO:
	 Setting-up fieldmap "auto_00000" (EstimatorType.PEPOLAR) with <sub-01_dir-AP_epi.nii.gz, sub-01_dir-PA_epi.nii.gz>
221125-15:24:34,545 nipype.workflow INFO:
	 fMRIPrep workflow graph with 2191 nodes built successfully.
221125-15:24:41,270 nipype.workflow IMPORTANT:
	 fMRIPrep started!
221125-15:24:42,896 nipype.workflow WARNING:
	 Some nodes exceed the total amount of memory available (13.82GB).
221125-15:24:52,17 nipype.workflow INFO:
	 [Node] Setting-up "fmriprep_wf.single_subject_01_wf.anat_preproc_wf.brain_extraction_wf.full_wm" in "/workdir/fmriprep_wf/single_subject_01_wf/anat_preproc_wf/brain_extraction_wf/full_wm".
221125-15:24:52,27 nipype.workflow INFO:
	 [Node] Running "full_wm" ("nipype.interfaces.utility.wrappers.Function")
221125-15:24:52,625 nipype.workflow INFO:
	 [Node] Setting-up "fmriprep_wf.single_subject_01_wf.func_preproc_task_obj_run_02_wf.bold_source" in "/workdir/fmriprep_wf/single_subject_01_wf/func_preproc_task_obj_run_02_wf/bold_source".
221125-15:24:52,723 nipype.workflow INFO:
	 [Node] Running "bold_source" ("nipype.interfaces.utility.base.Select")
221125-15:24:52,729 nipype.workflow INFO:
	 [Node] Setting-up "fmriprep_wf.single_subject_01_wf.func_preproc_task_obj_run_02_wf.func_derivatives_wf.raw_sources" in "/workdir/fmriprep_wf/single_subject_01_wf/func_preproc_task_obj_run_02_wf/func_derivatives_wf/raw_sources".
221125-15:24:52,819 nipype.workflow INFO:
	 [Node] Running "raw_sources" ("nipype.interfaces.utility.wrappers.Function")
221125-15:24:52,922 nipype.workflow INFO:
	 [Node] Finished "fmriprep_wf.single_subject_01_wf.func_preproc_task_obj_run_02_wf.bold_source".
221125-15:24:53,24 nipype.workflow INFO:
	 [Node] Finished "fmriprep_wf.single_subject_01_wf.func_preproc_task_obj_run_02_wf.func_derivatives_wf.raw_sources".
221125-15:24:53,25 nipype.workflow INFO:
	 [Node] Setting-up "fmriprep_wf.single_subject_01_wf.func_preproc_task_obj_run_08_wf.bold_source" in "/workdir/fmriprep_wf/single_subject_01_wf/func_preproc_task_obj_run_08_wf/bold_source".
221125-15:24:53,28 nipype.workflow INFO:
	 [Node] Setting-up "fmriprep_wf.single_subject_01_wf.func_preproc_task_obj_run_08_wf.func_derivatives_wf.raw_sources" in "/workdir/fmriprep_wf/single_subject_01_wf/func_preproc_task_obj_run_08_wf/func_derivatives_wf/raw_sources".
221125-15:24:53,30 nipype.workflow INFO:
	 [Node] Running "raw_sources" ("nipype.interfaces.utility.wrappers.Function")
221125-15:24:53,117 nipype.workflow INFO:
	 [Node] Running "bold_source" ("nipype.interfaces.utility.base.Select")
221125-15:24:53,121 nipype.workflow INFO:
	 [Node] Finished "fmriprep_wf.single_subject_01_wf.func_preproc_task_obj_run_08_wf.bold_source".
221125-15:24:53,126 nipype.workflow INFO:
	 [Node] Setting-up "fmriprep_wf.single_subject_01_wf.func_preproc_task_scene_run_01_wf.bold_source" in "/workdir/fmriprep_wf/single_subject_01_wf/func_preproc_task_scene_run_01_wf/bold_source".
221125-15:24:53,127 nipype.workflow INFO:
	 [Node] Running "bold_source" ("nipype.interfaces.utility.base.Select")
221125-15:24:53,235 nipype.workflow INFO:
	 [Node] Finished "fmriprep_wf.single_subject_01_wf.func_preproc_task_obj_run_08_wf.func_derivatives_wf.raw_sources".
221125-15:24:53,317 nipype.workflow INFO:
	 [Node] Setting-up "fmriprep_wf.single_subject_01_wf.func_preproc_task_scene_run_01_wf.func_derivatives_wf.raw_sources" in "/workdir/fmriprep_wf/single_subject_01_wf/func_preproc_task_scene_run_01_wf/func_derivatives_wf/raw_sources".
221125-15:24:53,319 nipype.workflow INFO:
	 [Node] Running "raw_sources" ("nipype.interfaces.utility.wrappers.Function")
221125-15:24:53,321 nipype.workflow INFO:
	 [Node] Finished "fmriprep_wf.single_subject_01_wf.func_preproc_task_scene_run_01_wf.func_derivatives_wf.raw_sources".
221125-15:24:53,322 nipype.workflow INFO:
	 [Node] Finished "fmriprep_wf.single_subject_01_wf.func_preproc_task_scene_run_01_wf.bold_source".
221125-15:24:53,423 nipype.workflow INFO:
	 [Node] Setting-up "fmriprep_wf.single_subject_01_wf.anat_preproc_wf.brain_extraction_wf.res_tmpl" in "/workdir/fmriprep_wf/single_subject_01_wf/anat_preproc_wf/brain_extraction_wf/res_tmpl".
221125-15:24:53,425 nipype.workflow INFO:
	 [Node] Running "res_tmpl" ("niworkflows.interfaces.nibabel.RegridToZooms")
221125-15:24:53,533 nipype.workflow INFO:
	 [Node] Setting-up "fmriprep_wf.single_subject_01_wf.anat_preproc_wf.brain_extraction_wf.lap_tmpl" in "/workdir/fmriprep_wf/single_subject_01_wf/anat_preproc_wf/brain_extraction_wf/lap_tmpl".
221125-15:24:53,620 nipype.workflow INFO:
	 [Node] Running "lap_tmpl" ("nipype.interfaces.ants.utils.ImageMath"), a CommandLine Interface with command:
ImageMath 3 tpl-OASIS30ANTs_res-01_T1w_maths.nii.gz Laplacian /home/fmriprep/.cache/templateflow/tpl-OASIS30ANTs/tpl-OASIS30ANTs_res-01_T1w.nii.gz 1.5 1
221125-15:24:53,824 nipype.workflow INFO:
	 [Node] Setting-up "fmriprep_wf.single_subject_01_wf.func_preproc_task_scene_run_03_wf.bold_source" in "/workdir/fmriprep_wf/single_subject_01_wf/func_preproc_task_scene_run_03_wf/bold_source".
221125-15:24:53,827 nipype.workflow INFO:
	 [Node] Running "bold_source" ("nipype.interfaces.utility.base.Select")
221125-15:24:54,22 nipype.workflow INFO:
	 [Node] Finished "fmriprep_wf.single_subject_01_wf.func_preproc_task_scene_run_03_wf.bold_source".
221125-15:24:54,24 nipype.workflow INFO:
	 [Node] Setting-up "fmriprep_wf.single_subject_01_wf.func_preproc_task_scene_run_03_wf.func_derivatives_wf.raw_sources" in "/workdir/fmriprep_wf/single_subject_01_wf/func_preproc_task_scene_run_03_wf/func_derivatives_wf/raw_sources".
221125-15:24:54,30 nipype.workflow INFO:
	 [Node] Running "raw_sources" ("nipype.interfaces.utility.wrappers.Function")
221125-15:24:54,120 nipype.workflow INFO:
	 [Node] Finished "fmriprep_wf.single_subject_01_wf.func_preproc_task_scene_run_03_wf.func_derivatives_wf.raw_sources".
221125-15:24:54,524 nipype.workflow INFO:
	 [Node] Setting-up "fmriprep_wf.single_subject_01_wf.func_preproc_task_obj_run_02_wf.initial_boldref_wf.val_bold" in "/workdir/fmriprep_wf/single_subject_01_wf/func_preproc_task_obj_run_02_wf/initial_boldref_wf/val_bold".
221125-15:24:54,527 nipype.workflow INFO:
	 [Node] Setting-up "_val_bold0" in "/workdir/fmriprep_wf/single_subject_01_wf/func_preproc_task_obj_run_02_wf/initial_boldref_wf/val_bold/mapflow/_val_bold0".
221125-15:24:54,528 nipype.workflow INFO:
	 [Node] Running "_val_bold0" ("niworkflows.interfaces.header.ValidateImage")
221125-15:24:54,622 nipype.workflow INFO:
	 [Node] Setting-up "fmriprep_wf.single_subject_01_wf.func_preproc_task_obj_run_08_wf.initial_boldref_wf.val_bold" in "/workdir/fmriprep_wf/single_subject_01_wf/func_preproc_task_obj_run_08_wf/initial_boldref_wf/val_bold".
221125-15:24:54,625 nipype.workflow INFO:
	 [Node] Setting-up "_val_bold0" in "/workdir/fmriprep_wf/single_subject_01_wf/func_preproc_task_obj_run_08_wf/initial_boldref_wf/val_bold/mapflow/_val_bold0".
221125-15:24:54,626 nipype.workflow INFO:
	 [Node] Running "_val_bold0" ("niworkflows.interfaces.header.ValidateImage")
221125-15:24:54,731 nipype.workflow INFO:
	 [Node] Setting-up "fmriprep_wf.single_subject_01_wf.func_preproc_task_scene_run_01_wf.initial_boldref_wf.val_bold" in "/workdir/fmriprep_wf/single_subject_01_wf/func_preproc_task_scene_run_01_wf/initial_boldref_wf/val_bold".
221125-15:24:54,731 nipype.workflow INFO:
	 [Node] Setting-up "fmriprep_wf.single_subject_01_wf.func_preproc_task_scene_run_01_wf.initial_boldref_wf.get_dummy" in "/workdir/fmriprep_wf/single_subject_01_wf/func_preproc_task_scene_run_01_wf/initial_boldref_wf/get_dummy".
221125-15:24:54,732 nipype.workflow INFO:
	 [Node] Running "get_dummy" ("niworkflows.interfaces.bold.NonsteadyStatesDetector")
221125-15:24:54,733 nipype.workflow INFO:
	 [Node] Setting-up "_val_bold0" in "/workdir/fmriprep_wf/single_subject_01_wf/func_preproc_task_scene_run_01_wf/initial_boldref_wf/val_bold/mapflow/_val_bold0".
221125-15:24:54,818 nipype.workflow INFO:
	 [Node] Running "_val_bold0" ("niworkflows.interfaces.header.ValidateImage")
221125-15:24:54,826 nipype.workflow INFO:
	 [Node] Setting-up "fmriprep_wf.single_subject_01_wf.func_preproc_task_obj_run_02_wf.initial_boldref_wf.get_dummy" in "/workdir/fmriprep_wf/single_subject_01_wf/func_preproc_task_obj_run_02_wf/initial_boldref_wf/get_dummy".
221125-15:24:54,826 nipype.workflow INFO:
	 [Node] Setting-up "fmriprep_wf.single_subject_01_wf.func_preproc_task_obj_run_08_wf.initial_boldref_wf.get_dummy" in "/workdir/fmriprep_wf/single_subject_01_wf/func_preproc_task_obj_run_08_wf/initial_boldref_wf/get_dummy".
221125-15:24:54,827 nipype.workflow INFO:
	 [Node] Running "get_dummy" ("niworkflows.interfaces.bold.NonsteadyStatesDetector")
221125-15:24:54,829 nipype.workflow INFO:
	 [Node] Running "get_dummy" ("niworkflows.interfaces.bold.NonsteadyStatesDetector")
221125-15:24:55,128 nipype.workflow INFO:
	 [Node] Setting-up "fmriprep_wf.single_subject_01_wf.func_preproc_task_scene_run_04_wf.bold_source" in "/workdir/fmriprep_wf/single_subject_01_wf/func_preproc_task_scene_run_04_wf/bold_source".
221125-15:24:55,130 nipype.workflow INFO:
	 [Node] Running "bold_source" ("nipype.interfaces.utility.base.Select")
221125-15:24:55,329 nipype.workflow INFO:
	 [Node] Finished "fmriprep_wf.single_subject_01_wf.func_preproc_task_scene_run_04_wf.bold_source".
221125-15:24:55,526 nipype.workflow INFO:
	 [Node] Setting-up "fmriprep_wf.single_subject_01_wf.func_preproc_task_scene_run_03_wf.initial_boldref_wf.val_bold" in "/workdir/fmriprep_wf/single_subject_01_wf/func_preproc_task_scene_run_03_wf/initial_boldref_wf/val_bold".
221125-15:24:55,529 nipype.workflow INFO:
	 [Node] Setting-up "_val_bold0" in "/workdir/fmriprep_wf/single_subject_01_wf/func_preproc_task_scene_run_03_wf/initial_boldref_wf/val_bold/mapflow/_val_bold0".
221125-15:24:55,618 nipype.workflow INFO:
	 [Node] Running "_val_bold0" ("niworkflows.interfaces.header.ValidateImage")
221125-15:24:56,32 nipype.workflow INFO:
	 [Node] Setting-up "fmriprep_wf.single_subject_01_wf.func_preproc_task_scene_run_03_wf.initial_boldref_wf.get_dummy" in "/workdir/fmriprep_wf/single_subject_01_wf/func_preproc_task_scene_run_03_wf/initial_boldref_wf/get_dummy".
221125-15:24:56,33 nipype.workflow INFO:
	 [Node] Running "get_dummy" ("niworkflows.interfaces.bold.NonsteadyStatesDetector")
221125-15:24:56,220 nipype.workflow INFO:
	 [Node] Finished "fmriprep_wf.single_subject_01_wf.anat_preproc_wf.brain_extraction_wf.full_wm".
221125-15:24:56,418 nipype.workflow INFO:
	 [Node] Setting-up "fmriprep_wf.single_subject_01_wf.func_preproc_task_scene_run_04_wf.func_derivatives_wf.raw_sources" in "/workdir/fmriprep_wf/single_subject_01_wf/func_preproc_task_scene_run_04_wf/func_derivatives_wf/raw_sources".
221125-15:24:56,420 nipype.workflow INFO:
	 [Node] Running "raw_sources" ("nipype.interfaces.utility.wrappers.Function")
221125-15:24:56,422 nipype.workflow INFO:
	 [Node] Finished "fmriprep_wf.single_subject_01_wf.func_preproc_task_scene_run_04_wf.func_derivatives_wf.raw_sources".
221125-15:24:56,423 nipype.workflow INFO:
	 [Node] Setting-up "fmriprep_wf.single_subject_01_wf.func_preproc_task_scene_run_05_wf.bold_source" in "/workdir/fmriprep_wf/single_subject_01_wf/func_preproc_task_scene_run_05_wf/bold_source".
221125-15:24:56,424 nipype.workflow INFO:
	 [Node] Setting-up "fmriprep_wf.single_subject_01_wf.func_preproc_task_scene_run_05_wf.func_derivatives_wf.raw_sources" in "/workdir/fmriprep_wf/single_subject_01_wf/func_preproc_task_scene_run_05_wf/func_derivatives_wf/raw_sources".
221125-15:24:56,425 nipype.workflow INFO:
	 [Node] Running "bold_source" ("nipype.interfaces.utility.base.Select")
221125-15:24:56,426 nipype.workflow INFO:
	 [Node] Running "raw_sources" ("nipype.interfaces.utility.wrappers.Function")
221125-15:24:56,428 nipype.workflow INFO:
	 [Node] Finished "fmriprep_wf.single_subject_01_wf.func_preproc_task_scene_run_05_wf.func_derivatives_wf.raw_sources".
221125-15:24:56,720 nipype.workflow INFO:
	 [Node] Finished "fmriprep_wf.single_subject_01_wf.func_preproc_task_scene_run_05_wf.bold_source".
221125-15:24:56,924 nipype.workflow INFO:
	 [Node] Setting-up "fmriprep_wf.single_subject_01_wf.func_preproc_task_scene_run_05_wf.initial_boldref_wf.get_dummy" in "/workdir/fmriprep_wf/single_subject_01_wf/func_preproc_task_scene_run_05_wf/initial_boldref_wf/get_dummy".
221125-15:24:56,926 nipype.workflow INFO:
	 [Node] Running "get_dummy" ("niworkflows.interfaces.bold.NonsteadyStatesDetector")
221125-15:24:57,320 nipype.workflow INFO:
	 [Node] Setting-up "fmriprep_wf.single_subject_01_wf.bidssrc" in "/workdir/fmriprep_wf/single_subject_01_wf/bidssrc".
221125-15:24:57,322 nipype.workflow INFO:
	 [Node] Running "bidssrc" ("niworkflows.interfaces.bids.BIDSDataGrabber")
221125-15:24:57,427 nipype.interface INFO:
	 No "t2w" images found for sub-01
221125-15:24:57,427 nipype.interface INFO:
	 No "flair" images found for sub-01
221125-15:24:57,427 nipype.interface INFO:
	 No "sbref" images found for sub-01
221125-15:24:57,427 nipype.interface INFO:
	 No "roi" images found for sub-01
221125-15:24:57,430 nipype.workflow INFO:
	 [Node] Finished "fmriprep_wf.single_subject_01_wf.bidssrc".
221125-15:24:57,619 nipype.workflow INFO:
	 [Node] Setting-up "fmriprep_wf.single_subject_01_wf.func_preproc_task_scene_run_05_wf.initial_boldref_wf.val_bold" in "/workdir/fmriprep_wf/single_subject_01_wf/func_preproc_task_scene_run_05_wf/initial_boldref_wf/val_bold".
221125-15:24:57,621 nipype.workflow INFO:
	 [Node] Setting-up "_val_bold0" in "/workdir/fmriprep_wf/single_subject_01_wf/func_preproc_task_scene_run_05_wf/initial_boldref_wf/val_bold/mapflow/_val_bold0".
221125-15:24:57,622 nipype.workflow INFO:
	 [Node] Running "_val_bold0" ("niworkflows.interfaces.header.ValidateImage")
221125-15:24:57,722 nipype.workflow INFO:
	 [Node] Setting-up "fmriprep_wf.single_subject_01_wf.func_preproc_task_scene_run_06_wf.bold_source" in "/workdir/fmriprep_wf/single_subject_01_wf/func_preproc_task_scene_run_06_wf/bold_source".
221125-15:24:57,723 nipype.workflow INFO:
	 [Node] Setting-up "fmriprep_wf.single_subject_01_wf.func_preproc_task_scene_run_06_wf.func_derivatives_wf.raw_sources" in "/workdir/fmriprep_wf/single_subject_01_wf/func_preproc_task_scene_run_06_wf/func_derivatives_wf/raw_sources".
221125-15:24:57,724 nipype.workflow INFO:
	 [Node] Running "bold_source" ("nipype.interfaces.utility.base.Select")
221125-15:24:57,724 nipype.workflow INFO:
	 [Node] Setting-up "fmriprep_wf.single_subject_01_wf.func_preproc_task_scene_run_04_wf.initial_boldref_wf.get_dummy" in "/workdir/fmriprep_wf/single_subject_01_wf/func_preproc_task_scene_run_04_wf/initial_boldref_wf/get_dummy".
221125-15:24:57,724 nipype.workflow INFO:
	 [Node] Running "raw_sources" ("nipype.interfaces.utility.wrappers.Function")
221125-15:24:57,725 nipype.workflow INFO:
	 [Node] Setting-up "fmriprep_wf.single_subject_01_wf.func_preproc_task_scene_run_07_wf.bold_source" in "/workdir/fmriprep_wf/single_subject_01_wf/func_preproc_task_scene_run_07_wf/bold_source".
221125-15:24:57,725 nipype.workflow INFO:
	 [Node] Running "get_dummy" ("niworkflows.interfaces.bold.NonsteadyStatesDetector")
221125-15:24:57,726 nipype.workflow INFO:
	 [Node] Running "bold_source" ("nipype.interfaces.utility.base.Select")
221125-15:24:57,831 nipype.workflow INFO:
	 [Node] Setting-up "fmriprep_wf.single_subject_01_wf.func_preproc_task_scene_run_04_wf.initial_boldref_wf.val_bold" in "/workdir/fmriprep_wf/single_subject_01_wf/func_preproc_task_scene_run_04_wf/initial_boldref_wf/val_bold".
221125-15:24:57,832 nipype.workflow INFO:
	 [Node] Finished "fmriprep_wf.single_subject_01_wf.func_preproc_task_scene_run_06_wf.func_derivatives_wf.raw_sources".
221125-15:24:57,834 nipype.workflow INFO:
	 [Node] Setting-up "_val_bold0" in "/workdir/fmriprep_wf/single_subject_01_wf/func_preproc_task_scene_run_04_wf/initial_boldref_wf/val_bold/mapflow/_val_bold0".
221125-15:24:57,835 nipype.workflow INFO:
	 [Node] Running "_val_bold0" ("niworkflows.interfaces.header.ValidateImage")
221125-15:24:57,921 nipype.workflow INFO:
	 [Node] Finished "fmriprep_wf.single_subject_01_wf.func_preproc_task_scene_run_07_wf.bold_source".
221125-15:24:57,922 nipype.workflow INFO:
	 [Node] Finished "fmriprep_wf.single_subject_01_wf.func_preproc_task_scene_run_06_wf.bold_source".
221125-15:24:58,922 nipype.workflow INFO:
	 [Node] Setting-up "fmriprep_wf.single_subject_01_wf.func_preproc_task_scene_run_06_wf.initial_boldref_wf.get_dummy" in "/workdir/fmriprep_wf/single_subject_01_wf/func_preproc_task_scene_run_06_wf/initial_boldref_wf/get_dummy".
221125-15:24:58,923 nipype.workflow INFO:
	 [Node] Running "get_dummy" ("niworkflows.interfaces.bold.NonsteadyStatesDetector")
221125-15:24:59,218 nipype.workflow INFO:
	 [Node] Setting-up "fmriprep_wf.single_subject_01_wf.func_preproc_task_scene_run_06_wf.initial_boldref_wf.val_bold" in "/workdir/fmriprep_wf/single_subject_01_wf/func_preproc_task_scene_run_06_wf/initial_boldref_wf/val_bold".
221125-15:24:59,221 nipype.workflow INFO:
	 [Node] Setting-up "_val_bold0" in "/workdir/fmriprep_wf/single_subject_01_wf/func_preproc_task_scene_run_06_wf/initial_boldref_wf/val_bold/mapflow/_val_bold0".
221125-15:24:59,222 nipype.workflow INFO:
	 [Node] Running "_val_bold0" ("niworkflows.interfaces.header.ValidateImage")
221125-15:24:59,728 nipype.workflow INFO:
	 [Node] Setting-up "fmriprep_wf.single_subject_01_wf.func_preproc_task_scene_run_07_wf.func_derivatives_wf.raw_sources" in "/workdir/fmriprep_wf/single_subject_01_wf/func_preproc_task_scene_run_07_wf/func_derivatives_wf/raw_sources".
221125-15:24:59,729 nipype.workflow INFO:
	 [Node] Running "raw_sources" ("nipype.interfaces.utility.wrappers.Function")
221125-15:24:59,730 nipype.workflow INFO:
	 [Node] Setting-up "fmriprep_wf.single_subject_01_wf.fmap_preproc_wf.out_merge_fmap_id" in "/workdir/fmriprep_wf/single_subject_01_wf/fmap_preproc_wf/out_merge_fmap_id".
221125-15:24:59,731 nipype.workflow INFO:
	 [Node] Finished "fmriprep_wf.single_subject_01_wf.func_preproc_task_scene_run_07_wf.func_derivatives_wf.raw_sources".
221125-15:24:59,732 nipype.workflow INFO:
	 [Node] Running "out_merge_fmap_id" ("nipype.interfaces.utility.base.Merge")
221125-15:24:59,734 nipype.workflow INFO:
	 [Node] Finished "fmriprep_wf.single_subject_01_wf.fmap_preproc_wf.out_merge_fmap_id".
221125-15:25:00,924 nipype.workflow INFO:
	 [Node] Setting-up "fmriprep_wf.single_subject_01_wf.func_preproc_task_scene_run_07_wf.initial_boldref_wf.val_bold" in "/workdir/fmriprep_wf/single_subject_01_wf/func_preproc_task_scene_run_07_wf/initial_boldref_wf/val_bold".
221125-15:25:00,926 nipype.workflow INFO:
	 [Node] Setting-up "_val_bold0" in "/workdir/fmriprep_wf/single_subject_01_wf/func_preproc_task_scene_run_07_wf/initial_boldref_wf/val_bold/mapflow/_val_bold0".
221125-15:25:00,927 nipype.workflow INFO:
	 [Node] Running "_val_bold0" ("niworkflows.interfaces.header.ValidateImage")
221125-15:25:01,23 nipype.workflow INFO:
	 [Node] Setting-up "fmriprep_wf.single_subject_01_wf.func_preproc_task_scene_run_07_wf.initial_boldref_wf.get_dummy" in "/workdir/fmriprep_wf/single_subject_01_wf/func_preproc_task_scene_run_07_wf/initial_boldref_wf/get_dummy".
221125-15:25:01,25 nipype.workflow INFO:
	 [Node] Running "get_dummy" ("niworkflows.interfaces.bold.NonsteadyStatesDetector")
221125-15:25:01,922 nipype.workflow INFO:
	 [Node] Setting-up "fmriprep_wf.single_subject_01_wf.fmap_preproc_wf.out_merge_method" in "/workdir/fmriprep_wf/single_subject_01_wf/fmap_preproc_wf/out_merge_method".
221125-15:25:01,924 nipype.workflow INFO:
	 [Node] Running "out_merge_method" ("nipype.interfaces.utility.base.Merge")
221125-15:25:01,926 nipype.workflow INFO:
	 [Node] Finished "fmriprep_wf.single_subject_01_wf.fmap_preproc_wf.out_merge_method".
221125-15:25:02,19 nipype.workflow INFO:
	 [Node] Finished "fmriprep_wf.single_subject_01_wf.anat_preproc_wf.brain_extraction_wf.res_tmpl".
221125-15:25:03,22 nipype.workflow INFO:
	 [Node] Setting-up "fmriprep_wf.single_subject_01_wf.fmap_preproc_wf.wf_auto_00000.flatten" in "/workdir/fmriprep_wf/single_subject_01_wf/fmap_preproc_wf/wf_auto_00000/flatten".
221125-15:25:03,30 nipype.workflow INFO:
	 [Node] Running "flatten" ("sdcflows.interfaces.utils.Flatten")
221125-15:25:03,318 nipype.workflow INFO:
	 [Node] Finished "fmriprep_wf.single_subject_01_wf.fmap_preproc_wf.wf_auto_00000.flatten".
exception calling callback for <Future at 0x7f36732ee640 state=finished raised BrokenProcessPool>
Traceback (most recent call last):
  File "/opt/conda/lib/python3.8/concurrent/futures/_base.py", line 328, in _invoke_callbacks
    callback(self)
  File "/opt/conda/lib/python3.8/site-packages/nipype/pipeline/plugins/multiproc.py", line 159, in _async_callback
    result = args.result()
  File "/opt/conda/lib/python3.8/concurrent/futures/_base.py", line 437, in result
    return self.__get_result()
  File "/opt/conda/lib/python3.8/concurrent/futures/_base.py", line 389, in __get_result
    raise self._exception
concurrent.futures.process.BrokenProcessPool: A process in the process pool was terminated abruptly while the future was running or pending.
exception calling callback for <Future at 0x7f3673267ca0 state=finished raised BrokenProcessPool>
Traceback (most recent call last):
  File "/opt/conda/lib/python3.8/concurrent/futures/_base.py", line 328, in _invoke_callbacks
    callback(self)
  File "/opt/conda/lib/python3.8/site-packages/nipype/pipeline/plugins/multiproc.py", line 159, in _async_callback
    result = args.result()
  File "/opt/conda/lib/python3.8/concurrent/futures/_base.py", line 437, in result
    return self.__get_result()
  File "/opt/conda/lib/python3.8/concurrent/futures/_base.py", line 389, in __get_result
    raise self._exception
  File "/opt/conda/lib/python3.8/concurrent/futures/_base.py", line 328, in _invoke_callbacks
    callback(self)
  File "/opt/conda/lib/python3.8/site-packages/nipype/pipeline/plugins/multiproc.py", line 159, in _async_callback
    result = args.result()
  File "/opt/conda/lib/python3.8/concurrent/futures/_base.py", line 437, in result
    return self.__get_result()
  File "/opt/conda/lib/python3.8/concurrent/futures/_base.py", line 389, in __get_result
    raise self._exception
concurrent.futures.process.BrokenProcessPool: A process in the process pool was terminated abruptly while the future was running or pending.
exception calling callback for <Future at 0x7f3673464310 state=finished raised BrokenProcessPool>
Traceback (most recent call last):
  File "/opt/conda/lib/python3.8/concurrent/futures/_base.py", line 328, in _invoke_callbacks
    callback(self)
  File "/opt/conda/lib/python3.8/site-packages/nipype/pipeline/plugins/multiproc.py", line 159, in _async_callback
    result = args.result()
  File "/opt/conda/lib/python3.8/concurrent/futures/_base.py", line 437, in result
    return self.__get_result()
  File "/opt/conda/lib/python3.8/concurrent/futures/_base.py", line 389, in __get_result
    raise self._exception
  File "/opt/conda/lib/python3.8/concurrent/futures/_base.py", line 328, in _invoke_callbacks
    callback(self)
  File "/opt/conda/lib/python3.8/site-packages/nipype/pipeline/plugins/multiproc.py", line 159, in _async_callback
    result = args.result()
  File "/opt/conda/lib/python3.8/concurrent/futures/_base.py", line 437, in result
    return self.__get_result()
  File "/opt/conda/lib/python3.8/concurrent/futures/_base.py", line 389, in __get_result
    raise self._exception
  File "/opt/conda/lib/python3.8/concurrent/futures/_base.py", line 328, in _invoke_callbacks
    callback(self)
  File "/opt/conda/lib/python3.8/site-packages/nipype/pipeline/plugins/multiproc.py", line 159, in _async_callback
    result = args.result()
  File "/opt/conda/lib/python3.8/concurrent/futures/_base.py", line 437, in result
    return self.__get_result()
  File "/opt/conda/lib/python3.8/concurrent/futures/_base.py", line 389, in __get_result
    raise self._exception
concurrent.futures.process.BrokenProcessPool: A process in the process pool was terminated abruptly while the future was running or pending.
exception calling callback for <Future at 0x7f3673267c10 state=finished raised BrokenProcessPool>
Traceback (most recent call last):
  File "/opt/conda/lib/python3.8/concurrent/futures/_base.py", line 328, in _invoke_callbacks
    callback(self)
  File "/opt/conda/lib/python3.8/site-packages/nipype/pipeline/plugins/multiproc.py", line 159, in _async_callback
    result = args.result()
  File "/opt/conda/lib/python3.8/concurrent/futures/_base.py", line 437, in result
    return self.__get_result()
  File "/opt/conda/lib/python3.8/concurrent/futures/_base.py", line 389, in __get_result
    raise self._exception
  File "/opt/conda/lib/python3.8/concurrent/futures/_base.py", line 328, in _invoke_callbacks
    callback(self)
  File "/opt/conda/lib/python3.8/site-packages/nipype/pipeline/plugins/multiproc.py", line 159, in _async_callback
    result = args.result()
  File "/opt/conda/lib/python3.8/concurrent/futures/_base.py", line 437, in result
    return self.__get_result()
  File "/opt/conda/lib/python3.8/concurrent/futures/_base.py", line 389, in __get_result
    raise self._exception
  File "/opt/conda/lib/python3.8/concurrent/futures/_base.py", line 328, in _invoke_callbacks
    callback(self)
  File "/opt/conda/lib/python3.8/site-packages/nipype/pipeline/plugins/multiproc.py", line 159, in _async_callback
    result = args.result()
  File "/opt/conda/lib/python3.8/concurrent/futures/_base.py", line 437, in result
    return self.__get_result()
  File "/opt/conda/lib/python3.8/concurrent/futures/_base.py", line 389, in __get_result
    raise self._exception
  File "/opt/conda/lib/python3.8/concurrent/futures/_base.py", line 328, in _invoke_callbacks
    callback(self)
  File "/opt/conda/lib/python3.8/site-packages/nipype/pipeline/plugins/multiproc.py", line 159, in _async_callback
    result = args.result()
  File "/opt/conda/lib/python3.8/concurrent/futures/_base.py", line 437, in result
    return self.__get_result()
  File "/opt/conda/lib/python3.8/concurrent/futures/_base.py", line 389, in __get_result
    raise self._exception
concurrent.futures.process.BrokenProcessPool: A process in the process pool was terminated abruptly while the future was running or pending.
exception calling callback for <Future at 0x7f367324ca30 state=finished raised BrokenProcessPool>
Traceback (most recent call last):
  File "/opt/conda/lib/python3.8/concurrent/futures/_base.py", line 328, in _invoke_callbacks
    callback(self)
  File "/opt/conda/lib/python3.8/site-packages/nipype/pipeline/plugins/multiproc.py", line 159, in _async_callback
    result = args.result()
  File "/opt/conda/lib/python3.8/concurrent/futures/_base.py", line 437, in result
    return self.__get_result()
  File "/opt/conda/lib/python3.8/concurrent/futures/_base.py", line 389, in __get_result
    raise self._exception
  File "/opt/conda/lib/python3.8/concurrent/futures/_base.py", line 328, in _invoke_callbacks
    callback(self)
  File "/opt/conda/lib/python3.8/site-packages/nipype/pipeline/plugins/multiproc.py", line 159, in _async_callback
    result = args.result()
  File "/opt/conda/lib/python3.8/concurrent/futures/_base.py", line 437, in result
    return self.__get_result()
  File "/opt/conda/lib/python3.8/concurrent/futures/_base.py", line 389, in __get_result
    raise self._exception
  File "/opt/conda/lib/python3.8/concurrent/futures/_base.py", line 328, in _invoke_callbacks
    callback(self)
  File "/opt/conda/lib/python3.8/site-packages/nipype/pipeline/plugins/multiproc.py", line 159, in _async_callback
    result = args.result()
  File "/opt/conda/lib/python3.8/concurrent/futures/_base.py", line 437, in result
    return self.__get_result()
  File "/opt/conda/lib/python3.8/concurrent/futures/_base.py", line 389, in __get_result
    raise self._exception
  File "/opt/conda/lib/python3.8/concurrent/futures/_base.py", line 328, in _invoke_callbacks
    callback(self)
  File "/opt/conda/lib/python3.8/site-packages/nipype/pipeline/plugins/multiproc.py", line 159, in _async_callback
    result = args.result()
  File "/opt/conda/lib/python3.8/concurrent/futures/_base.py", line 437, in result
    return self.__get_result()
  File "/opt/conda/lib/python3.8/concurrent/futures/_base.py", line 389, in __get_result
    raise self._exception
  File "/opt/conda/lib/python3.8/concurrent/futures/_base.py", line 328, in _invoke_callbacks
    callback(self)
  File "/opt/conda/lib/python3.8/site-packages/nipype/pipeline/plugins/multiproc.py", line 159, in _async_callback
    result = args.result()
  File "/opt/conda/lib/python3.8/concurrent/futures/_base.py", line 437, in result
    return self.__get_result()
  File "/opt/conda/lib/python3.8/concurrent/futures/_base.py", line 389, in __get_result
    raise self._exception
concurrent.futures.process.BrokenProcessPool: A process in the process pool was terminated abruptly while the future was running or pending.
exception calling callback for <Future at 0x7f36734fa8e0 state=finished raised BrokenProcessPool>
Traceback (most recent call last):
  File "/opt/conda/lib/python3.8/concurrent/futures/_base.py", line 328, in _invoke_callbacks
    callback(self)
  File "/opt/conda/lib/python3.8/site-packages/nipype/pipeline/plugins/multiproc.py", line 159, in _async_callback
    result = args.result()
  File "/opt/conda/lib/python3.8/concurrent/futures/_base.py", line 437, in result
    return self.__get_result()
  File "/opt/conda/lib/python3.8/concurrent/futures/_base.py", line 389, in __get_result
    raise self._exception
  File "/opt/conda/lib/python3.8/concurrent/futures/_base.py", line 328, in _invoke_callbacks
    callback(self)
  File "/opt/conda/lib/python3.8/site-packages/nipype/pipeline/plugins/multiproc.py", line 159, in _async_callback
    result = args.result()
  File "/opt/conda/lib/python3.8/concurrent/futures/_base.py", line 437, in result
    return self.__get_result()
  File "/opt/conda/lib/python3.8/concurrent/futures/_base.py", line 389, in __get_result
    raise self._exception
  File "/opt/conda/lib/python3.8/concurrent/futures/_base.py", line 328, in _invoke_callbacks
    callback(self)
  File "/opt/conda/lib/python3.8/site-packages/nipype/pipeline/plugins/multiproc.py", line 159, in _async_callback
    result = args.result()
  File "/opt/conda/lib/python3.8/concurrent/futures/_base.py", line 437, in result
    return self.__get_result()
  File "/opt/conda/lib/python3.8/concurrent/futures/_base.py", line 389, in __get_result
    raise self._exception
  File "/opt/conda/lib/python3.8/concurrent/futures/_base.py", line 328, in _invoke_callbacks
    callback(self)
  File "/opt/conda/lib/python3.8/site-packages/nipype/pipeline/plugins/multiproc.py", line 159, in _async_callback
    result = args.result()
  File "/opt/conda/lib/python3.8/concurrent/futures/_base.py", line 437, in result
    return self.__get_result()
  File "/opt/conda/lib/python3.8/concurrent/futures/_base.py", line 389, in __get_result
    raise self._exception
  File "/opt/conda/lib/python3.8/concurrent/futures/_base.py", line 328, in _invoke_callbacks
    callback(self)
  File "/opt/conda/lib/python3.8/site-packages/nipype/pipeline/plugins/multiproc.py", line 159, in _async_callback
    result = args.result()
  File "/opt/conda/lib/python3.8/concurrent/futures/_base.py", line 437, in result
    return self.__get_result()
  File "/opt/conda/lib/python3.8/concurrent/futures/_base.py", line 389, in __get_result
    raise self._exception
  File "/opt/conda/lib/python3.8/concurrent/futures/_base.py", line 328, in _invoke_callbacks
    callback(self)
  File "/opt/conda/lib/python3.8/site-packages/nipype/pipeline/plugins/multiproc.py", line 159, in _async_callback
    result = args.result()
  File "/opt/conda/lib/python3.8/concurrent/futures/_base.py", line 437, in result
    return self.__get_result()
  File "/opt/conda/lib/python3.8/concurrent/futures/_base.py", line 389, in __get_result
    raise self._exception
concurrent.futures.process.BrokenProcessPool: A process in the process pool was terminated abruptly while the future was running or pending.
exception calling callback for <Future at 0x7f3673348550 state=finished raised BrokenProcessPool>
Traceback (most recent call last):
  File "/opt/conda/lib/python3.8/concurrent/futures/_base.py", line 328, in _invoke_callbacks
    callback(self)
  File "/opt/conda/lib/python3.8/site-packages/nipype/pipeline/plugins/multiproc.py", line 159, in _async_callback
    result = args.result()
  File "/opt/conda/lib/python3.8/concurrent/futures/_base.py", line 437, in result
    return self.__get_result()
  File "/opt/conda/lib/python3.8/concurrent/futures/_base.py", line 389, in __get_result
    raise self._exception
  File "/opt/conda/lib/python3.8/concurrent/futures/_base.py", line 328, in _invoke_callbacks
    callback(self)
  File "/opt/conda/lib/python3.8/site-packages/nipype/pipeline/plugins/multiproc.py", line 159, in _async_callback
    result = args.result()
  File "/opt/conda/lib/python3.8/concurrent/futures/_base.py", line 437, in result
    return self.__get_result()
  File "/opt/conda/lib/python3.8/concurrent/futures/_base.py", line 389, in __get_result
    raise self._exception
  File "/opt/conda/lib/python3.8/concurrent/futures/_base.py", line 328, in _invoke_callbacks
    callback(self)
  File "/opt/conda/lib/python3.8/site-packages/nipype/pipeline/plugins/multiproc.py", line 159, in _async_callback
    result = args.result()
  File "/opt/conda/lib/python3.8/concurrent/futures/_base.py", line 437, in result
    return self.__get_result()
  File "/opt/conda/lib/python3.8/concurrent/futures/_base.py", line 389, in __get_result
    raise self._exception
  File "/opt/conda/lib/python3.8/concurrent/futures/_base.py", line 328, in _invoke_callbacks
    callback(self)
  File "/opt/conda/lib/python3.8/site-packages/nipype/pipeline/plugins/multiproc.py", line 159, in _async_callback
    result = args.result()
  File "/opt/conda/lib/python3.8/concurrent/futures/_base.py", line 437, in result
    return self.__get_result()
  File "/opt/conda/lib/python3.8/concurrent/futures/_base.py", line 389, in __get_result
    raise self._exception
  File "/opt/conda/lib/python3.8/concurrent/futures/_base.py", line 328, in _invoke_callbacks
    callback(self)
  File "/opt/conda/lib/python3.8/site-packages/nipype/pipeline/plugins/multiproc.py", line 159, in _async_callback
    result = args.result()
  File "/opt/conda/lib/python3.8/concurrent/futures/_base.py", line 437, in result
    return self.__get_result()
  File "/opt/conda/lib/python3.8/concurrent/futures/_base.py", line 389, in __get_result
    raise self._exception
  File "/opt/conda/lib/python3.8/concurrent/futures/_base.py", line 328, in _invoke_callbacks
    callback(self)
  File "/opt/conda/lib/python3.8/site-packages/nipype/pipeline/plugins/multiproc.py", line 159, in _async_callback
    result = args.result()
  File "/opt/conda/lib/python3.8/concurrent/futures/_base.py", line 437, in result
    return self.__get_result()
  File "/opt/conda/lib/python3.8/concurrent/futures/_base.py", line 389, in __get_result
    raise self._exception
  File "/opt/conda/lib/python3.8/concurrent/futures/_base.py", line 328, in _invoke_callbacks
    callback(self)
  File "/opt/conda/lib/python3.8/site-packages/nipype/pipeline/plugins/multiproc.py", line 159, in _async_callback
    result = args.result()
  File "/opt/conda/lib/python3.8/concurrent/futures/_base.py", line 437, in result
    return self.__get_result()
  File "/opt/conda/lib/python3.8/concurrent/futures/_base.py", line 389, in __get_result
    raise self._exception
concurrent.futures.process.BrokenProcessPool: A process in the process pool was terminated abruptly while the future was running or pending.
exception calling callback for <Future at 0x7f36734fa5e0 state=finished raised BrokenProcessPool>
Traceback (most recent call last):
  File "/opt/conda/lib/python3.8/concurrent/futures/_base.py", line 328, in _invoke_callbacks
    callback(self)
  File "/opt/conda/lib/python3.8/site-packages/nipype/pipeline/plugins/multiproc.py", line 159, in _async_callback
    result = args.result()
  File "/opt/conda/lib/python3.8/concurrent/futures/_base.py", line 437, in result
    return self.__get_result()
  File "/opt/conda/lib/python3.8/concurrent/futures/_base.py", line 389, in __get_result
    raise self._exception
  File "/opt/conda/lib/python3.8/concurrent/futures/_base.py", line 328, in _invoke_callbacks
    callback(self)
  File "/opt/conda/lib/python3.8/site-packages/nipype/pipeline/plugins/multiproc.py", line 159, in _async_callback
    result = args.result()
  File "/opt/conda/lib/python3.8/concurrent/futures/_base.py", line 437, in result
    return self.__get_result()
  File "/opt/conda/lib/python3.8/concurrent/futures/_base.py", line 389, in __get_result
    raise self._exception
  File "/opt/conda/lib/python3.8/concurrent/futures/_base.py", line 328, in _invoke_callbacks
    callback(self)
  File "/opt/conda/lib/python3.8/site-packages/nipype/pipeline/plugins/multiproc.py", line 159, in _async_callback
    result = args.result()
  File "/opt/conda/lib/python3.8/concurrent/futures/_base.py", line 437, in result
    return self.__get_result()
  File "/opt/conda/lib/python3.8/concurrent/futures/_base.py", line 389, in __get_result
    raise self._exception
  File "/opt/conda/lib/python3.8/concurrent/futures/_base.py", line 328, in _invoke_callbacks
    callback(self)
  File "/opt/conda/lib/python3.8/site-packages/nipype/pipeline/plugins/multiproc.py", line 159, in _async_callback
    result = args.result()
  File "/opt/conda/lib/python3.8/concurrent/futures/_base.py", line 437, in result
    return self.__get_result()
  File "/opt/conda/lib/python3.8/concurrent/futures/_base.py", line 389, in __get_result
    raise self._exception
  File "/opt/conda/lib/python3.8/concurrent/futures/_base.py", line 328, in _invoke_callbacks
    callback(self)
  File "/opt/conda/lib/python3.8/site-packages/nipype/pipeline/plugins/multiproc.py", line 159, in _async_callback
    result = args.result()
  File "/opt/conda/lib/python3.8/concurrent/futures/_base.py", line 437, in result
    return self.__get_result()
  File "/opt/conda/lib/python3.8/concurrent/futures/_base.py", line 389, in __get_result
    raise self._exception
  File "/opt/conda/lib/python3.8/concurrent/futures/_base.py", line 328, in _invoke_callbacks
    callback(self)
  File "/opt/conda/lib/python3.8/site-packages/nipype/pipeline/plugins/multiproc.py", line 159, in _async_callback
    result = args.result()
  File "/opt/conda/lib/python3.8/concurrent/futures/_base.py", line 437, in result
    return self.__get_result()
  File "/opt/conda/lib/python3.8/concurrent/futures/_base.py", line 389, in __get_result
    raise self._exception
  File "/opt/conda/lib/python3.8/concurrent/futures/_base.py", line 328, in _invoke_callbacks
    callback(self)
  File "/opt/conda/lib/python3.8/site-packages/nipype/pipeline/plugins/multiproc.py", line 159, in _async_callback
    result = args.result()
  File "/opt/conda/lib/python3.8/concurrent/futures/_base.py", line 437, in result
    return self.__get_result()
  File "/opt/conda/lib/python3.8/concurrent/futures/_base.py", line 389, in __get_result
    raise self._exception
  File "/opt/conda/lib/python3.8/concurrent/futures/_base.py", line 328, in _invoke_callbacks
    callback(self)
  File "/opt/conda/lib/python3.8/site-packages/nipype/pipeline/plugins/multiproc.py", line 159, in _async_callback
    result = args.result()
  File "/opt/conda/lib/python3.8/concurrent/futures/_base.py", line 437, in result
    return self.__get_result()
  File "/opt/conda/lib/python3.8/concurrent/futures/_base.py", line 389, in __get_result
    raise self._exception
concurrent.futures.process.BrokenProcessPool: A process in the process pool was terminated abruptly while the future was running or pending.
exception calling callback for <Future at 0x7f36731d3550 state=finished raised BrokenProcessPool>
Traceback (most recent call last):
  File "/opt/conda/lib/python3.8/concurrent/futures/_base.py", line 328, in _invoke_callbacks
    callback(self)
  File "/opt/conda/lib/python3.8/site-packages/nipype/pipeline/plugins/multiproc.py", line 159, in _async_callback
    result = args.result()
  File "/opt/conda/lib/python3.8/concurrent/futures/_base.py", line 437, in result
    return self.__get_result()
  File "/opt/conda/lib/python3.8/concurrent/futures/_base.py", line 389, in __get_result
    raise self._exception
  File "/opt/conda/lib/python3.8/concurrent/futures/_base.py", line 328, in _invoke_callbacks
    callback(self)
  File "/opt/conda/lib/python3.8/site-packages/nipype/pipeline/plugins/multiproc.py", line 159, in _async_callback
    result = args.result()
  File "/opt/conda/lib/python3.8/concurrent/futures/_base.py", line 437, in result
    return self.__get_result()
  File "/opt/conda/lib/python3.8/concurrent/futures/_base.py", line 389, in __get_result
    raise self._exception
  File "/opt/conda/lib/python3.8/concurrent/futures/_base.py", line 328, in _invoke_callbacks
    callback(self)
  File "/opt/conda/lib/python3.8/site-packages/nipype/pipeline/plugins/multiproc.py", line 159, in _async_callback
    result = args.result()
  File "/opt/conda/lib/python3.8/concurrent/futures/_base.py", line 437, in result
    return self.__get_result()
  File "/opt/conda/lib/python3.8/concurrent/futures/_base.py", line 389, in __get_result
    raise self._exception
  File "/opt/conda/lib/python3.8/concurrent/futures/_base.py", line 328, in _invoke_callbacks
    callback(self)
  File "/opt/conda/lib/python3.8/site-packages/nipype/pipeline/plugins/multiproc.py", line 159, in _async_callback
    result = args.result()
  File "/opt/conda/lib/python3.8/concurrent/futures/_base.py", line 437, in result
    return self.__get_result()
  File "/opt/conda/lib/python3.8/concurrent/futures/_base.py", line 389, in __get_result
    raise self._exception
  File "/opt/conda/lib/python3.8/concurrent/futures/_base.py", line 328, in _invoke_callbacks
    callback(self)
  File "/opt/conda/lib/python3.8/site-packages/nipype/pipeline/plugins/multiproc.py", line 159, in _async_callback
    result = args.result()
  File "/opt/conda/lib/python3.8/concurrent/futures/_base.py", line 437, in result
    return self.__get_result()
  File "/opt/conda/lib/python3.8/concurrent/futures/_base.py", line 389, in __get_result
    raise self._exception
  File "/opt/conda/lib/python3.8/concurrent/futures/_base.py", line 328, in _invoke_callbacks
    callback(self)
  File "/opt/conda/lib/python3.8/site-packages/nipype/pipeline/plugins/multiproc.py", line 159, in _async_callback
    result = args.result()
  File "/opt/conda/lib/python3.8/concurrent/futures/_base.py", line 437, in result
    return self.__get_result()
  File "/opt/conda/lib/python3.8/concurrent/futures/_base.py", line 389, in __get_result
    raise self._exception
  File "/opt/conda/lib/python3.8/concurrent/futures/_base.py", line 328, in _invoke_callbacks
    callback(self)
  File "/opt/conda/lib/python3.8/site-packages/nipype/pipeline/plugins/multiproc.py", line 159, in _async_callback
    result = args.result()
  File "/opt/conda/lib/python3.8/concurrent/futures/_base.py", line 437, in result
    return self.__get_result()
  File "/opt/conda/lib/python3.8/concurrent/futures/_base.py", line 389, in __get_result
    raise self._exception
  File "/opt/conda/lib/python3.8/concurrent/futures/_base.py", line 328, in _invoke_callbacks
    callback(self)
  File "/opt/conda/lib/python3.8/site-packages/nipype/pipeline/plugins/multiproc.py", line 159, in _async_callback
    result = args.result()
  File "/opt/conda/lib/python3.8/concurrent/futures/_base.py", line 437, in result
    return self.__get_result()
  File "/opt/conda/lib/python3.8/concurrent/futures/_base.py", line 389, in __get_result
    raise self._exception
  File "/opt/conda/lib/python3.8/concurrent/futures/_base.py", line 328, in _invoke_callbacks
    callback(self)
  File "/opt/conda/lib/python3.8/site-packages/nipype/pipeline/plugins/multiproc.py", line 159, in _async_callback
    result = args.result()
  File "/opt/conda/lib/python3.8/concurrent/futures/_base.py", line 437, in result
    return self.__get_result()
  File "/opt/conda/lib/python3.8/concurrent/futures/_base.py", line 389, in __get_result
    raise self._exception
concurrent.futures.process.BrokenProcessPool: A process in the process pool was terminated abruptly while the future was running or pending.
exception calling callback for <Future at 0x7f36733481f0 state=finished raised BrokenProcessPool>
Traceback (most recent call last):
  File "/opt/conda/lib/python3.8/concurrent/futures/_base.py", line 328, in _invoke_callbacks
    callback(self)
  File "/opt/conda/lib/python3.8/site-packages/nipype/pipeline/plugins/multiproc.py", line 159, in _async_callback
    result = args.result()
  File "/opt/conda/lib/python3.8/concurrent/futures/_base.py", line 437, in result
    return self.__get_result()
  File "/opt/conda/lib/python3.8/concurrent/futures/_base.py", line 389, in __get_result
    raise self._exception
  File "/opt/conda/lib/python3.8/concurrent/futures/_base.py", line 328, in _invoke_callbacks
    callback(self)
  File "/opt/conda/lib/python3.8/site-packages/nipype/pipeline/plugins/multiproc.py", line 159, in _async_callback
    result = args.result()
  File "/opt/conda/lib/python3.8/concurrent/futures/_base.py", line 437, in result
    return self.__get_result()
  File "/opt/conda/lib/python3.8/concurrent/futures/_base.py", line 389, in __get_result
    raise self._exception
  File "/opt/conda/lib/python3.8/concurrent/futures/_base.py", line 328, in _invoke_callbacks
    callback(self)
  File "/opt/conda/lib/python3.8/site-packages/nipype/pipeline/plugins/multiproc.py", line 159, in _async_callback
    result = args.result()
  File "/opt/conda/lib/python3.8/concurrent/futures/_base.py", line 437, in result
    return self.__get_result()
  File "/opt/conda/lib/python3.8/concurrent/futures/_base.py", line 389, in __get_result
    raise self._exception
  File "/opt/conda/lib/python3.8/concurrent/futures/_base.py", line 328, in _invoke_callbacks
    callback(self)
  File "/opt/conda/lib/python3.8/site-packages/nipype/pipeline/plugins/multiproc.py", line 159, in _async_callback
    result = args.result()
  File "/opt/conda/lib/python3.8/concurrent/futures/_base.py", line 437, in result
    return self.__get_result()
  File "/opt/conda/lib/python3.8/concurrent/futures/_base.py", line 389, in __get_result
    raise self._exception
  File "/opt/conda/lib/python3.8/concurrent/futures/_base.py", line 328, in _invoke_callbacks
    callback(self)
  File "/opt/conda/lib/python3.8/site-packages/nipype/pipeline/plugins/multiproc.py", line 159, in _async_callback
    result = args.result()
  File "/opt/conda/lib/python3.8/concurrent/futures/_base.py", line 437, in result
    return self.__get_result()
  File "/opt/conda/lib/python3.8/concurrent/futures/_base.py", line 389, in __get_result
    raise self._exception
  File "/opt/conda/lib/python3.8/concurrent/futures/_base.py", line 328, in _invoke_callbacks
    callback(self)
  File "/opt/conda/lib/python3.8/site-packages/nipype/pipeline/plugins/multiproc.py", line 159, in _async_callback
    result = args.result()
  File "/opt/conda/lib/python3.8/concurrent/futures/_base.py", line 437, in result
    return self.__get_result()
  File "/opt/conda/lib/python3.8/concurrent/futures/_base.py", line 389, in __get_result
    raise self._exception
  File "/opt/conda/lib/python3.8/concurrent/futures/_base.py", line 328, in _invoke_callbacks
    callback(self)
  File "/opt/conda/lib/python3.8/site-packages/nipype/pipeline/plugins/multiproc.py", line 159, in _async_callback
    result = args.result()
  File "/opt/conda/lib/python3.8/concurrent/futures/_base.py", line 437, in result
    return self.__get_result()
  File "/opt/conda/lib/python3.8/concurrent/futures/_base.py", line 389, in __get_result
    raise self._exception
  File "/opt/conda/lib/python3.8/concurrent/futures/_base.py", line 328, in _invoke_callbacks
    callback(self)
  File "/opt/conda/lib/python3.8/site-packages/nipype/pipeline/plugins/multiproc.py", line 159, in _async_callback
    result = args.result()
  File "/opt/conda/lib/python3.8/concurrent/futures/_base.py", line 437, in result
    return self.__get_result()
  File "/opt/conda/lib/python3.8/concurrent/futures/_base.py", line 389, in __get_result
    raise self._exception
  File "/opt/conda/lib/python3.8/concurrent/futures/_base.py", line 328, in _invoke_callbacks
    callback(self)
  File "/opt/conda/lib/python3.8/site-packages/nipype/pipeline/plugins/multiproc.py", line 159, in _async_callback
    result = args.result()
  File "/opt/conda/lib/python3.8/concurrent/futures/_base.py", line 437, in result
    return self.__get_result()
  File "/opt/conda/lib/python3.8/concurrent/futures/_base.py", line 389, in __get_result
    raise self._exception
  File "/opt/conda/lib/python3.8/concurrent/futures/_base.py", line 328, in _invoke_callbacks
    callback(self)
  File "/opt/conda/lib/python3.8/site-packages/nipype/pipeline/plugins/multiproc.py", line 159, in _async_callback
    result = args.result()
  File "/opt/conda/lib/python3.8/concurrent/futures/_base.py", line 437, in result
    return self.__get_result()
  File "/opt/conda/lib/python3.8/concurrent/futures/_base.py", line 389, in __get_result
    raise self._exception
concurrent.futures.process.BrokenProcessPool: A process in the process pool was terminated abruptly while the future was running or pending.
exception calling callback for <Future at 0x7f3673276850 state=finished raised BrokenProcessPool>
Traceback (most recent call last):
  File "/opt/conda/lib/python3.8/concurrent/futures/_base.py", line 328, in _invoke_callbacks
    callback(self)
  File "/opt/conda/lib/python3.8/site-packages/nipype/pipeline/plugins/multiproc.py", line 159, in _async_callback
    result = args.result()
  File "/opt/conda/lib/python3.8/concurrent/futures/_base.py", line 437, in result
    return self.__get_result()
  File "/opt/conda/lib/python3.8/concurrent/futures/_base.py", line 389, in __get_result
    raise self._exception
  File "/opt/conda/lib/python3.8/concurrent/futures/_base.py", line 328, in _invoke_callbacks
    callback(self)
  File "/opt/conda/lib/python3.8/site-packages/nipype/pipeline/plugins/multiproc.py", line 159, in _async_callback
    result = args.result()
  File "/opt/conda/lib/python3.8/concurrent/futures/_base.py", line 437, in result
    return self.__get_result()
  File "/opt/conda/lib/python3.8/concurrent/futures/_base.py", line 389, in __get_result
    raise self._exception
  File "/opt/conda/lib/python3.8/concurrent/futures/_base.py", line 328, in _invoke_callbacks
    callback(self)
  File "/opt/conda/lib/python3.8/site-packages/nipype/pipeline/plugins/multiproc.py", line 159, in _async_callback
    result = args.result()
  File "/opt/conda/lib/python3.8/concurrent/futures/_base.py", line 437, in result
    return self.__get_result()
  File "/opt/conda/lib/python3.8/concurrent/futures/_base.py", line 389, in __get_result
    raise self._exception
  File "/opt/conda/lib/python3.8/concurrent/futures/_base.py", line 328, in _invoke_callbacks
    callback(self)
  File "/opt/conda/lib/python3.8/site-packages/nipype/pipeline/plugins/multiproc.py", line 159, in _async_callback
    result = args.result()
  File "/opt/conda/lib/python3.8/concurrent/futures/_base.py", line 437, in result
    return self.__get_result()
  File "/opt/conda/lib/python3.8/concurrent/futures/_base.py", line 389, in __get_result
    raise self._exception
  File "/opt/conda/lib/python3.8/concurrent/futures/_base.py", line 328, in _invoke_callbacks
    callback(self)
  File "/opt/conda/lib/python3.8/site-packages/nipype/pipeline/plugins/multiproc.py", line 159, in _async_callback
    result = args.result()
  File "/opt/conda/lib/python3.8/concurrent/futures/_base.py", line 437, in result
    return self.__get_result()
  File "/opt/conda/lib/python3.8/concurrent/futures/_base.py", line 389, in __get_result
    raise self._exception
  File "/opt/conda/lib/python3.8/concurrent/futures/_base.py", line 328, in _invoke_callbacks
    callback(self)
  File "/opt/conda/lib/python3.8/site-packages/nipype/pipeline/plugins/multiproc.py", line 159, in _async_callback
    result = args.result()
  File "/opt/conda/lib/python3.8/concurrent/futures/_base.py", line 437, in result
    return self.__get_result()
  File "/opt/conda/lib/python3.8/concurrent/futures/_base.py", line 389, in __get_result
    raise self._exception
  File "/opt/conda/lib/python3.8/concurrent/futures/_base.py", line 328, in _invoke_callbacks
    callback(self)
  File "/opt/conda/lib/python3.8/site-packages/nipype/pipeline/plugins/multiproc.py", line 159, in _async_callback
    result = args.result()
  File "/opt/conda/lib/python3.8/concurrent/futures/_base.py", line 437, in result
    return self.__get_result()
  File "/opt/conda/lib/python3.8/concurrent/futures/_base.py", line 389, in __get_result
    raise self._exception
  File "/opt/conda/lib/python3.8/concurrent/futures/_base.py", line 328, in _invoke_callbacks
    callback(self)
  File "/opt/conda/lib/python3.8/site-packages/nipype/pipeline/plugins/multiproc.py", line 159, in _async_callback
    result = args.result()
  File "/opt/conda/lib/python3.8/concurrent/futures/_base.py", line 437, in result
    return self.__get_result()
  File "/opt/conda/lib/python3.8/concurrent/futures/_base.py", line 389, in __get_result
    raise self._exception
  File "/opt/conda/lib/python3.8/concurrent/futures/_base.py", line 328, in _invoke_callbacks
    callback(self)
  File "/opt/conda/lib/python3.8/site-packages/nipype/pipeline/plugins/multiproc.py", line 159, in _async_callback
    result = args.result()
  File "/opt/conda/lib/python3.8/concurrent/futures/_base.py", line 437, in result
    return self.__get_result()
  File "/opt/conda/lib/python3.8/concurrent/futures/_base.py", line 389, in __get_result
    raise self._exception
  File "/opt/conda/lib/python3.8/concurrent/futures/_base.py", line 328, in _invoke_callbacks
    callback(self)
  File "/opt/conda/lib/python3.8/site-packages/nipype/pipeline/plugins/multiproc.py", line 159, in _async_callback
    result = args.result()
  File "/opt/conda/lib/python3.8/concurrent/futures/_base.py", line 437, in result
    return self.__get_result()
  File "/opt/conda/lib/python3.8/concurrent/futures/_base.py", line 389, in __get_result
    raise self._exception
  File "/opt/conda/lib/python3.8/concurrent/futures/_base.py", line 328, in _invoke_callbacks
    callback(self)
  File "/opt/conda/lib/python3.8/site-packages/nipype/pipeline/plugins/multiproc.py", line 159, in _async_callback
    result = args.result()
  File "/opt/conda/lib/python3.8/concurrent/futures/_base.py", line 437, in result
    return self.__get_result()
  File "/opt/conda/lib/python3.8/concurrent/futures/_base.py", line 389, in __get_result
    raise self._exception
concurrent.futures.process.BrokenProcessPool: A process in the process pool was terminated abruptly while the future was running or pending.
exception calling callback for <Future at 0x7f3673276cd0 state=finished raised BrokenProcessPool>
Traceback (most recent call last):
  File "/opt/conda/lib/python3.8/concurrent/futures/_base.py", line 328, in _invoke_callbacks
    callback(self)
  File "/opt/conda/lib/python3.8/site-packages/nipype/pipeline/plugins/multiproc.py", line 159, in _async_callback
    result = args.result()
  File "/opt/conda/lib/python3.8/concurrent/futures/_base.py", line 437, in result
    return self.__get_result()
  File "/opt/conda/lib/python3.8/concurrent/futures/_base.py", line 389, in __get_result
    raise self._exception
  File "/opt/conda/lib/python3.8/concurrent/futures/_base.py", line 328, in _invoke_callbacks
    callback(self)
  File "/opt/conda/lib/python3.8/site-packages/nipype/pipeline/plugins/multiproc.py", line 159, in _async_callback
    result = args.result()
  File "/opt/conda/lib/python3.8/concurrent/futures/_base.py", line 437, in result
    return self.__get_result()
  File "/opt/conda/lib/python3.8/concurrent/futures/_base.py", line 389, in __get_result
    raise self._exception
  File "/opt/conda/lib/python3.8/concurrent/futures/_base.py", line 328, in _invoke_callbacks
    callback(self)
  File "/opt/conda/lib/python3.8/site-packages/nipype/pipeline/plugins/multiproc.py", line 159, in _async_callback
    result = args.result()
  File "/opt/conda/lib/python3.8/concurrent/futures/_base.py", line 437, in result
    return self.__get_result()
  File "/opt/conda/lib/python3.8/concurrent/futures/_base.py", line 389, in __get_result
    raise self._exception
  File "/opt/conda/lib/python3.8/concurrent/futures/_base.py", line 328, in _invoke_callbacks
    callback(self)
  File "/opt/conda/lib/python3.8/site-packages/nipype/pipeline/plugins/multiproc.py", line 159, in _async_callback
    result = args.result()
  File "/opt/conda/lib/python3.8/concurrent/futures/_base.py", line 437, in result
    return self.__get_result()
  File "/opt/conda/lib/python3.8/concurrent/futures/_base.py", line 389, in __get_result
    raise self._exception
  File "/opt/conda/lib/python3.8/concurrent/futures/_base.py", line 328, in _invoke_callbacks
    callback(self)
  File "/opt/conda/lib/python3.8/site-packages/nipype/pipeline/plugins/multiproc.py", line 159, in _async_callback
    result = args.result()
  File "/opt/conda/lib/python3.8/concurrent/futures/_base.py", line 437, in result
    return self.__get_result()
  File "/opt/conda/lib/python3.8/concurrent/futures/_base.py", line 389, in __get_result
    raise self._exception
  File "/opt/conda/lib/python3.8/concurrent/futures/_base.py", line 328, in _invoke_callbacks
    callback(self)
  File "/opt/conda/lib/python3.8/site-packages/nipype/pipeline/plugins/multiproc.py", line 159, in _async_callback
    result = args.result()
  File "/opt/conda/lib/python3.8/concurrent/futures/_base.py", line 437, in result
    return self.__get_result()
  File "/opt/conda/lib/python3.8/concurrent/futures/_base.py", line 389, in __get_result
    raise self._exception
  File "/opt/conda/lib/python3.8/concurrent/futures/_base.py", line 328, in _invoke_callbacks
    callback(self)
  File "/opt/conda/lib/python3.8/site-packages/nipype/pipeline/plugins/multiproc.py", line 159, in _async_callback
    result = args.result()
  File "/opt/conda/lib/python3.8/concurrent/futures/_base.py", line 437, in result
    return self.__get_result()
  File "/opt/conda/lib/python3.8/concurrent/futures/_base.py", line 389, in __get_result
    raise self._exception
  File "/opt/conda/lib/python3.8/concurrent/futures/_base.py", line 328, in _invoke_callbacks
    callback(self)
  File "/opt/conda/lib/python3.8/site-packages/nipype/pipeline/plugins/multiproc.py", line 159, in _async_callback
    result = args.result()
  File "/opt/conda/lib/python3.8/concurrent/futures/_base.py", line 437, in result
    return self.__get_result()
  File "/opt/conda/lib/python3.8/concurrent/futures/_base.py", line 389, in __get_result
    raise self._exception
  File "/opt/conda/lib/python3.8/concurrent/futures/_base.py", line 328, in _invoke_callbacks
    callback(self)
  File "/opt/conda/lib/python3.8/site-packages/nipype/pipeline/plugins/multiproc.py", line 159, in _async_callback
    result = args.result()
  File "/opt/conda/lib/python3.8/concurrent/futures/_base.py", line 437, in result
    return self.__get_result()
  File "/opt/conda/lib/python3.8/concurrent/futures/_base.py", line 389, in __get_result
    raise self._exception
  File "/opt/conda/lib/python3.8/concurrent/futures/_base.py", line 328, in _invoke_callbacks
    callback(self)
  File "/opt/conda/lib/python3.8/site-packages/nipype/pipeline/plugins/multiproc.py", line 159, in _async_callback
    result = args.result()
  File "/opt/conda/lib/python3.8/concurrent/futures/_base.py", line 437, in result
    return self.__get_result()
  File "/opt/conda/lib/python3.8/concurrent/futures/_base.py", line 389, in __get_result
    raise self._exception
  File "/opt/conda/lib/python3.8/concurrent/futures/_base.py", line 328, in _invoke_callbacks
    callback(self)
  File "/opt/conda/lib/python3.8/site-packages/nipype/pipeline/plugins/multiproc.py", line 159, in _async_callback
    result = args.result()
  File "/opt/conda/lib/python3.8/concurrent/futures/_base.py", line 437, in result
    return self.__get_result()
  File "/opt/conda/lib/python3.8/concurrent/futures/_base.py", line 389, in __get_result
    raise self._exception
  File "/opt/conda/lib/python3.8/concurrent/futures/_base.py", line 328, in _invoke_callbacks
    callback(self)
  File "/opt/conda/lib/python3.8/site-packages/nipype/pipeline/plugins/multiproc.py", line 159, in _async_callback
    result = args.result()
  File "/opt/conda/lib/python3.8/concurrent/futures/_base.py", line 437, in result
    return self.__get_result()
  File "/opt/conda/lib/python3.8/concurrent/futures/_base.py", line 389, in __get_result
    raise self._exception
concurrent.futures.process.BrokenProcessPool: A process in the process pool was terminated abruptly while the future was running or pending.
exception calling callback for <Future at 0x7f36733fe520 state=finished raised BrokenProcessPool>
Traceback (most recent call last):
  File "/opt/conda/lib/python3.8/concurrent/futures/_base.py", line 328, in _invoke_callbacks
    callback(self)
  File "/opt/conda/lib/python3.8/site-packages/nipype/pipeline/plugins/multiproc.py", line 159, in _async_callback
    result = args.result()
  File "/opt/conda/lib/python3.8/concurrent/futures/_base.py", line 437, in result
    return self.__get_result()
  File "/opt/conda/lib/python3.8/concurrent/futures/_base.py", line 389, in __get_result
    raise self._exception
  File "/opt/conda/lib/python3.8/concurrent/futures/_base.py", line 328, in _invoke_callbacks
    callback(self)
  File "/opt/conda/lib/python3.8/site-packages/nipype/pipeline/plugins/multiproc.py", line 159, in _async_callback
    result = args.result()
  File "/opt/conda/lib/python3.8/concurrent/futures/_base.py", line 437, in result
    return self.__get_result()
  File "/opt/conda/lib/python3.8/concurrent/futures/_base.py", line 389, in __get_result
    raise self._exception
  File "/opt/conda/lib/python3.8/concurrent/futures/_base.py", line 328, in _invoke_callbacks
    callback(self)
  File "/opt/conda/lib/python3.8/site-packages/nipype/pipeline/plugins/multiproc.py", line 159, in _async_callback
    result = args.result()
  File "/opt/conda/lib/python3.8/concurrent/futures/_base.py", line 437, in result
    return self.__get_result()
  File "/opt/conda/lib/python3.8/concurrent/futures/_base.py", line 389, in __get_result
    raise self._exception
  File "/opt/conda/lib/python3.8/concurrent/futures/_base.py", line 328, in _invoke_callbacks
    callback(self)
  File "/opt/conda/lib/python3.8/site-packages/nipype/pipeline/plugins/multiproc.py", line 159, in _async_callback
    result = args.result()
  File "/opt/conda/lib/python3.8/concurrent/futures/_base.py", line 437, in result
    return self.__get_result()
  File "/opt/conda/lib/python3.8/concurrent/futures/_base.py", line 389, in __get_result
    raise self._exception
  File "/opt/conda/lib/python3.8/concurrent/futures/_base.py", line 328, in _invoke_callbacks
    callback(self)
  File "/opt/conda/lib/python3.8/site-packages/nipype/pipeline/plugins/multiproc.py", line 159, in _async_callback
    result = args.result()
  File "/opt/conda/lib/python3.8/concurrent/futures/_base.py", line 437, in result
    return self.__get_result()
  File "/opt/conda/lib/python3.8/concurrent/futures/_base.py", line 389, in __get_result
    raise self._exception
  File "/opt/conda/lib/python3.8/concurrent/futures/_base.py", line 328, in _invoke_callbacks
    callback(self)
  File "/opt/conda/lib/python3.8/site-packages/nipype/pipeline/plugins/multiproc.py", line 159, in _async_callback
    result = args.result()
  File "/opt/conda/lib/python3.8/concurrent/futures/_base.py", line 437, in result
    return self.__get_result()
  File "/opt/conda/lib/python3.8/concurrent/futures/_base.py", line 389, in __get_result
    raise self._exception
  File "/opt/conda/lib/python3.8/concurrent/futures/_base.py", line 328, in _invoke_callbacks
    callback(self)
  File "/opt/conda/lib/python3.8/site-packages/nipype/pipeline/plugins/multiproc.py", line 159, in _async_callback
    result = args.result()
  File "/opt/conda/lib/python3.8/concurrent/futures/_base.py", line 437, in result
    return self.__get_result()
  File "/opt/conda/lib/python3.8/concurrent/futures/_base.py", line 389, in __get_result
    raise self._exception
  File "/opt/conda/lib/python3.8/concurrent/futures/_base.py", line 328, in _invoke_callbacks
    callback(self)
  File "/opt/conda/lib/python3.8/site-packages/nipype/pipeline/plugins/multiproc.py", line 159, in _async_callback
    result = args.result()
  File "/opt/conda/lib/python3.8/concurrent/futures/_base.py", line 437, in result
    return self.__get_result()
  File "/opt/conda/lib/python3.8/concurrent/futures/_base.py", line 389, in __get_result
    raise self._exception
  File "/opt/conda/lib/python3.8/concurrent/futures/_base.py", line 328, in _invoke_callbacks
    callback(self)
  File "/opt/conda/lib/python3.8/site-packages/nipype/pipeline/plugins/multiproc.py", line 159, in _async_callback
    result = args.result()
  File "/opt/conda/lib/python3.8/concurrent/futures/_base.py", line 437, in result
    return self.__get_result()
  File "/opt/conda/lib/python3.8/concurrent/futures/_base.py", line 389, in __get_result
    raise self._exception
  File "/opt/conda/lib/python3.8/concurrent/futures/_base.py", line 328, in _invoke_callbacks
    callback(self)
  File "/opt/conda/lib/python3.8/site-packages/nipype/pipeline/plugins/multiproc.py", line 159, in _async_callback
    result = args.result()
  File "/opt/conda/lib/python3.8/concurrent/futures/_base.py", line 437, in result
    return self.__get_result()
  File "/opt/conda/lib/python3.8/concurrent/futures/_base.py", line 389, in __get_result
    raise self._exception
  File "/opt/conda/lib/python3.8/concurrent/futures/_base.py", line 328, in _invoke_callbacks
    callback(self)
  File "/opt/conda/lib/python3.8/site-packages/nipype/pipeline/plugins/multiproc.py", line 159, in _async_callback
    result = args.result()
  File "/opt/conda/lib/python3.8/concurrent/futures/_base.py", line 437, in result
    return self.__get_result()
  File "/opt/conda/lib/python3.8/concurrent/futures/_base.py", line 389, in __get_result
    raise self._exception
  File "/opt/conda/lib/python3.8/concurrent/futures/_base.py", line 328, in _invoke_callbacks
    callback(self)
  File "/opt/conda/lib/python3.8/site-packages/nipype/pipeline/plugins/multiproc.py", line 159, in _async_callback
    result = args.result()
  File "/opt/conda/lib/python3.8/concurrent/futures/_base.py", line 437, in result
    return self.__get_result()
  File "/opt/conda/lib/python3.8/concurrent/futures/_base.py", line 389, in __get_result
    raise self._exception
  File "/opt/conda/lib/python3.8/concurrent/futures/_base.py", line 328, in _invoke_callbacks
    callback(self)
  File "/opt/conda/lib/python3.8/site-packages/nipype/pipeline/plugins/multiproc.py", line 159, in _async_callback
    result = args.result()
  File "/opt/conda/lib/python3.8/concurrent/futures/_base.py", line 437, in result
    return self.__get_result()
  File "/opt/conda/lib/python3.8/concurrent/futures/_base.py", line 389, in __get_result
    raise self._exception
concurrent.futures.process.BrokenProcessPool: A process in the process pool was terminated abruptly while the future was running or pending.
exception calling callback for <Future at 0x7f36734fa970 state=finished raised BrokenProcessPool>
Traceback (most recent call last):
  File "/opt/conda/lib/python3.8/concurrent/futures/_base.py", line 328, in _invoke_callbacks
    callback(self)
  File "/opt/conda/lib/python3.8/site-packages/nipype/pipeline/plugins/multiproc.py", line 159, in _async_callback
    result = args.result()
  File "/opt/conda/lib/python3.8/concurrent/futures/_base.py", line 437, in result
    return self.__get_result()
  File "/opt/conda/lib/python3.8/concurrent/futures/_base.py", line 389, in __get_result
    raise self._exception
  File "/opt/conda/lib/python3.8/concurrent/futures/_base.py", line 328, in _invoke_callbacks
    callback(self)
  File "/opt/conda/lib/python3.8/site-packages/nipype/pipeline/plugins/multiproc.py", line 159, in _async_callback
    result = args.result()
  File "/opt/conda/lib/python3.8/concurrent/futures/_base.py", line 437, in result
    return self.__get_result()
  File "/opt/conda/lib/python3.8/concurrent/futures/_base.py", line 389, in __get_result
    raise self._exception
  File "/opt/conda/lib/python3.8/concurrent/futures/_base.py", line 328, in _invoke_callbacks
    callback(self)
  File "/opt/conda/lib/python3.8/site-packages/nipype/pipeline/plugins/multiproc.py", line 159, in _async_callback
    result = args.result()
  File "/opt/conda/lib/python3.8/concurrent/futures/_base.py", line 437, in result
    return self.__get_result()
  File "/opt/conda/lib/python3.8/concurrent/futures/_base.py", line 389, in __get_result
    raise self._exception
  File "/opt/conda/lib/python3.8/concurrent/futures/_base.py", line 328, in _invoke_callbacks
    callback(self)
  File "/opt/conda/lib/python3.8/site-packages/nipype/pipeline/plugins/multiproc.py", line 159, in _async_callback
    result = args.result()
  File "/opt/conda/lib/python3.8/concurrent/futures/_base.py", line 437, in result
    return self.__get_result()
  File "/opt/conda/lib/python3.8/concurrent/futures/_base.py", line 389, in __get_result
    raise self._exception
  File "/opt/conda/lib/python3.8/concurrent/futures/_base.py", line 328, in _invoke_callbacks
    callback(self)
  File "/opt/conda/lib/python3.8/site-packages/nipype/pipeline/plugins/multiproc.py", line 159, in _async_callback
    result = args.result()
  File "/opt/conda/lib/python3.8/concurrent/futures/_base.py", line 437, in result
    return self.__get_result()
  File "/opt/conda/lib/python3.8/concurrent/futures/_base.py", line 389, in __get_result
    raise self._exception
  File "/opt/conda/lib/python3.8/concurrent/futures/_base.py", line 328, in _invoke_callbacks
    callback(self)
  File "/opt/conda/lib/python3.8/site-packages/nipype/pipeline/plugins/multiproc.py", line 159, in _async_callback
    result = args.result()
  File "/opt/conda/lib/python3.8/concurrent/futures/_base.py", line 437, in result
    return self.__get_result()
  File "/opt/conda/lib/python3.8/concurrent/futures/_base.py", line 389, in __get_result
    raise self._exception
  File "/opt/conda/lib/python3.8/concurrent/futures/_base.py", line 328, in _invoke_callbacks
    callback(self)
  File "/opt/conda/lib/python3.8/site-packages/nipype/pipeline/plugins/multiproc.py", line 159, in _async_callback
    result = args.result()
  File "/opt/conda/lib/python3.8/concurrent/futures/_base.py", line 437, in result
    return self.__get_result()
  File "/opt/conda/lib/python3.8/concurrent/futures/_base.py", line 389, in __get_result
    raise self._exception
  File "/opt/conda/lib/python3.8/concurrent/futures/_base.py", line 328, in _invoke_callbacks
    callback(self)
  File "/opt/conda/lib/python3.8/site-packages/nipype/pipeline/plugins/multiproc.py", line 159, in _async_callback
    result = args.result()
  File "/opt/conda/lib/python3.8/concurrent/futures/_base.py", line 437, in result
    return self.__get_result()
  File "/opt/conda/lib/python3.8/concurrent/futures/_base.py", line 389, in __get_result
    raise self._exception
  File "/opt/conda/lib/python3.8/concurrent/futures/_base.py", line 328, in _invoke_callbacks
    callback(self)
  File "/opt/conda/lib/python3.8/site-packages/nipype/pipeline/plugins/multiproc.py", line 159, in _async_callback
    result = args.result()
  File "/opt/conda/lib/python3.8/concurrent/futures/_base.py", line 437, in result
    return self.__get_result()
  File "/opt/conda/lib/python3.8/concurrent/futures/_base.py", line 389, in __get_result
    raise self._exception
  File "/opt/conda/lib/python3.8/concurrent/futures/_base.py", line 328, in _invoke_callbacks
    callback(self)
  File "/opt/conda/lib/python3.8/site-packages/nipype/pipeline/plugins/multiproc.py", line 159, in _async_callback
    result = args.result()
  File "/opt/conda/lib/python3.8/concurrent/futures/_base.py", line 437, in result
    return self.__get_result()
  File "/opt/conda/lib/python3.8/concurrent/futures/_base.py", line 389, in __get_result
    raise self._exception
  File "/opt/conda/lib/python3.8/concurrent/futures/_base.py", line 328, in _invoke_callbacks
    callback(self)
  File "/opt/conda/lib/python3.8/site-packages/nipype/pipeline/plugins/multiproc.py", line 159, in _async_callback
    result = args.result()
  File "/opt/conda/lib/python3.8/concurrent/futures/_base.py", line 437, in result
    return self.__get_result()
  File "/opt/conda/lib/python3.8/concurrent/futures/_base.py", line 389, in __get_result
    raise self._exception
  File "/opt/conda/lib/python3.8/concurrent/futures/_base.py", line 328, in _invoke_callbacks
    callback(self)
  File "/opt/conda/lib/python3.8/site-packages/nipype/pipeline/plugins/multiproc.py", line 159, in _async_callback
    result = args.result()
  File "/opt/conda/lib/python3.8/concurrent/futures/_base.py", line 437, in result
    return self.__get_result()
  File "/opt/conda/lib/python3.8/concurrent/futures/_base.py", line 389, in __get_result
    raise self._exception
  File "/opt/conda/lib/python3.8/concurrent/futures/_base.py", line 328, in _invoke_callbacks
    callback(self)
  File "/opt/conda/lib/python3.8/site-packages/nipype/pipeline/plugins/multiproc.py", line 159, in _async_callback
    result = args.result()
  File "/opt/conda/lib/python3.8/concurrent/futures/_base.py", line 437, in result
    return self.__get_result()
  File "/opt/conda/lib/python3.8/concurrent/futures/_base.py", line 389, in __get_result
    raise self._exception
  File "/opt/conda/lib/python3.8/concurrent/futures/_base.py", line 328, in _invoke_callbacks
    callback(self)
  File "/opt/conda/lib/python3.8/site-packages/nipype/pipeline/plugins/multiproc.py", line 159, in _async_callback
    result = args.result()
  File "/opt/conda/lib/python3.8/concurrent/futures/_base.py", line 437, in result
    return self.__get_result()
  File "/opt/conda/lib/python3.8/concurrent/futures/_base.py", line 389, in __get_result
    raise self._exception
concurrent.futures.process.BrokenProcessPool: A process in the process pool was terminated abruptly while the future was running or pending.
exception calling callback for <Future at 0x7f367324c9a0 state=finished raised BrokenProcessPool>
Traceback (most recent call last):
  File "/opt/conda/lib/python3.8/concurrent/futures/_base.py", line 328, in _invoke_callbacks
    callback(self)
  File "/opt/conda/lib/python3.8/site-packages/nipype/pipeline/plugins/multiproc.py", line 159, in _async_callback
    result = args.result()
  File "/opt/conda/lib/python3.8/concurrent/futures/_base.py", line 437, in result
    return self.__get_result()
  File "/opt/conda/lib/python3.8/concurrent/futures/_base.py", line 389, in __get_result
    raise self._exception
  File "/opt/conda/lib/python3.8/concurrent/futures/_base.py", line 328, in _invoke_callbacks
    callback(self)
  File "/opt/conda/lib/python3.8/site-packages/nipype/pipeline/plugins/multiproc.py", line 159, in _async_callback
    result = args.result()
  File "/opt/conda/lib/python3.8/concurrent/futures/_base.py", line 437, in result
    return self.__get_result()
  File "/opt/conda/lib/python3.8/concurrent/futures/_base.py", line 389, in __get_result
    raise self._exception
  File "/opt/conda/lib/python3.8/concurrent/futures/_base.py", line 328, in _invoke_callbacks
    callback(self)
  File "/opt/conda/lib/python3.8/site-packages/nipype/pipeline/plugins/multiproc.py", line 159, in _async_callback
    result = args.result()
  File "/opt/conda/lib/python3.8/concurrent/futures/_base.py", line 437, in result
    return self.__get_result()
  File "/opt/conda/lib/python3.8/concurrent/futures/_base.py", line 389, in __get_result
    raise self._exception
  File "/opt/conda/lib/python3.8/concurrent/futures/_base.py", line 328, in _invoke_callbacks
    callback(self)
  File "/opt/conda/lib/python3.8/site-packages/nipype/pipeline/plugins/multiproc.py", line 159, in _async_callback
    result = args.result()
  File "/opt/conda/lib/python3.8/concurrent/futures/_base.py", line 437, in result
    return self.__get_result()
  File "/opt/conda/lib/python3.8/concurrent/futures/_base.py", line 389, in __get_result
    raise self._exception
  File "/opt/conda/lib/python3.8/concurrent/futures/_base.py", line 328, in _invoke_callbacks
    callback(self)
  File "/opt/conda/lib/python3.8/site-packages/nipype/pipeline/plugins/multiproc.py", line 159, in _async_callback
    result = args.result()
  File "/opt/conda/lib/python3.8/concurrent/futures/_base.py", line 437, in result
    return self.__get_result()
  File "/opt/conda/lib/python3.8/concurrent/futures/_base.py", line 389, in __get_result
    raise self._exception
  File "/opt/conda/lib/python3.8/concurrent/futures/_base.py", line 328, in _invoke_callbacks
    callback(self)
  File "/opt/conda/lib/python3.8/site-packages/nipype/pipeline/plugins/multiproc.py", line 159, in _async_callback
    result = args.result()
  File "/opt/conda/lib/python3.8/concurrent/futures/_base.py", line 437, in result
    return self.__get_result()
  File "/opt/conda/lib/python3.8/concurrent/futures/_base.py", line 389, in __get_result
    raise self._exception
  File "/opt/conda/lib/python3.8/concurrent/futures/_base.py", line 328, in _invoke_callbacks
    callback(self)
  File "/opt/conda/lib/python3.8/site-packages/nipype/pipeline/plugins/multiproc.py", line 159, in _async_callback
    result = args.result()
  File "/opt/conda/lib/python3.8/concurrent/futures/_base.py", line 437, in result
    return self.__get_result()
  File "/opt/conda/lib/python3.8/concurrent/futures/_base.py", line 389, in __get_result
    raise self._exception
  File "/opt/conda/lib/python3.8/concurrent/futures/_base.py", line 328, in _invoke_callbacks
    callback(self)
  File "/opt/conda/lib/python3.8/site-packages/nipype/pipeline/plugins/multiproc.py", line 159, in _async_callback
    result = args.result()
  File "/opt/conda/lib/python3.8/concurrent/futures/_base.py", line 437, in result
    return self.__get_result()
  File "/opt/conda/lib/python3.8/concurrent/futures/_base.py", line 389, in __get_result
    raise self._exception
  File "/opt/conda/lib/python3.8/concurrent/futures/_base.py", line 328, in _invoke_callbacks
    callback(self)
  File "/opt/conda/lib/python3.8/site-packages/nipype/pipeline/plugins/multiproc.py", line 159, in _async_callback
    result = args.result()
  File "/opt/conda/lib/python3.8/concurrent/futures/_base.py", line 437, in result
    return self.__get_result()
  File "/opt/conda/lib/python3.8/concurrent/futures/_base.py", line 389, in __get_result
    raise self._exception
  File "/opt/conda/lib/python3.8/concurrent/futures/_base.py", line 328, in _invoke_callbacks
    callback(self)
  File "/opt/conda/lib/python3.8/site-packages/nipype/pipeline/plugins/multiproc.py", line 159, in _async_callback
    result = args.result()
  File "/opt/conda/lib/python3.8/concurrent/futures/_base.py", line 437, in result
    return self.__get_result()
  File "/opt/conda/lib/python3.8/concurrent/futures/_base.py", line 389, in __get_result
    raise self._exception
  File "/opt/conda/lib/python3.8/concurrent/futures/_base.py", line 328, in _invoke_callbacks
    callback(self)
  File "/opt/conda/lib/python3.8/site-packages/nipype/pipeline/plugins/multiproc.py", line 159, in _async_callback
    result = args.result()
  File "/opt/conda/lib/python3.8/concurrent/futures/_base.py", line 437, in result
    return self.__get_result()
  File "/opt/conda/lib/python3.8/concurrent/futures/_base.py", line 389, in __get_result
    raise self._exception
  File "/opt/conda/lib/python3.8/concurrent/futures/_base.py", line 328, in _invoke_callbacks
    callback(self)
  File "/opt/conda/lib/python3.8/site-packages/nipype/pipeline/plugins/multiproc.py", line 159, in _async_callback
    result = args.result()
  File "/opt/conda/lib/python3.8/concurrent/futures/_base.py", line 437, in result
    return self.__get_result()
  File "/opt/conda/lib/python3.8/concurrent/futures/_base.py", line 389, in __get_result
    raise self._exception
  File "/opt/conda/lib/python3.8/concurrent/futures/_base.py", line 328, in _invoke_callbacks
    callback(self)
  File "/opt/conda/lib/python3.8/site-packages/nipype/pipeline/plugins/multiproc.py", line 159, in _async_callback
    result = args.result()
  File "/opt/conda/lib/python3.8/concurrent/futures/_base.py", line 437, in result
    return self.__get_result()
  File "/opt/conda/lib/python3.8/concurrent/futures/_base.py", line 389, in __get_result
    raise self._exception
  File "/opt/conda/lib/python3.8/concurrent/futures/_base.py", line 328, in _invoke_callbacks
    callback(self)
  File "/opt/conda/lib/python3.8/site-packages/nipype/pipeline/plugins/multiproc.py", line 159, in _async_callback
    result = args.result()
  File "/opt/conda/lib/python3.8/concurrent/futures/_base.py", line 437, in result
    return self.__get_result()
  File "/opt/conda/lib/python3.8/concurrent/futures/_base.py", line 389, in __get_result
    raise self._exception
  File "/opt/conda/lib/python3.8/concurrent/futures/_base.py", line 328, in _invoke_callbacks
    callback(self)
  File "/opt/conda/lib/python3.8/site-packages/nipype/pipeline/plugins/multiproc.py", line 159, in _async_callback
    result = args.result()
  File "/opt/conda/lib/python3.8/concurrent/futures/_base.py", line 437, in result
    return self.__get_result()
  File "/opt/conda/lib/python3.8/concurrent/futures/_base.py", line 389, in __get_result
    raise self._exception
concurrent.futures.process.BrokenProcessPool: A process in the process pool was terminated abruptly while the future was running or pending.
exception calling callback for <Future at 0x7f36731d3100 state=finished raised BrokenProcessPool>
Traceback (most recent call last):
  File "/opt/conda/lib/python3.8/concurrent/futures/_base.py", line 328, in _invoke_callbacks
    callback(self)
  File "/opt/conda/lib/python3.8/site-packages/nipype/pipeline/plugins/multiproc.py", line 159, in _async_callback
    result = args.result()
  File "/opt/conda/lib/python3.8/concurrent/futures/_base.py", line 437, in result
    return self.__get_result()
  File "/opt/conda/lib/python3.8/concurrent/futures/_base.py", line 389, in __get_result
    raise self._exception
  File "/opt/conda/lib/python3.8/concurrent/futures/_base.py", line 328, in _invoke_callbacks
    callback(self)
  File "/opt/conda/lib/python3.8/site-packages/nipype/pipeline/plugins/multiproc.py", line 159, in _async_callback
    result = args.result()
  File "/opt/conda/lib/python3.8/concurrent/futures/_base.py", line 437, in result
    return self.__get_result()
  File "/opt/conda/lib/python3.8/concurrent/futures/_base.py", line 389, in __get_result
    raise self._exception
  File "/opt/conda/lib/python3.8/concurrent/futures/_base.py", line 328, in _invoke_callbacks
    callback(self)
  File "/opt/conda/lib/python3.8/site-packages/nipype/pipeline/plugins/multiproc.py", line 159, in _async_callback
    result = args.result()
  File "/opt/conda/lib/python3.8/concurrent/futures/_base.py", line 437, in result
    return self.__get_result()
  File "/opt/conda/lib/python3.8/concurrent/futures/_base.py", line 389, in __get_result
    raise self._exception
  File "/opt/conda/lib/python3.8/concurrent/futures/_base.py", line 328, in _invoke_callbacks
    callback(self)
  File "/opt/conda/lib/python3.8/site-packages/nipype/pipeline/plugins/multiproc.py", line 159, in _async_callback
    result = args.result()
  File "/opt/conda/lib/python3.8/concurrent/futures/_base.py", line 437, in result
    return self.__get_result()
  File "/opt/conda/lib/python3.8/concurrent/futures/_base.py", line 389, in __get_result
    raise self._exception
  File "/opt/conda/lib/python3.8/concurrent/futures/_base.py", line 328, in _invoke_callbacks
    callback(self)
  File "/opt/conda/lib/python3.8/site-packages/nipype/pipeline/plugins/multiproc.py", line 159, in _async_callback
    result = args.result()
  File "/opt/conda/lib/python3.8/concurrent/futures/_base.py", line 437, in result
    return self.__get_result()
  File "/opt/conda/lib/python3.8/concurrent/futures/_base.py", line 389, in __get_result
    raise self._exception
  File "/opt/conda/lib/python3.8/concurrent/futures/_base.py", line 328, in _invoke_callbacks
    callback(self)
  File "/opt/conda/lib/python3.8/site-packages/nipype/pipeline/plugins/multiproc.py", line 159, in _async_callback
    result = args.result()
  File "/opt/conda/lib/python3.8/concurrent/futures/_base.py", line 437, in result
    return self.__get_result()
  File "/opt/conda/lib/python3.8/concurrent/futures/_base.py", line 389, in __get_result
    raise self._exception
  File "/opt/conda/lib/python3.8/concurrent/futures/_base.py", line 328, in _invoke_callbacks
    callback(self)
  File "/opt/conda/lib/python3.8/site-packages/nipype/pipeline/plugins/multiproc.py", line 159, in _async_callback
    result = args.result()
  File "/opt/conda/lib/python3.8/concurrent/futures/_base.py", line 437, in result
    return self.__get_result()
  File "/opt/conda/lib/python3.8/concurrent/futures/_base.py", line 389, in __get_result
    raise self._exception
  File "/opt/conda/lib/python3.8/concurrent/futures/_base.py", line 328, in _invoke_callbacks
    callback(self)
  File "/opt/conda/lib/python3.8/site-packages/nipype/pipeline/plugins/multiproc.py", line 159, in _async_callback
    result = args.result()
  File "/opt/conda/lib/python3.8/concurrent/futures/_base.py", line 437, in result
    return self.__get_result()
  File "/opt/conda/lib/python3.8/concurrent/futures/_base.py", line 389, in __get_result
    raise self._exception
  File "/opt/conda/lib/python3.8/concurrent/futures/_base.py", line 328, in _invoke_callbacks
    callback(self)
  File "/opt/conda/lib/python3.8/site-packages/nipype/pipeline/plugins/multiproc.py", line 159, in _async_callback
    result = args.result()
  File "/opt/conda/lib/python3.8/concurrent/futures/_base.py", line 437, in result
    return self.__get_result()
  File "/opt/conda/lib/python3.8/concurrent/futures/_base.py", line 389, in __get_result
    raise self._exception
  File "/opt/conda/lib/python3.8/concurrent/futures/_base.py", line 328, in _invoke_callbacks
    callback(self)
  File "/opt/conda/lib/python3.8/site-packages/nipype/pipeline/plugins/multiproc.py", line 159, in _async_callback
    result = args.result()
  File "/opt/conda/lib/python3.8/concurrent/futures/_base.py", line 437, in result
    return self.__get_result()
  File "/opt/conda/lib/python3.8/concurrent/futures/_base.py", line 389, in __get_result
    raise self._exception
  File "/opt/conda/lib/python3.8/concurrent/futures/_base.py", line 328, in _invoke_callbacks
    callback(self)
  File "/opt/conda/lib/python3.8/site-packages/nipype/pipeline/plugins/multiproc.py", line 159, in _async_callback
    result = args.result()
  File "/opt/conda/lib/python3.8/concurrent/futures/_base.py", line 437, in result
    return self.__get_result()
  File "/opt/conda/lib/python3.8/concurrent/futures/_base.py", line 389, in __get_result
    raise self._exception
  File "/opt/conda/lib/python3.8/concurrent/futures/_base.py", line 328, in _invoke_callbacks
    callback(self)
  File "/opt/conda/lib/python3.8/site-packages/nipype/pipeline/plugins/multiproc.py", line 159, in _async_callback
    result = args.result()
  File "/opt/conda/lib/python3.8/concurrent/futures/_base.py", line 437, in result
    return self.__get_result()
  File "/opt/conda/lib/python3.8/concurrent/futures/_base.py", line 389, in __get_result
    raise self._exception
  File "/opt/conda/lib/python3.8/concurrent/futures/_base.py", line 328, in _invoke_callbacks
    callback(self)
  File "/opt/conda/lib/python3.8/site-packages/nipype/pipeline/plugins/multiproc.py", line 159, in _async_callback
    result = args.result()
  File "/opt/conda/lib/python3.8/concurrent/futures/_base.py", line 437, in result
    return self.__get_result()
  File "/opt/conda/lib/python3.8/concurrent/futures/_base.py", line 389, in __get_result
    raise self._exception
  File "/opt/conda/lib/python3.8/concurrent/futures/_base.py", line 328, in _invoke_callbacks
    callback(self)
  File "/opt/conda/lib/python3.8/site-packages/nipype/pipeline/plugins/multiproc.py", line 159, in _async_callback
    result = args.result()
  File "/opt/conda/lib/python3.8/concurrent/futures/_base.py", line 437, in result
    return self.__get_result()
  File "/opt/conda/lib/python3.8/concurrent/futures/_base.py", line 389, in __get_result
    raise self._exception
  File "/opt/conda/lib/python3.8/concurrent/futures/_base.py", line 328, in _invoke_callbacks
    callback(self)
  File "/opt/conda/lib/python3.8/site-packages/nipype/pipeline/plugins/multiproc.py", line 159, in _async_callback
    result = args.result()
  File "/opt/conda/lib/python3.8/concurrent/futures/_base.py", line 437, in result
    return self.__get_result()
  File "/opt/conda/lib/python3.8/concurrent/futures/_base.py", line 389, in __get_result
    raise self._exception
  File "/opt/conda/lib/python3.8/concurrent/futures/_base.py", line 328, in _invoke_callbacks
    callback(self)
  File "/opt/conda/lib/python3.8/site-packages/nipype/pipeline/plugins/multiproc.py", line 159, in _async_callback
    result = args.result()
  File "/opt/conda/lib/python3.8/concurrent/futures/_base.py", line 437, in result
    return self.__get_result()
  File "/opt/conda/lib/python3.8/concurrent/futures/_base.py", line 389, in __get_result
    raise self._exception
concurrent.futures.process.BrokenProcessPool: A process in the process pool was terminated abruptly while the future was running or pending.
exception calling callback for <Future at 0x7f3673348ee0 state=finished raised BrokenProcessPool>
Traceback (most recent call last):
  File "/opt/conda/lib/python3.8/concurrent/futures/_base.py", line 328, in _invoke_callbacks
    callback(self)
  File "/opt/conda/lib/python3.8/site-packages/nipype/pipeline/plugins/multiproc.py", line 159, in _async_callback
    result = args.result()
  File "/opt/conda/lib/python3.8/concurrent/futures/_base.py", line 437, in result
    return self.__get_result()
  File "/opt/conda/lib/python3.8/concurrent/futures/_base.py", line 389, in __get_result
    raise self._exception
  File "/opt/conda/lib/python3.8/concurrent/futures/_base.py", line 328, in _invoke_callbacks
    callback(self)
  File "/opt/conda/lib/python3.8/site-packages/nipype/pipeline/plugins/multiproc.py", line 159, in _async_callback
    result = args.result()
  File "/opt/conda/lib/python3.8/concurrent/futures/_base.py", line 437, in result
    return self.__get_result()
  File "/opt/conda/lib/python3.8/concurrent/futures/_base.py", line 389, in __get_result
    raise self._exception
  File "/opt/conda/lib/python3.8/concurrent/futures/_base.py", line 328, in _invoke_callbacks
    callback(self)
  File "/opt/conda/lib/python3.8/site-packages/nipype/pipeline/plugins/multiproc.py", line 159, in _async_callback
    result = args.result()
  File "/opt/conda/lib/python3.8/concurrent/futures/_base.py", line 437, in result
    return self.__get_result()
  File "/opt/conda/lib/python3.8/concurrent/futures/_base.py", line 389, in __get_result
    raise self._exception
  File "/opt/conda/lib/python3.8/concurrent/futures/_base.py", line 328, in _invoke_callbacks
    callback(self)
  File "/opt/conda/lib/python3.8/site-packages/nipype/pipeline/plugins/multiproc.py", line 159, in _async_callback
    result = args.result()
  File "/opt/conda/lib/python3.8/concurrent/futures/_base.py", line 437, in result
    return self.__get_result()
  File "/opt/conda/lib/python3.8/concurrent/futures/_base.py", line 389, in __get_result
    raise self._exception
  File "/opt/conda/lib/python3.8/concurrent/futures/_base.py", line 328, in _invoke_callbacks
    callback(self)
  File "/opt/conda/lib/python3.8/site-packages/nipype/pipeline/plugins/multiproc.py", line 159, in _async_callback
    result = args.result()
  File "/opt/conda/lib/python3.8/concurrent/futures/_base.py", line 437, in result
    return self.__get_result()
  File "/opt/conda/lib/python3.8/concurrent/futures/_base.py", line 389, in __get_result
    raise self._exception
  File "/opt/conda/lib/python3.8/concurrent/futures/_base.py", line 328, in _invoke_callbacks
    callback(self)
  File "/opt/conda/lib/python3.8/site-packages/nipype/pipeline/plugins/multiproc.py", line 159, in _async_callback
    result = args.result()
  File "/opt/conda/lib/python3.8/concurrent/futures/_base.py", line 437, in result
    return self.__get_result()
  File "/opt/conda/lib/python3.8/concurrent/futures/_base.py", line 389, in __get_result
    raise self._exception
  File "/opt/conda/lib/python3.8/concurrent/futures/_base.py", line 328, in _invoke_callbacks
    callback(self)
  File "/opt/conda/lib/python3.8/site-packages/nipype/pipeline/plugins/multiproc.py", line 159, in _async_callback
    result = args.result()
  File "/opt/conda/lib/python3.8/concurrent/futures/_base.py", line 437, in result
    return self.__get_result()
  File "/opt/conda/lib/python3.8/concurrent/futures/_base.py", line 389, in __get_result
    raise self._exception
  File "/opt/conda/lib/python3.8/concurrent/futures/_base.py", line 328, in _invoke_callbacks
    callback(self)
  File "/opt/conda/lib/python3.8/site-packages/nipype/pipeline/plugins/multiproc.py", line 159, in _async_callback
    result = args.result()
  File "/opt/conda/lib/python3.8/concurrent/futures/_base.py", line 437, in result
    return self.__get_result()
  File "/opt/conda/lib/python3.8/concurrent/futures/_base.py", line 389, in __get_result
    raise self._exception
  File "/opt/conda/lib/python3.8/concurrent/futures/_base.py", line 328, in _invoke_callbacks
    callback(self)
  File "/opt/conda/lib/python3.8/site-packages/nipype/pipeline/plugins/multiproc.py", line 159, in _async_callback
    result = args.result()
  File "/opt/conda/lib/python3.8/concurrent/futures/_base.py", line 437, in result
    return self.__get_result()
  File "/opt/conda/lib/python3.8/concurrent/futures/_base.py", line 389, in __get_result
    raise self._exception
  File "/opt/conda/lib/python3.8/concurrent/futures/_base.py", line 328, in _invoke_callbacks
    callback(self)
  File "/opt/conda/lib/python3.8/site-packages/nipype/pipeline/plugins/multiproc.py", line 159, in _async_callback
    result = args.result()
  File "/opt/conda/lib/python3.8/concurrent/futures/_base.py", line 437, in result
    return self.__get_result()
  File "/opt/conda/lib/python3.8/concurrent/futures/_base.py", line 389, in __get_result
    raise self._exception
  File "/opt/conda/lib/python3.8/concurrent/futures/_base.py", line 328, in _invoke_callbacks
    callback(self)
  File "/opt/conda/lib/python3.8/site-packages/nipype/pipeline/plugins/multiproc.py", line 159, in _async_callback
    result = args.result()
  File "/opt/conda/lib/python3.8/concurrent/futures/_base.py", line 437, in result
    return self.__get_result()
  File "/opt/conda/lib/python3.8/concurrent/futures/_base.py", line 389, in __get_result
    raise self._exception
  File "/opt/conda/lib/python3.8/concurrent/futures/_base.py", line 328, in _invoke_callbacks
    callback(self)
  File "/opt/conda/lib/python3.8/site-packages/nipype/pipeline/plugins/multiproc.py", line 159, in _async_callback
    result = args.result()
  File "/opt/conda/lib/python3.8/concurrent/futures/_base.py", line 437, in result
    return self.__get_result()
  File "/opt/conda/lib/python3.8/concurrent/futures/_base.py", line 389, in __get_result
    raise self._exception
  File "/opt/conda/lib/python3.8/concurrent/futures/_base.py", line 328, in _invoke_callbacks
    callback(self)
  File "/opt/conda/lib/python3.8/site-packages/nipype/pipeline/plugins/multiproc.py", line 159, in _async_callback
    result = args.result()
  File "/opt/conda/lib/python3.8/concurrent/futures/_base.py", line 437, in result
    return self.__get_result()
  File "/opt/conda/lib/python3.8/concurrent/futures/_base.py", line 389, in __get_result
    raise self._exception
  File "/opt/conda/lib/python3.8/concurrent/futures/_base.py", line 328, in _invoke_callbacks
    callback(self)
  File "/opt/conda/lib/python3.8/site-packages/nipype/pipeline/plugins/multiproc.py", line 159, in _async_callback
    result = args.result()
  File "/opt/conda/lib/python3.8/concurrent/futures/_base.py", line 437, in result
    return self.__get_result()
  File "/opt/conda/lib/python3.8/concurrent/futures/_base.py", line 389, in __get_result
    raise self._exception
  File "/opt/conda/lib/python3.8/concurrent/futures/_base.py", line 328, in _invoke_callbacks
    callback(self)
  File "/opt/conda/lib/python3.8/site-packages/nipype/pipeline/plugins/multiproc.py", line 159, in _async_callback
    result = args.result()
  File "/opt/conda/lib/python3.8/concurrent/futures/_base.py", line 437, in result
    return self.__get_result()
  File "/opt/conda/lib/python3.8/concurrent/futures/_base.py", line 389, in __get_result
    raise self._exception
  File "/opt/conda/lib/python3.8/concurrent/futures/_base.py", line 328, in _invoke_callbacks
    callback(self)
  File "/opt/conda/lib/python3.8/site-packages/nipype/pipeline/plugins/multiproc.py", line 159, in _async_callback
    result = args.result()
  File "/opt/conda/lib/python3.8/concurrent/futures/_base.py", line 437, in result
    return self.__get_result()
  File "/opt/conda/lib/python3.8/concurrent/futures/_base.py", line 389, in __get_result
    raise self._exception
  File "/opt/conda/lib/python3.8/concurrent/futures/_base.py", line 328, in _invoke_callbacks
    callback(self)
  File "/opt/conda/lib/python3.8/site-packages/nipype/pipeline/plugins/multiproc.py", line 159, in _async_callback
    result = args.result()
  File "/opt/conda/lib/python3.8/concurrent/futures/_base.py", line 437, in result
    return self.__get_result()
  File "/opt/conda/lib/python3.8/concurrent/futures/_base.py", line 389, in __get_result
    raise self._exception
concurrent.futures.process.BrokenProcessPool: A process in the process pool was terminated abruptly while the future was running or pending.
221125-15:25:27,345 nipype.workflow CRITICAL:
	 fMRIPrep failed: A child process terminated abruptly, the process pool is not usable anymore
