(base) tchaase@tobiaslegion:~$ docker run -it --rm -m 10GB --cpus="3" -v /home/tchaase/Documents/Universitaet/Forschungsmodul/project/data/ds003707:/data:ro \
-v /home/tchaase/Documents/Universitaet/Forschungsmodul/project/data/derivatives:/out -v  /home/tchaase/licenses/freesurfer/license.txt:/opt/freesurfer/license.txt nipreps/fmriprep:21.0.4  \
/data /out participant --participant_label 01 --use-aroma  --ignore t2w --output-spaces MNI152NLin6Asym:res-2 T1w --fs-license-file /opt/freesurfer/license.txt 
You are using fMRIPrep-21.0.4, and a newer version of fMRIPrep is available: 22.0.2.
Please check out our documentation about how and when to upgrade:
https://fmriprep.readthedocs.io/en/latest/faq.html#upgrading
bids-validator@1.8.0

This dataset appears to be BIDS compatible.

        Summary:                Available Tasks:                      Available Modalities: 
        69 Files, 4.65GB        objects old new identification        MRI                   
        2 - Subjects            scenes old new identification                               
        1 - Session                                                                         


	If you have any questions, please post on https://neurostars.org/tags/bids.

221125-15:10:50,910 nipype.workflow IMPORTANT:
	 Running fMRIPrep version 21.0.4

         License NOTICE ##################################################
         fMRIPrep 21.0.4
         Copyright 2021 The NiPreps Developers.
         
         This product includes software developed by
         the NiPreps Community (https://nipreps.org/).
         
         Portions of this software were developed at the Department of
         Psychology at Stanford University, Stanford, CA, US.
         
         This software redistributes the versioneer Python package, which is
         Public domain source code.
         
         This software is also distributed as a Docker container image.
         The bootstraping file for the image ("Dockerfile") is licensed
         under the MIT License.
         
         This software may be distributed through an add-on package called
         "Docker Wrapper" that is under the BSD 3-clause License.
         #################################################################
221125-15:10:51,576 nipype.workflow IMPORTANT:
	 Building fMRIPrep's workflow:
           * BIDS dataset path: /data.
           * Participant list: ['01'].
           * Run identifier: 20221125-151039_3a1e6aa7-6a50-416d-803c-fb09377facc8.
           * Output spaces: MNI152NLin6Asym:res-2 T1w.
           * Pre-run FreeSurfer's SUBJECTS_DIR: /out/sourcedata/freesurfer.
221125-15:10:52,926 nipype.workflow INFO:
	 B0 field inhomogeneity map will be estimated with  the following 1 estimators: [<EstimatorType.PEPOLAR: 2>].
221125-15:10:52,970 nipype.workflow INFO:
	 No single-band-reference found for sub-01_task-obj_run-02_bold.nii.gz.
221125-15:10:52,970 nipype.workflow INFO:
	 Found usable B0-map (fieldmap) estimator(s) <auto_00000> to correct </data/sub-01/func/sub-01_task-obj_run-02_bold.nii.gz> for susceptibility-derived distortions.
221125-15:10:53,52 nipype.workflow IMPORTANT:
	 BOLD series will be slice-timing corrected to an offset of 0.949s.
221125-15:10:53,184 nipype.workflow INFO:
	 No single-band-reference found for sub-01_task-obj_run-08_bold.nii.gz.
221125-15:10:53,184 nipype.workflow INFO:
	 Found usable B0-map (fieldmap) estimator(s) <auto_00000> to correct </data/sub-01/func/sub-01_task-obj_run-08_bold.nii.gz> for susceptibility-derived distortions.
221125-15:10:53,259 nipype.workflow IMPORTANT:
	 BOLD series will be slice-timing corrected to an offset of 0.949s.
221125-15:10:53,421 nipype.workflow INFO:
	 No single-band-reference found for sub-01_task-scene_run-01_bold.nii.gz.
221125-15:10:53,421 nipype.workflow INFO:
	 Found usable B0-map (fieldmap) estimator(s) <auto_00000> to correct </data/sub-01/func/sub-01_task-scene_run-01_bold.nii.gz> for susceptibility-derived distortions.
221125-15:10:53,495 nipype.workflow IMPORTANT:
	 BOLD series will be slice-timing corrected to an offset of 0.949s.
221125-15:10:53,608 nipype.workflow INFO:
	 No single-band-reference found for sub-01_task-scene_run-03_bold.nii.gz.
221125-15:10:53,608 nipype.workflow INFO:
	 Found usable B0-map (fieldmap) estimator(s) <auto_00000> to correct </data/sub-01/func/sub-01_task-scene_run-03_bold.nii.gz> for susceptibility-derived distortions.
221125-15:10:53,682 nipype.workflow IMPORTANT:
	 BOLD series will be slice-timing corrected to an offset of 0.949s.
221125-15:10:53,796 nipype.workflow INFO:
	 No single-band-reference found for sub-01_task-scene_run-04_bold.nii.gz.
221125-15:10:53,797 nipype.workflow INFO:
	 Found usable B0-map (fieldmap) estimator(s) <auto_00000> to correct </data/sub-01/func/sub-01_task-scene_run-04_bold.nii.gz> for susceptibility-derived distortions.
221125-15:10:53,871 nipype.workflow IMPORTANT:
	 BOLD series will be slice-timing corrected to an offset of 0.949s.
221125-15:10:53,983 nipype.workflow INFO:
	 No single-band-reference found for sub-01_task-scene_run-05_bold.nii.gz.
221125-15:10:53,983 nipype.workflow INFO:
	 Found usable B0-map (fieldmap) estimator(s) <auto_00000> to correct </data/sub-01/func/sub-01_task-scene_run-05_bold.nii.gz> for susceptibility-derived distortions.
221125-15:10:54,58 nipype.workflow IMPORTANT:
	 BOLD series will be slice-timing corrected to an offset of 0.949s.
221125-15:10:54,170 nipype.workflow INFO:
	 No single-band-reference found for sub-01_task-scene_run-06_bold.nii.gz.
221125-15:10:54,170 nipype.workflow INFO:
	 Found usable B0-map (fieldmap) estimator(s) <auto_00000> to correct </data/sub-01/func/sub-01_task-scene_run-06_bold.nii.gz> for susceptibility-derived distortions.
221125-15:10:54,304 nipype.workflow IMPORTANT:
	 BOLD series will be slice-timing corrected to an offset of 0.949s.
221125-15:10:54,418 nipype.workflow INFO:
	 No single-band-reference found for sub-01_task-scene_run-07_bold.nii.gz.
221125-15:10:54,418 nipype.workflow INFO:
	 Found usable B0-map (fieldmap) estimator(s) <auto_00000> to correct </data/sub-01/func/sub-01_task-scene_run-07_bold.nii.gz> for susceptibility-derived distortions.
221125-15:10:54,493 nipype.workflow IMPORTANT:
	 BOLD series will be slice-timing corrected to an offset of 0.949s.
221125-15:10:54,623 nipype.workflow INFO:
	 Setting-up fieldmap "auto_00000" (EstimatorType.PEPOLAR) with <sub-01_dir-AP_epi.nii.gz, sub-01_dir-PA_epi.nii.gz>
221125-15:10:57,434 nipype.workflow INFO:
	 fMRIPrep workflow graph with 2191 nodes built successfully.
221125-15:11:04,168 nipype.workflow IMPORTANT:
	 fMRIPrep started!
221125-15:11:05,792 nipype.workflow WARNING:
	 Some nodes exceed the total amount of memory available (13.82GB).
221125-15:11:15,23 nipype.workflow INFO:
	 [Node] Setting-up "fmriprep_wf.single_subject_01_wf.anat_preproc_wf.brain_extraction_wf.full_wm" in "/tmp/work/fmriprep_wf/single_subject_01_wf/anat_preproc_wf/brain_extraction_wf/full_wm".
221125-15:11:15,28 nipype.workflow INFO:
	 [Node] Running "full_wm" ("nipype.interfaces.utility.wrappers.Function")
221125-15:11:15,130 nipype.workflow INFO:
	 [Node] Setting-up "fmriprep_wf.single_subject_01_wf.func_preproc_task_obj_run_02_wf.bold_source" in "/tmp/work/fmriprep_wf/single_subject_01_wf/func_preproc_task_obj_run_02_wf/bold_source".
221125-15:11:15,133 nipype.workflow INFO:
	 [Node] Running "bold_source" ("nipype.interfaces.utility.base.Select")
221125-15:11:15,328 nipype.workflow INFO:
	 [Node] Setting-up "fmriprep_wf.single_subject_01_wf.func_preproc_task_obj_run_02_wf.func_derivatives_wf.raw_sources" in "/tmp/work/fmriprep_wf/single_subject_01_wf/func_preproc_task_obj_run_02_wf/func_derivatives_wf/raw_sources".
221125-15:11:15,328 nipype.workflow INFO:
	 [Node] Finished "fmriprep_wf.single_subject_01_wf.func_preproc_task_obj_run_02_wf.bold_source".
221125-15:11:15,421 nipype.workflow INFO:
	 [Node] Running "raw_sources" ("nipype.interfaces.utility.wrappers.Function")
221125-15:11:15,619 nipype.workflow INFO:
	 [Node] Finished "fmriprep_wf.single_subject_01_wf.func_preproc_task_obj_run_02_wf.func_derivatives_wf.raw_sources".
221125-15:11:15,621 nipype.workflow INFO:
	 [Node] Setting-up "fmriprep_wf.single_subject_01_wf.func_preproc_task_obj_run_08_wf.bold_source" in "/tmp/work/fmriprep_wf/single_subject_01_wf/func_preproc_task_obj_run_08_wf/bold_source".
221125-15:11:15,622 nipype.workflow INFO:
	 [Node] Running "bold_source" ("nipype.interfaces.utility.base.Select")
221125-15:11:15,624 nipype.workflow INFO:
	 [Node] Finished "fmriprep_wf.single_subject_01_wf.func_preproc_task_obj_run_08_wf.bold_source".
221125-15:11:15,625 nipype.workflow INFO:
	 [Node] Setting-up "fmriprep_wf.single_subject_01_wf.func_preproc_task_obj_run_08_wf.func_derivatives_wf.raw_sources" in "/tmp/work/fmriprep_wf/single_subject_01_wf/func_preproc_task_obj_run_08_wf/func_derivatives_wf/raw_sources".
221125-15:11:15,626 nipype.workflow INFO:
	 [Node] Running "raw_sources" ("nipype.interfaces.utility.wrappers.Function")
221125-15:11:15,628 nipype.workflow INFO:
	 [Node] Finished "fmriprep_wf.single_subject_01_wf.func_preproc_task_obj_run_08_wf.func_derivatives_wf.raw_sources".
221125-15:11:15,920 nipype.workflow INFO:
	 [Node] Setting-up "fmriprep_wf.single_subject_01_wf.func_preproc_task_scene_run_01_wf.bold_source" in "/tmp/work/fmriprep_wf/single_subject_01_wf/func_preproc_task_scene_run_01_wf/bold_source".
221125-15:11:15,927 nipype.workflow INFO:
	 [Node] Running "bold_source" ("nipype.interfaces.utility.base.Select")
221125-15:11:16,26 nipype.workflow INFO:
	 [Node] Setting-up "fmriprep_wf.single_subject_01_wf.func_preproc_task_scene_run_01_wf.func_derivatives_wf.raw_sources" in "/tmp/work/fmriprep_wf/single_subject_01_wf/func_preproc_task_scene_run_01_wf/func_derivatives_wf/raw_sources".
221125-15:11:16,30 nipype.workflow INFO:
	 [Node] Running "raw_sources" ("nipype.interfaces.utility.wrappers.Function")
221125-15:11:16,219 nipype.workflow INFO:
	 [Node] Setting-up "fmriprep_wf.single_subject_01_wf.anat_preproc_wf.brain_extraction_wf.lap_tmpl" in "/tmp/work/fmriprep_wf/single_subject_01_wf/anat_preproc_wf/brain_extraction_wf/lap_tmpl".
221125-15:11:16,221 nipype.workflow INFO:
	 [Node] Finished "fmriprep_wf.single_subject_01_wf.func_preproc_task_scene_run_01_wf.bold_source".
221125-15:11:16,228 nipype.workflow INFO:
	 [Node] Running "lap_tmpl" ("nipype.interfaces.ants.utils.ImageMath"), a CommandLine Interface with command:
ImageMath 3 tpl-OASIS30ANTs_res-01_T1w_maths.nii.gz Laplacian /home/fmriprep/.cache/templateflow/tpl-OASIS30ANTs/tpl-OASIS30ANTs_res-01_T1w.nii.gz 1.5 1
221125-15:11:16,319 nipype.workflow INFO:
	 [Node] Finished "fmriprep_wf.single_subject_01_wf.func_preproc_task_scene_run_01_wf.func_derivatives_wf.raw_sources".
221125-15:11:16,331 nipype.workflow INFO:
	 [Node] Setting-up "fmriprep_wf.single_subject_01_wf.anat_preproc_wf.brain_extraction_wf.res_tmpl" in "/tmp/work/fmriprep_wf/single_subject_01_wf/anat_preproc_wf/brain_extraction_wf/res_tmpl".
221125-15:11:16,333 nipype.workflow INFO:
	 [Node] Setting-up "fmriprep_wf.single_subject_01_wf.func_preproc_task_scene_run_03_wf.bold_source" in "/tmp/work/fmriprep_wf/single_subject_01_wf/func_preproc_task_scene_run_03_wf/bold_source".
221125-15:11:16,336 nipype.workflow INFO:
	 [Node] Running "res_tmpl" ("niworkflows.interfaces.nibabel.RegridToZooms")
221125-15:11:16,420 nipype.workflow INFO:
	 [Node] Running "bold_source" ("nipype.interfaces.utility.base.Select")
221125-15:11:16,619 nipype.workflow INFO:
	 [Node] Finished "fmriprep_wf.single_subject_01_wf.func_preproc_task_scene_run_03_wf.bold_source".
221125-15:11:16,619 nipype.workflow INFO:
	 [Node] Setting-up "fmriprep_wf.single_subject_01_wf.func_preproc_task_scene_run_03_wf.func_derivatives_wf.raw_sources" in "/tmp/work/fmriprep_wf/single_subject_01_wf/func_preproc_task_scene_run_03_wf/func_derivatives_wf/raw_sources".
221125-15:11:16,624 nipype.workflow INFO:
	 [Node] Running "raw_sources" ("nipype.interfaces.utility.wrappers.Function")
221125-15:11:16,627 nipype.workflow INFO:
	 [Node] Finished "fmriprep_wf.single_subject_01_wf.func_preproc_task_scene_run_03_wf.func_derivatives_wf.raw_sources".
221125-15:11:16,635 nipype.workflow INFO:
	 [Node] Setting-up "fmriprep_wf.single_subject_01_wf.func_preproc_task_obj_run_02_wf.initial_boldref_wf.get_dummy" in "/tmp/work/fmriprep_wf/single_subject_01_wf/func_preproc_task_obj_run_02_wf/initial_boldref_wf/get_dummy".
221125-15:11:16,721 nipype.workflow INFO:
	 [Node] Running "get_dummy" ("niworkflows.interfaces.bold.NonsteadyStatesDetector")
221125-15:11:16,933 nipype.workflow INFO:
	 [Node] Setting-up "fmriprep_wf.single_subject_01_wf.func_preproc_task_obj_run_02_wf.initial_boldref_wf.val_bold" in "/tmp/work/fmriprep_wf/single_subject_01_wf/func_preproc_task_obj_run_02_wf/initial_boldref_wf/val_bold".
221125-15:11:17,20 nipype.workflow INFO:
	 [Node] Setting-up "_val_bold0" in "/tmp/work/fmriprep_wf/single_subject_01_wf/func_preproc_task_obj_run_02_wf/initial_boldref_wf/val_bold/mapflow/_val_bold0".
221125-15:11:17,22 nipype.workflow INFO:
	 [Node] Running "_val_bold0" ("niworkflows.interfaces.header.ValidateImage")
221125-15:11:17,129 nipype.workflow INFO:
	 [Node] Setting-up "fmriprep_wf.single_subject_01_wf.func_preproc_task_obj_run_08_wf.initial_boldref_wf.val_bold" in "/tmp/work/fmriprep_wf/single_subject_01_wf/func_preproc_task_obj_run_08_wf/initial_boldref_wf/val_bold".
221125-15:11:17,221 nipype.workflow INFO:
	 [Node] Setting-up "_val_bold0" in "/tmp/work/fmriprep_wf/single_subject_01_wf/func_preproc_task_obj_run_08_wf/initial_boldref_wf/val_bold/mapflow/_val_bold0".
221125-15:11:17,223 nipype.workflow INFO:
	 [Node] Running "_val_bold0" ("niworkflows.interfaces.header.ValidateImage")
221125-15:11:17,327 nipype.workflow INFO:
	 [Node] Setting-up "fmriprep_wf.single_subject_01_wf.func_preproc_task_obj_run_08_wf.initial_boldref_wf.get_dummy" in "/tmp/work/fmriprep_wf/single_subject_01_wf/func_preproc_task_obj_run_08_wf/initial_boldref_wf/get_dummy".
221125-15:11:17,422 nipype.workflow INFO:
	 [Node] Running "get_dummy" ("niworkflows.interfaces.bold.NonsteadyStatesDetector")
221125-15:11:17,826 nipype.workflow INFO:
	 [Node] Setting-up "fmriprep_wf.single_subject_01_wf.func_preproc_task_scene_run_01_wf.initial_boldref_wf.val_bold" in "/tmp/work/fmriprep_wf/single_subject_01_wf/func_preproc_task_scene_run_01_wf/initial_boldref_wf/val_bold".
221125-15:11:17,829 nipype.workflow INFO:
	 [Node] Setting-up "_val_bold0" in "/tmp/work/fmriprep_wf/single_subject_01_wf/func_preproc_task_scene_run_01_wf/initial_boldref_wf/val_bold/mapflow/_val_bold0".
221125-15:11:17,921 nipype.workflow INFO:
	 [Node] Running "_val_bold0" ("niworkflows.interfaces.header.ValidateImage")
221125-15:11:17,934 nipype.workflow INFO:
	 [Node] Setting-up "fmriprep_wf.single_subject_01_wf.func_preproc_task_scene_run_01_wf.initial_boldref_wf.get_dummy" in "/tmp/work/fmriprep_wf/single_subject_01_wf/func_preproc_task_scene_run_01_wf/initial_boldref_wf/get_dummy".
221125-15:11:18,21 nipype.workflow INFO:
	 [Node] Running "get_dummy" ("niworkflows.interfaces.bold.NonsteadyStatesDetector")
221125-15:11:18,217 nipype.workflow INFO:
	 [Node] Setting-up "fmriprep_wf.single_subject_01_wf.func_preproc_task_scene_run_04_wf.bold_source" in "/tmp/work/fmriprep_wf/single_subject_01_wf/func_preproc_task_scene_run_04_wf/bold_source".
221125-15:11:18,221 nipype.workflow INFO:
	 [Node] Running "bold_source" ("nipype.interfaces.utility.base.Select")
221125-15:11:18,229 nipype.workflow INFO:
	 [Node] Setting-up "fmriprep_wf.single_subject_01_wf.func_preproc_task_scene_run_03_wf.initial_boldref_wf.get_dummy" in "/tmp/work/fmriprep_wf/single_subject_01_wf/func_preproc_task_scene_run_03_wf/initial_boldref_wf/get_dummy".
221125-15:11:18,319 nipype.workflow INFO:
	 [Node] Running "get_dummy" ("niworkflows.interfaces.bold.NonsteadyStatesDetector")
221125-15:11:18,424 nipype.workflow INFO:
	 [Node] Finished "fmriprep_wf.single_subject_01_wf.func_preproc_task_scene_run_04_wf.bold_source".
221125-15:11:18,425 nipype.workflow INFO:
	 [Node] Setting-up "fmriprep_wf.single_subject_01_wf.func_preproc_task_scene_run_04_wf.func_derivatives_wf.raw_sources" in "/tmp/work/fmriprep_wf/single_subject_01_wf/func_preproc_task_scene_run_04_wf/func_derivatives_wf/raw_sources".
221125-15:11:18,433 nipype.workflow INFO:
	 [Node] Running "raw_sources" ("nipype.interfaces.utility.wrappers.Function")
221125-15:11:18,519 nipype.workflow INFO:
	 [Node] Finished "fmriprep_wf.single_subject_01_wf.func_preproc_task_scene_run_04_wf.func_derivatives_wf.raw_sources".
221125-15:11:18,523 nipype.workflow INFO:
	 [Node] Setting-up "fmriprep_wf.single_subject_01_wf.func_preproc_task_scene_run_03_wf.initial_boldref_wf.val_bold" in "/tmp/work/fmriprep_wf/single_subject_01_wf/func_preproc_task_scene_run_03_wf/initial_boldref_wf/val_bold".
221125-15:11:18,529 nipype.workflow INFO:
	 [Node] Setting-up "_val_bold0" in "/tmp/work/fmriprep_wf/single_subject_01_wf/func_preproc_task_scene_run_03_wf/initial_boldref_wf/val_bold/mapflow/_val_bold0".
221125-15:11:18,530 nipype.workflow INFO:
	 [Node] Running "_val_bold0" ("niworkflows.interfaces.header.ValidateImage")
221125-15:11:19,19 nipype.workflow INFO:
	 [Node] Setting-up "fmriprep_wf.single_subject_01_wf.func_preproc_task_scene_run_05_wf.bold_source" in "/tmp/work/fmriprep_wf/single_subject_01_wf/func_preproc_task_scene_run_05_wf/bold_source".
221125-15:11:19,20 nipype.workflow INFO:
	 [Node] Running "bold_source" ("nipype.interfaces.utility.base.Select")
221125-15:11:19,128 nipype.workflow INFO:
	 [Node] Setting-up "fmriprep_wf.single_subject_01_wf.func_preproc_task_scene_run_05_wf.func_derivatives_wf.raw_sources" in "/tmp/work/fmriprep_wf/single_subject_01_wf/func_preproc_task_scene_run_05_wf/func_derivatives_wf/raw_sources".
221125-15:11:19,130 nipype.workflow INFO:
	 [Node] Running "raw_sources" ("nipype.interfaces.utility.wrappers.Function")
221125-15:11:19,134 nipype.workflow INFO:
	 [Node] Finished "fmriprep_wf.single_subject_01_wf.func_preproc_task_scene_run_05_wf.bold_source".
221125-15:11:19,322 nipype.workflow INFO:
	 [Node] Finished "fmriprep_wf.single_subject_01_wf.func_preproc_task_scene_run_05_wf.func_derivatives_wf.raw_sources".
221125-15:11:19,718 nipype.workflow INFO:
	 [Node] Finished "fmriprep_wf.single_subject_01_wf.anat_preproc_wf.brain_extraction_wf.full_wm".
221125-15:11:19,931 nipype.workflow INFO:
	 [Node] Setting-up "fmriprep_wf.single_subject_01_wf.bidssrc" in "/tmp/work/fmriprep_wf/single_subject_01_wf/bidssrc".
221125-15:11:19,933 nipype.workflow INFO:
	 [Node] Running "bidssrc" ("niworkflows.interfaces.bids.BIDSDataGrabber")
221125-15:11:20,36 nipype.interface INFO:
	 No "t2w" images found for sub-01
221125-15:11:20,36 nipype.interface INFO:
	 No "flair" images found for sub-01
221125-15:11:20,36 nipype.interface INFO:
	 No "sbref" images found for sub-01
221125-15:11:20,36 nipype.interface INFO:
	 No "roi" images found for sub-01
221125-15:11:20,38 nipype.workflow INFO:
	 [Node] Finished "fmriprep_wf.single_subject_01_wf.bidssrc".
221125-15:11:20,321 nipype.workflow INFO:
	 [Node] Setting-up "fmriprep_wf.single_subject_01_wf.func_preproc_task_scene_run_04_wf.initial_boldref_wf.get_dummy" in "/tmp/work/fmriprep_wf/single_subject_01_wf/func_preproc_task_scene_run_04_wf/initial_boldref_wf/get_dummy".
221125-15:11:20,322 nipype.workflow INFO:
	 [Node] Running "get_dummy" ("niworkflows.interfaces.bold.NonsteadyStatesDetector")
221125-15:11:20,328 nipype.workflow INFO:
	 [Node] Setting-up "fmriprep_wf.single_subject_01_wf.func_preproc_task_scene_run_04_wf.initial_boldref_wf.val_bold" in "/tmp/work/fmriprep_wf/single_subject_01_wf/func_preproc_task_scene_run_04_wf/initial_boldref_wf/val_bold".
221125-15:11:20,331 nipype.workflow INFO:
	 [Node] Setting-up "_val_bold0" in "/tmp/work/fmriprep_wf/single_subject_01_wf/func_preproc_task_scene_run_04_wf/initial_boldref_wf/val_bold/mapflow/_val_bold0".
221125-15:11:20,332 nipype.workflow INFO:
	 [Node] Running "_val_bold0" ("niworkflows.interfaces.header.ValidateImage")
221125-15:11:20,435 nipype.workflow INFO:
	 [Node] Setting-up "fmriprep_wf.single_subject_01_wf.func_preproc_task_scene_run_05_wf.initial_boldref_wf.get_dummy" in "/tmp/work/fmriprep_wf/single_subject_01_wf/func_preproc_task_scene_run_05_wf/initial_boldref_wf/get_dummy".
221125-15:11:20,518 nipype.workflow INFO:
	 [Node] Running "get_dummy" ("niworkflows.interfaces.bold.NonsteadyStatesDetector")
221125-15:11:21,25 nipype.workflow INFO:
	 [Node] Setting-up "fmriprep_wf.single_subject_01_wf.func_preproc_task_scene_run_05_wf.initial_boldref_wf.val_bold" in "/tmp/work/fmriprep_wf/single_subject_01_wf/func_preproc_task_scene_run_05_wf/initial_boldref_wf/val_bold".
221125-15:11:21,27 nipype.workflow INFO:
	 [Node] Setting-up "_val_bold0" in "/tmp/work/fmriprep_wf/single_subject_01_wf/func_preproc_task_scene_run_05_wf/initial_boldref_wf/val_bold/mapflow/_val_bold0".
221125-15:11:21,28 nipype.workflow INFO:
	 [Node] Running "_val_bold0" ("niworkflows.interfaces.header.ValidateImage")
221125-15:11:21,122 nipype.workflow INFO:
	 [Node] Setting-up "fmriprep_wf.single_subject_01_wf.func_preproc_task_scene_run_06_wf.bold_source" in "/tmp/work/fmriprep_wf/single_subject_01_wf/func_preproc_task_scene_run_06_wf/bold_source".
221125-15:11:21,122 nipype.workflow INFO:
	 [Node] Setting-up "fmriprep_wf.single_subject_01_wf.func_preproc_task_scene_run_06_wf.func_derivatives_wf.raw_sources" in "/tmp/work/fmriprep_wf/single_subject_01_wf/func_preproc_task_scene_run_06_wf/func_derivatives_wf/raw_sources".
221125-15:11:21,123 nipype.workflow INFO:
	 [Node] Running "bold_source" ("nipype.interfaces.utility.base.Select")
221125-15:11:21,123 nipype.workflow INFO:
	 [Node] Running "raw_sources" ("nipype.interfaces.utility.wrappers.Function")
221125-15:11:21,124 nipype.workflow INFO:
	 [Node] Setting-up "fmriprep_wf.single_subject_01_wf.func_preproc_task_scene_run_07_wf.func_derivatives_wf.raw_sources" in "/tmp/work/fmriprep_wf/single_subject_01_wf/func_preproc_task_scene_run_07_wf/func_derivatives_wf/raw_sources".
221125-15:11:21,124 nipype.workflow INFO:
	 [Node] Setting-up "fmriprep_wf.single_subject_01_wf.func_preproc_task_scene_run_07_wf.bold_source" in "/tmp/work/fmriprep_wf/single_subject_01_wf/func_preproc_task_scene_run_07_wf/bold_source".
221125-15:11:21,125 nipype.workflow INFO:
	 [Node] Finished "fmriprep_wf.single_subject_01_wf.func_preproc_task_scene_run_06_wf.bold_source".
221125-15:11:21,125 nipype.workflow INFO:
	 [Node] Running "bold_source" ("nipype.interfaces.utility.base.Select")
221125-15:11:21,126 nipype.workflow INFO:
	 [Node] Running "raw_sources" ("nipype.interfaces.utility.wrappers.Function")
221125-15:11:21,128 nipype.workflow INFO:
	 [Node] Finished "fmriprep_wf.single_subject_01_wf.func_preproc_task_scene_run_07_wf.func_derivatives_wf.raw_sources".
221125-15:11:21,227 nipype.workflow INFO:
	 [Node] Finished "fmriprep_wf.single_subject_01_wf.func_preproc_task_scene_run_06_wf.func_derivatives_wf.raw_sources".
221125-15:11:21,417 nipype.workflow INFO:
	 [Node] Finished "fmriprep_wf.single_subject_01_wf.func_preproc_task_scene_run_07_wf.bold_source".
221125-15:11:21,521 nipype.workflow INFO:
	 [Node] Setting-up "fmriprep_wf.single_subject_01_wf.func_preproc_task_scene_run_06_wf.initial_boldref_wf.val_bold" in "/tmp/work/fmriprep_wf/single_subject_01_wf/func_preproc_task_scene_run_06_wf/initial_boldref_wf/val_bold".
221125-15:11:21,523 nipype.workflow INFO:
	 [Node] Setting-up "_val_bold0" in "/tmp/work/fmriprep_wf/single_subject_01_wf/func_preproc_task_scene_run_06_wf/initial_boldref_wf/val_bold/mapflow/_val_bold0".
221125-15:11:21,524 nipype.workflow INFO:
	 [Node] Running "_val_bold0" ("niworkflows.interfaces.header.ValidateImage")
221125-15:11:22,522 nipype.workflow INFO:
	 [Node] Setting-up "fmriprep_wf.single_subject_01_wf.func_preproc_task_scene_run_06_wf.initial_boldref_wf.get_dummy" in "/tmp/work/fmriprep_wf/single_subject_01_wf/func_preproc_task_scene_run_06_wf/initial_boldref_wf/get_dummy".
221125-15:11:22,524 nipype.workflow INFO:
	 [Node] Running "get_dummy" ("niworkflows.interfaces.bold.NonsteadyStatesDetector")
221125-15:11:23,24 nipype.workflow INFO:
	 [Node] Setting-up "fmriprep_wf.single_subject_01_wf.fmap_preproc_wf.out_merge_fmap_id" in "/tmp/work/fmriprep_wf/single_subject_01_wf/fmap_preproc_wf/out_merge_fmap_id".
221125-15:11:23,24 nipype.workflow INFO:
	 [Node] Setting-up "fmriprep_wf.single_subject_01_wf.fmap_preproc_wf.out_merge_method" in "/tmp/work/fmriprep_wf/single_subject_01_wf/fmap_preproc_wf/out_merge_method".
221125-15:11:23,24 nipype.workflow INFO:
	 [Node] Setting-up "fmriprep_wf.single_subject_01_wf.func_preproc_task_scene_run_07_wf.initial_boldref_wf.get_dummy" in "/tmp/work/fmriprep_wf/single_subject_01_wf/func_preproc_task_scene_run_07_wf/initial_boldref_wf/get_dummy".
221125-15:11:23,25 nipype.workflow INFO:
	 [Node] Running "get_dummy" ("niworkflows.interfaces.bold.NonsteadyStatesDetector")
221125-15:11:23,26 nipype.workflow INFO:
	 [Node] Running "out_merge_fmap_id" ("nipype.interfaces.utility.base.Merge")
221125-15:11:23,27 nipype.workflow INFO:
	 [Node] Running "out_merge_method" ("nipype.interfaces.utility.base.Merge")
221125-15:11:23,29 nipype.workflow INFO:
	 [Node] Finished "fmriprep_wf.single_subject_01_wf.fmap_preproc_wf.out_merge_fmap_id".
221125-15:11:23,31 nipype.workflow INFO:
	 [Node] Finished "fmriprep_wf.single_subject_01_wf.fmap_preproc_wf.out_merge_method".
221125-15:11:24,318 nipype.workflow INFO:
	 [Node] Setting-up "fmriprep_wf.single_subject_01_wf.func_preproc_task_scene_run_07_wf.initial_boldref_wf.val_bold" in "/tmp/work/fmriprep_wf/single_subject_01_wf/func_preproc_task_scene_run_07_wf/initial_boldref_wf/val_bold".
221125-15:11:24,320 nipype.workflow INFO:
	 [Node] Setting-up "_val_bold0" in "/tmp/work/fmriprep_wf/single_subject_01_wf/func_preproc_task_scene_run_07_wf/initial_boldref_wf/val_bold/mapflow/_val_bold0".
221125-15:11:24,321 nipype.workflow INFO:
	 [Node] Running "_val_bold0" ("niworkflows.interfaces.header.ValidateImage")
221125-15:11:24,920 nipype.workflow INFO:
	 [Node] Finished "fmriprep_wf.single_subject_01_wf.anat_preproc_wf.brain_extraction_wf.res_tmpl".
221125-15:11:25,937 nipype.workflow INFO:
	 [Node] Setting-up "fmriprep_wf.single_subject_01_wf.fmap_preproc_wf.wf_auto_00000.flatten" in "/tmp/work/fmriprep_wf/single_subject_01_wf/fmap_preproc_wf/wf_auto_00000/flatten".
221125-15:11:26,22 nipype.workflow INFO:
	 [Node] Running "flatten" ("sdcflows.interfaces.utils.Flatten")
221125-15:11:26,228 nipype.workflow INFO:
	 [Node] Finished "fmriprep_wf.single_subject_01_wf.fmap_preproc_wf.wf_auto_00000.flatten".
exception calling callback for <Future at 0x7fa01cf22040 state=finished raised BrokenProcessPool>
Traceback (most recent call last):
  File "/opt/conda/lib/python3.8/concurrent/futures/_base.py", line 328, in _invoke_callbacks
    callback(self)
  File "/opt/conda/lib/python3.8/site-packages/nipype/pipeline/plugins/multiproc.py", line 159, in _async_callback
    result = args.result()
  File "/opt/conda/lib/python3.8/concurrent/futures/_base.py", line 437, in result
    return self.__get_result()
  File "/opt/conda/lib/python3.8/concurrent/futures/_base.py", line 389, in __get_result
    raise self._exception
concurrent.futures.process.BrokenProcessPool: A process in the process pool was terminated abruptly while the future was running or pending.
exception calling callback for <Future at 0x7fa01cf08e50 state=finished raised BrokenProcessPool>
Traceback (most recent call last):
  File "/opt/conda/lib/python3.8/concurrent/futures/_base.py", line 328, in _invoke_callbacks
    callback(self)
  File "/opt/conda/lib/python3.8/site-packages/nipype/pipeline/plugins/multiproc.py", line 159, in _async_callback
    result = args.result()
  File "/opt/conda/lib/python3.8/concurrent/futures/_base.py", line 437, in result
    return self.__get_result()
  File "/opt/conda/lib/python3.8/concurrent/futures/_base.py", line 389, in __get_result
    raise self._exception
  File "/opt/conda/lib/python3.8/concurrent/futures/_base.py", line 328, in _invoke_callbacks
    callback(self)
  File "/opt/conda/lib/python3.8/site-packages/nipype/pipeline/plugins/multiproc.py", line 159, in _async_callback
    result = args.result()
  File "/opt/conda/lib/python3.8/concurrent/futures/_base.py", line 437, in result
    return self.__get_result()
  File "/opt/conda/lib/python3.8/concurrent/futures/_base.py", line 389, in __get_result
    raise self._exception
concurrent.futures.process.BrokenProcessPool: A process in the process pool was terminated abruptly while the future was running or pending.
exception calling callback for <Future at 0x7fa01cf2f730 state=finished raised BrokenProcessPool>
Traceback (most recent call last):
  File "/opt/conda/lib/python3.8/concurrent/futures/_base.py", line 328, in _invoke_callbacks
    callback(self)
  File "/opt/conda/lib/python3.8/site-packages/nipype/pipeline/plugins/multiproc.py", line 159, in _async_callback
    result = args.result()
  File "/opt/conda/lib/python3.8/concurrent/futures/_base.py", line 437, in result
    return self.__get_result()
  File "/opt/conda/lib/python3.8/concurrent/futures/_base.py", line 389, in __get_result
    raise self._exception
  File "/opt/conda/lib/python3.8/concurrent/futures/_base.py", line 328, in _invoke_callbacks
    callback(self)
  File "/opt/conda/lib/python3.8/site-packages/nipype/pipeline/plugins/multiproc.py", line 159, in _async_callback
    result = args.result()
  File "/opt/conda/lib/python3.8/concurrent/futures/_base.py", line 437, in result
    return self.__get_result()
  File "/opt/conda/lib/python3.8/concurrent/futures/_base.py", line 389, in __get_result
    raise self._exception
  File "/opt/conda/lib/python3.8/concurrent/futures/_base.py", line 328, in _invoke_callbacks
    callback(self)
  File "/opt/conda/lib/python3.8/site-packages/nipype/pipeline/plugins/multiproc.py", line 159, in _async_callback
    result = args.result()
  File "/opt/conda/lib/python3.8/concurrent/futures/_base.py", line 437, in result
    return self.__get_result()
  File "/opt/conda/lib/python3.8/concurrent/futures/_base.py", line 389, in __get_result
    raise self._exception
concurrent.futures.process.BrokenProcessPool: A process in the process pool was terminated abruptly while the future was running or pending.
exception calling callback for <Future at 0x7fa01d003190 state=finished raised BrokenProcessPool>
Traceback (most recent call last):
  File "/opt/conda/lib/python3.8/concurrent/futures/_base.py", line 328, in _invoke_callbacks
    callback(self)
  File "/opt/conda/lib/python3.8/site-packages/nipype/pipeline/plugins/multiproc.py", line 159, in _async_callback
    result = args.result()
  File "/opt/conda/lib/python3.8/concurrent/futures/_base.py", line 437, in result
    return self.__get_result()
  File "/opt/conda/lib/python3.8/concurrent/futures/_base.py", line 389, in __get_result
    raise self._exception
  File "/opt/conda/lib/python3.8/concurrent/futures/_base.py", line 328, in _invoke_callbacks
    callback(self)
  File "/opt/conda/lib/python3.8/site-packages/nipype/pipeline/plugins/multiproc.py", line 159, in _async_callback
    result = args.result()
  File "/opt/conda/lib/python3.8/concurrent/futures/_base.py", line 437, in result
    return self.__get_result()
  File "/opt/conda/lib/python3.8/concurrent/futures/_base.py", line 389, in __get_result
    raise self._exception
  File "/opt/conda/lib/python3.8/concurrent/futures/_base.py", line 328, in _invoke_callbacks
    callback(self)
  File "/opt/conda/lib/python3.8/site-packages/nipype/pipeline/plugins/multiproc.py", line 159, in _async_callback
    result = args.result()
  File "/opt/conda/lib/python3.8/concurrent/futures/_base.py", line 437, in result
    return self.__get_result()
  File "/opt/conda/lib/python3.8/concurrent/futures/_base.py", line 389, in __get_result
    raise self._exception
  File "/opt/conda/lib/python3.8/concurrent/futures/_base.py", line 328, in _invoke_callbacks
    callback(self)
  File "/opt/conda/lib/python3.8/site-packages/nipype/pipeline/plugins/multiproc.py", line 159, in _async_callback
    result = args.result()
  File "/opt/conda/lib/python3.8/concurrent/futures/_base.py", line 437, in result
    return self.__get_result()
  File "/opt/conda/lib/python3.8/concurrent/futures/_base.py", line 389, in __get_result
    raise self._exception
concurrent.futures.process.BrokenProcessPool: A process in the process pool was terminated abruptly while the future was running or pending.
exception calling callback for <Future at 0x7fa01cece100 state=finished raised BrokenProcessPool>
Traceback (most recent call last):
  File "/opt/conda/lib/python3.8/concurrent/futures/_base.py", line 328, in _invoke_callbacks
    callback(self)
  File "/opt/conda/lib/python3.8/site-packages/nipype/pipeline/plugins/multiproc.py", line 159, in _async_callback
    result = args.result()
  File "/opt/conda/lib/python3.8/concurrent/futures/_base.py", line 437, in result
    return self.__get_result()
  File "/opt/conda/lib/python3.8/concurrent/futures/_base.py", line 389, in __get_result
    raise self._exception
  File "/opt/conda/lib/python3.8/concurrent/futures/_base.py", line 328, in _invoke_callbacks
    callback(self)
  File "/opt/conda/lib/python3.8/site-packages/nipype/pipeline/plugins/multiproc.py", line 159, in _async_callback
    result = args.result()
  File "/opt/conda/lib/python3.8/concurrent/futures/_base.py", line 437, in result
    return self.__get_result()
  File "/opt/conda/lib/python3.8/concurrent/futures/_base.py", line 389, in __get_result
    raise self._exception
  File "/opt/conda/lib/python3.8/concurrent/futures/_base.py", line 328, in _invoke_callbacks
    callback(self)
  File "/opt/conda/lib/python3.8/site-packages/nipype/pipeline/plugins/multiproc.py", line 159, in _async_callback
    result = args.result()
  File "/opt/conda/lib/python3.8/concurrent/futures/_base.py", line 437, in result
    return self.__get_result()
  File "/opt/conda/lib/python3.8/concurrent/futures/_base.py", line 389, in __get_result
    raise self._exception
  File "/opt/conda/lib/python3.8/concurrent/futures/_base.py", line 328, in _invoke_callbacks
    callback(self)
  File "/opt/conda/lib/python3.8/site-packages/nipype/pipeline/plugins/multiproc.py", line 159, in _async_callback
    result = args.result()
  File "/opt/conda/lib/python3.8/concurrent/futures/_base.py", line 437, in result
    return self.__get_result()
  File "/opt/conda/lib/python3.8/concurrent/futures/_base.py", line 389, in __get_result
    raise self._exception
  File "/opt/conda/lib/python3.8/concurrent/futures/_base.py", line 328, in _invoke_callbacks
    callback(self)
  File "/opt/conda/lib/python3.8/site-packages/nipype/pipeline/plugins/multiproc.py", line 159, in _async_callback
    result = args.result()
  File "/opt/conda/lib/python3.8/concurrent/futures/_base.py", line 437, in result
    return self.__get_result()
  File "/opt/conda/lib/python3.8/concurrent/futures/_base.py", line 389, in __get_result
    raise self._exception
concurrent.futures.process.BrokenProcessPool: A process in the process pool was terminated abruptly while the future was running or pending.
exception calling callback for <Future at 0x7fa01ce8f250 state=finished raised BrokenProcessPool>
Traceback (most recent call last):
  File "/opt/conda/lib/python3.8/concurrent/futures/_base.py", line 328, in _invoke_callbacks
    callback(self)
  File "/opt/conda/lib/python3.8/site-packages/nipype/pipeline/plugins/multiproc.py", line 159, in _async_callback
    result = args.result()
  File "/opt/conda/lib/python3.8/concurrent/futures/_base.py", line 437, in result
    return self.__get_result()
  File "/opt/conda/lib/python3.8/concurrent/futures/_base.py", line 389, in __get_result
    raise self._exception
  File "/opt/conda/lib/python3.8/concurrent/futures/_base.py", line 328, in _invoke_callbacks
    callback(self)
  File "/opt/conda/lib/python3.8/site-packages/nipype/pipeline/plugins/multiproc.py", line 159, in _async_callback
    result = args.result()
  File "/opt/conda/lib/python3.8/concurrent/futures/_base.py", line 437, in result
    return self.__get_result()
  File "/opt/conda/lib/python3.8/concurrent/futures/_base.py", line 389, in __get_result
    raise self._exception
  File "/opt/conda/lib/python3.8/concurrent/futures/_base.py", line 328, in _invoke_callbacks
    callback(self)
  File "/opt/conda/lib/python3.8/site-packages/nipype/pipeline/plugins/multiproc.py", line 159, in _async_callback
    result = args.result()
  File "/opt/conda/lib/python3.8/concurrent/futures/_base.py", line 437, in result
    return self.__get_result()
  File "/opt/conda/lib/python3.8/concurrent/futures/_base.py", line 389, in __get_result
    raise self._exception
  File "/opt/conda/lib/python3.8/concurrent/futures/_base.py", line 328, in _invoke_callbacks
    callback(self)
  File "/opt/conda/lib/python3.8/site-packages/nipype/pipeline/plugins/multiproc.py", line 159, in _async_callback
    result = args.result()
  File "/opt/conda/lib/python3.8/concurrent/futures/_base.py", line 437, in result
    return self.__get_result()
  File "/opt/conda/lib/python3.8/concurrent/futures/_base.py", line 389, in __get_result
    raise self._exception
  File "/opt/conda/lib/python3.8/concurrent/futures/_base.py", line 328, in _invoke_callbacks
    callback(self)
  File "/opt/conda/lib/python3.8/site-packages/nipype/pipeline/plugins/multiproc.py", line 159, in _async_callback
    result = args.result()
  File "/opt/conda/lib/python3.8/concurrent/futures/_base.py", line 437, in result
    return self.__get_result()
  File "/opt/conda/lib/python3.8/concurrent/futures/_base.py", line 389, in __get_result
    raise self._exception
  File "/opt/conda/lib/python3.8/concurrent/futures/_base.py", line 328, in _invoke_callbacks
    callback(self)
  File "/opt/conda/lib/python3.8/site-packages/nipype/pipeline/plugins/multiproc.py", line 159, in _async_callback
    result = args.result()
  File "/opt/conda/lib/python3.8/concurrent/futures/_base.py", line 437, in result
    return self.__get_result()
  File "/opt/conda/lib/python3.8/concurrent/futures/_base.py", line 389, in __get_result
    raise self._exception
concurrent.futures.process.BrokenProcessPool: A process in the process pool was terminated abruptly while the future was running or pending.
exception calling callback for <Future at 0x7fa01ce8fbe0 state=finished raised BrokenProcessPool>
Traceback (most recent call last):
  File "/opt/conda/lib/python3.8/concurrent/futures/_base.py", line 328, in _invoke_callbacks
    callback(self)
  File "/opt/conda/lib/python3.8/site-packages/nipype/pipeline/plugins/multiproc.py", line 159, in _async_callback
    result = args.result()
  File "/opt/conda/lib/python3.8/concurrent/futures/_base.py", line 437, in result
    return self.__get_result()
  File "/opt/conda/lib/python3.8/concurrent/futures/_base.py", line 389, in __get_result
    raise self._exception
  File "/opt/conda/lib/python3.8/concurrent/futures/_base.py", line 328, in _invoke_callbacks
    callback(self)
  File "/opt/conda/lib/python3.8/site-packages/nipype/pipeline/plugins/multiproc.py", line 159, in _async_callback
    result = args.result()
  File "/opt/conda/lib/python3.8/concurrent/futures/_base.py", line 437, in result
    return self.__get_result()
  File "/opt/conda/lib/python3.8/concurrent/futures/_base.py", line 389, in __get_result
    raise self._exception
  File "/opt/conda/lib/python3.8/concurrent/futures/_base.py", line 328, in _invoke_callbacks
    callback(self)
  File "/opt/conda/lib/python3.8/site-packages/nipype/pipeline/plugins/multiproc.py", line 159, in _async_callback
    result = args.result()
  File "/opt/conda/lib/python3.8/concurrent/futures/_base.py", line 437, in result
    return self.__get_result()
  File "/opt/conda/lib/python3.8/concurrent/futures/_base.py", line 389, in __get_result
    raise self._exception
  File "/opt/conda/lib/python3.8/concurrent/futures/_base.py", line 328, in _invoke_callbacks
    callback(self)
  File "/opt/conda/lib/python3.8/site-packages/nipype/pipeline/plugins/multiproc.py", line 159, in _async_callback
    result = args.result()
  File "/opt/conda/lib/python3.8/concurrent/futures/_base.py", line 437, in result
    return self.__get_result()
  File "/opt/conda/lib/python3.8/concurrent/futures/_base.py", line 389, in __get_result
    raise self._exception
  File "/opt/conda/lib/python3.8/concurrent/futures/_base.py", line 328, in _invoke_callbacks
    callback(self)
  File "/opt/conda/lib/python3.8/site-packages/nipype/pipeline/plugins/multiproc.py", line 159, in _async_callback
    result = args.result()
  File "/opt/conda/lib/python3.8/concurrent/futures/_base.py", line 437, in result
    return self.__get_result()
  File "/opt/conda/lib/python3.8/concurrent/futures/_base.py", line 389, in __get_result
    raise self._exception
  File "/opt/conda/lib/python3.8/concurrent/futures/_base.py", line 328, in _invoke_callbacks
    callback(self)
  File "/opt/conda/lib/python3.8/site-packages/nipype/pipeline/plugins/multiproc.py", line 159, in _async_callback
    result = args.result()
  File "/opt/conda/lib/python3.8/concurrent/futures/_base.py", line 437, in result
    return self.__get_result()
  File "/opt/conda/lib/python3.8/concurrent/futures/_base.py", line 389, in __get_result
    raise self._exception
  File "/opt/conda/lib/python3.8/concurrent/futures/_base.py", line 328, in _invoke_callbacks
    callback(self)
  File "/opt/conda/lib/python3.8/site-packages/nipype/pipeline/plugins/multiproc.py", line 159, in _async_callback
    result = args.result()
  File "/opt/conda/lib/python3.8/concurrent/futures/_base.py", line 437, in result
    return self.__get_result()
  File "/opt/conda/lib/python3.8/concurrent/futures/_base.py", line 389, in __get_result
    raise self._exception
concurrent.futures.process.BrokenProcessPool: A process in the process pool was terminated abruptly while the future was running or pending.
exception calling callback for <Future at 0x7fa01ceb4d60 state=finished raised BrokenProcessPool>
Traceback (most recent call last):
  File "/opt/conda/lib/python3.8/concurrent/futures/_base.py", line 328, in _invoke_callbacks
    callback(self)
  File "/opt/conda/lib/python3.8/site-packages/nipype/pipeline/plugins/multiproc.py", line 159, in _async_callback
    result = args.result()
  File "/opt/conda/lib/python3.8/concurrent/futures/_base.py", line 437, in result
    return self.__get_result()
  File "/opt/conda/lib/python3.8/concurrent/futures/_base.py", line 389, in __get_result
    raise self._exception
  File "/opt/conda/lib/python3.8/concurrent/futures/_base.py", line 328, in _invoke_callbacks
    callback(self)
  File "/opt/conda/lib/python3.8/site-packages/nipype/pipeline/plugins/multiproc.py", line 159, in _async_callback
    result = args.result()
  File "/opt/conda/lib/python3.8/concurrent/futures/_base.py", line 437, in result
    return self.__get_result()
  File "/opt/conda/lib/python3.8/concurrent/futures/_base.py", line 389, in __get_result
    raise self._exception
  File "/opt/conda/lib/python3.8/concurrent/futures/_base.py", line 328, in _invoke_callbacks
    callback(self)
  File "/opt/conda/lib/python3.8/site-packages/nipype/pipeline/plugins/multiproc.py", line 159, in _async_callback
    result = args.result()
  File "/opt/conda/lib/python3.8/concurrent/futures/_base.py", line 437, in result
    return self.__get_result()
  File "/opt/conda/lib/python3.8/concurrent/futures/_base.py", line 389, in __get_result
    raise self._exception
  File "/opt/conda/lib/python3.8/concurrent/futures/_base.py", line 328, in _invoke_callbacks
    callback(self)
  File "/opt/conda/lib/python3.8/site-packages/nipype/pipeline/plugins/multiproc.py", line 159, in _async_callback
    result = args.result()
  File "/opt/conda/lib/python3.8/concurrent/futures/_base.py", line 437, in result
    return self.__get_result()
  File "/opt/conda/lib/python3.8/concurrent/futures/_base.py", line 389, in __get_result
    raise self._exception
  File "/opt/conda/lib/python3.8/concurrent/futures/_base.py", line 328, in _invoke_callbacks
    callback(self)
  File "/opt/conda/lib/python3.8/site-packages/nipype/pipeline/plugins/multiproc.py", line 159, in _async_callback
    result = args.result()
  File "/opt/conda/lib/python3.8/concurrent/futures/_base.py", line 437, in result
    return self.__get_result()
  File "/opt/conda/lib/python3.8/concurrent/futures/_base.py", line 389, in __get_result
    raise self._exception
  File "/opt/conda/lib/python3.8/concurrent/futures/_base.py", line 328, in _invoke_callbacks
    callback(self)
  File "/opt/conda/lib/python3.8/site-packages/nipype/pipeline/plugins/multiproc.py", line 159, in _async_callback
    result = args.result()
  File "/opt/conda/lib/python3.8/concurrent/futures/_base.py", line 437, in result
    return self.__get_result()
  File "/opt/conda/lib/python3.8/concurrent/futures/_base.py", line 389, in __get_result
    raise self._exception
  File "/opt/conda/lib/python3.8/concurrent/futures/_base.py", line 328, in _invoke_callbacks
    callback(self)
  File "/opt/conda/lib/python3.8/site-packages/nipype/pipeline/plugins/multiproc.py", line 159, in _async_callback
    result = args.result()
  File "/opt/conda/lib/python3.8/concurrent/futures/_base.py", line 437, in result
    return self.__get_result()
  File "/opt/conda/lib/python3.8/concurrent/futures/_base.py", line 389, in __get_result
    raise self._exception
  File "/opt/conda/lib/python3.8/concurrent/futures/_base.py", line 328, in _invoke_callbacks
    callback(self)
  File "/opt/conda/lib/python3.8/site-packages/nipype/pipeline/plugins/multiproc.py", line 159, in _async_callback
    result = args.result()
  File "/opt/conda/lib/python3.8/concurrent/futures/_base.py", line 437, in result
    return self.__get_result()
  File "/opt/conda/lib/python3.8/concurrent/futures/_base.py", line 389, in __get_result
    raise self._exception
concurrent.futures.process.BrokenProcessPool: A process in the process pool was terminated abruptly while the future was running or pending.
exception calling callback for <Future at 0x7fa01d1b6af0 state=finished raised BrokenProcessPool>
Traceback (most recent call last):
  File "/opt/conda/lib/python3.8/concurrent/futures/_base.py", line 328, in _invoke_callbacks
    callback(self)
  File "/opt/conda/lib/python3.8/site-packages/nipype/pipeline/plugins/multiproc.py", line 159, in _async_callback
    result = args.result()
  File "/opt/conda/lib/python3.8/concurrent/futures/_base.py", line 437, in result
    return self.__get_result()
  File "/opt/conda/lib/python3.8/concurrent/futures/_base.py", line 389, in __get_result
    raise self._exception
  File "/opt/conda/lib/python3.8/concurrent/futures/_base.py", line 328, in _invoke_callbacks
    callback(self)
  File "/opt/conda/lib/python3.8/site-packages/nipype/pipeline/plugins/multiproc.py", line 159, in _async_callback
    result = args.result()
  File "/opt/conda/lib/python3.8/concurrent/futures/_base.py", line 437, in result
    return self.__get_result()
  File "/opt/conda/lib/python3.8/concurrent/futures/_base.py", line 389, in __get_result
    raise self._exception
  File "/opt/conda/lib/python3.8/concurrent/futures/_base.py", line 328, in _invoke_callbacks
    callback(self)
  File "/opt/conda/lib/python3.8/site-packages/nipype/pipeline/plugins/multiproc.py", line 159, in _async_callback
    result = args.result()
  File "/opt/conda/lib/python3.8/concurrent/futures/_base.py", line 437, in result
    return self.__get_result()
  File "/opt/conda/lib/python3.8/concurrent/futures/_base.py", line 389, in __get_result
    raise self._exception
  File "/opt/conda/lib/python3.8/concurrent/futures/_base.py", line 328, in _invoke_callbacks
    callback(self)
  File "/opt/conda/lib/python3.8/site-packages/nipype/pipeline/plugins/multiproc.py", line 159, in _async_callback
    result = args.result()
  File "/opt/conda/lib/python3.8/concurrent/futures/_base.py", line 437, in result
    return self.__get_result()
  File "/opt/conda/lib/python3.8/concurrent/futures/_base.py", line 389, in __get_result
    raise self._exception
  File "/opt/conda/lib/python3.8/concurrent/futures/_base.py", line 328, in _invoke_callbacks
    callback(self)
  File "/opt/conda/lib/python3.8/site-packages/nipype/pipeline/plugins/multiproc.py", line 159, in _async_callback
    result = args.result()
  File "/opt/conda/lib/python3.8/concurrent/futures/_base.py", line 437, in result
    return self.__get_result()
  File "/opt/conda/lib/python3.8/concurrent/futures/_base.py", line 389, in __get_result
    raise self._exception
  File "/opt/conda/lib/python3.8/concurrent/futures/_base.py", line 328, in _invoke_callbacks
    callback(self)
  File "/opt/conda/lib/python3.8/site-packages/nipype/pipeline/plugins/multiproc.py", line 159, in _async_callback
    result = args.result()
  File "/opt/conda/lib/python3.8/concurrent/futures/_base.py", line 437, in result
    return self.__get_result()
  File "/opt/conda/lib/python3.8/concurrent/futures/_base.py", line 389, in __get_result
    raise self._exception
  File "/opt/conda/lib/python3.8/concurrent/futures/_base.py", line 328, in _invoke_callbacks
    callback(self)
  File "/opt/conda/lib/python3.8/site-packages/nipype/pipeline/plugins/multiproc.py", line 159, in _async_callback
    result = args.result()
  File "/opt/conda/lib/python3.8/concurrent/futures/_base.py", line 437, in result
    return self.__get_result()
  File "/opt/conda/lib/python3.8/concurrent/futures/_base.py", line 389, in __get_result
    raise self._exception
  File "/opt/conda/lib/python3.8/concurrent/futures/_base.py", line 328, in _invoke_callbacks
    callback(self)
  File "/opt/conda/lib/python3.8/site-packages/nipype/pipeline/plugins/multiproc.py", line 159, in _async_callback
    result = args.result()
  File "/opt/conda/lib/python3.8/concurrent/futures/_base.py", line 437, in result
    return self.__get_result()
  File "/opt/conda/lib/python3.8/concurrent/futures/_base.py", line 389, in __get_result
    raise self._exception
  File "/opt/conda/lib/python3.8/concurrent/futures/_base.py", line 328, in _invoke_callbacks
    callback(self)
  File "/opt/conda/lib/python3.8/site-packages/nipype/pipeline/plugins/multiproc.py", line 159, in _async_callback
    result = args.result()
  File "/opt/conda/lib/python3.8/concurrent/futures/_base.py", line 437, in result
    return self.__get_result()
  File "/opt/conda/lib/python3.8/concurrent/futures/_base.py", line 389, in __get_result
    raise self._exception
concurrent.futures.process.BrokenProcessPool: A process in the process pool was terminated abruptly while the future was running or pending.
exception calling callback for <Future at 0x7fa01ce8f3a0 state=finished raised BrokenProcessPool>
Traceback (most recent call last):
  File "/opt/conda/lib/python3.8/concurrent/futures/_base.py", line 328, in _invoke_callbacks
    callback(self)
  File "/opt/conda/lib/python3.8/site-packages/nipype/pipeline/plugins/multiproc.py", line 159, in _async_callback
    result = args.result()
  File "/opt/conda/lib/python3.8/concurrent/futures/_base.py", line 437, in result
    return self.__get_result()
  File "/opt/conda/lib/python3.8/concurrent/futures/_base.py", line 389, in __get_result
    raise self._exception
  File "/opt/conda/lib/python3.8/concurrent/futures/_base.py", line 328, in _invoke_callbacks
    callback(self)
  File "/opt/conda/lib/python3.8/site-packages/nipype/pipeline/plugins/multiproc.py", line 159, in _async_callback
    result = args.result()
  File "/opt/conda/lib/python3.8/concurrent/futures/_base.py", line 437, in result
    return self.__get_result()
  File "/opt/conda/lib/python3.8/concurrent/futures/_base.py", line 389, in __get_result
    raise self._exception
  File "/opt/conda/lib/python3.8/concurrent/futures/_base.py", line 328, in _invoke_callbacks
    callback(self)
  File "/opt/conda/lib/python3.8/site-packages/nipype/pipeline/plugins/multiproc.py", line 159, in _async_callback
    result = args.result()
  File "/opt/conda/lib/python3.8/concurrent/futures/_base.py", line 437, in result
    return self.__get_result()
  File "/opt/conda/lib/python3.8/concurrent/futures/_base.py", line 389, in __get_result
    raise self._exception
  File "/opt/conda/lib/python3.8/concurrent/futures/_base.py", line 328, in _invoke_callbacks
    callback(self)
  File "/opt/conda/lib/python3.8/site-packages/nipype/pipeline/plugins/multiproc.py", line 159, in _async_callback
    result = args.result()
  File "/opt/conda/lib/python3.8/concurrent/futures/_base.py", line 437, in result
    return self.__get_result()
  File "/opt/conda/lib/python3.8/concurrent/futures/_base.py", line 389, in __get_result
    raise self._exception
  File "/opt/conda/lib/python3.8/concurrent/futures/_base.py", line 328, in _invoke_callbacks
    callback(self)
  File "/opt/conda/lib/python3.8/site-packages/nipype/pipeline/plugins/multiproc.py", line 159, in _async_callback
    result = args.result()
  File "/opt/conda/lib/python3.8/concurrent/futures/_base.py", line 437, in result
    return self.__get_result()
  File "/opt/conda/lib/python3.8/concurrent/futures/_base.py", line 389, in __get_result
    raise self._exception
  File "/opt/conda/lib/python3.8/concurrent/futures/_base.py", line 328, in _invoke_callbacks
    callback(self)
  File "/opt/conda/lib/python3.8/site-packages/nipype/pipeline/plugins/multiproc.py", line 159, in _async_callback
    result = args.result()
  File "/opt/conda/lib/python3.8/concurrent/futures/_base.py", line 437, in result
    return self.__get_result()
  File "/opt/conda/lib/python3.8/concurrent/futures/_base.py", line 389, in __get_result
    raise self._exception
  File "/opt/conda/lib/python3.8/concurrent/futures/_base.py", line 328, in _invoke_callbacks
    callback(self)
  File "/opt/conda/lib/python3.8/site-packages/nipype/pipeline/plugins/multiproc.py", line 159, in _async_callback
    result = args.result()
  File "/opt/conda/lib/python3.8/concurrent/futures/_base.py", line 437, in result
    return self.__get_result()
  File "/opt/conda/lib/python3.8/concurrent/futures/_base.py", line 389, in __get_result
    raise self._exception
  File "/opt/conda/lib/python3.8/concurrent/futures/_base.py", line 328, in _invoke_callbacks
    callback(self)
  File "/opt/conda/lib/python3.8/site-packages/nipype/pipeline/plugins/multiproc.py", line 159, in _async_callback
    result = args.result()
  File "/opt/conda/lib/python3.8/concurrent/futures/_base.py", line 437, in result
    return self.__get_result()
  File "/opt/conda/lib/python3.8/concurrent/futures/_base.py", line 389, in __get_result
    raise self._exception
  File "/opt/conda/lib/python3.8/concurrent/futures/_base.py", line 328, in _invoke_callbacks
    callback(self)
  File "/opt/conda/lib/python3.8/site-packages/nipype/pipeline/plugins/multiproc.py", line 159, in _async_callback
    result = args.result()
  File "/opt/conda/lib/python3.8/concurrent/futures/_base.py", line 437, in result
    return self.__get_result()
  File "/opt/conda/lib/python3.8/concurrent/futures/_base.py", line 389, in __get_result
    raise self._exception
  File "/opt/conda/lib/python3.8/concurrent/futures/_base.py", line 328, in _invoke_callbacks
    callback(self)
  File "/opt/conda/lib/python3.8/site-packages/nipype/pipeline/plugins/multiproc.py", line 159, in _async_callback
    result = args.result()
  File "/opt/conda/lib/python3.8/concurrent/futures/_base.py", line 437, in result
    return self.__get_result()
  File "/opt/conda/lib/python3.8/concurrent/futures/_base.py", line 389, in __get_result
    raise self._exception
concurrent.futures.process.BrokenProcessPool: A process in the process pool was terminated abruptly while the future was running or pending.
exception calling callback for <Future at 0x7fa01ce8fac0 state=finished raised BrokenProcessPool>
Traceback (most recent call last):
  File "/opt/conda/lib/python3.8/concurrent/futures/_base.py", line 328, in _invoke_callbacks
    callback(self)
  File "/opt/conda/lib/python3.8/site-packages/nipype/pipeline/plugins/multiproc.py", line 159, in _async_callback
    result = args.result()
  File "/opt/conda/lib/python3.8/concurrent/futures/_base.py", line 437, in result
    return self.__get_result()
  File "/opt/conda/lib/python3.8/concurrent/futures/_base.py", line 389, in __get_result
    raise self._exception
  File "/opt/conda/lib/python3.8/concurrent/futures/_base.py", line 328, in _invoke_callbacks
    callback(self)
  File "/opt/conda/lib/python3.8/site-packages/nipype/pipeline/plugins/multiproc.py", line 159, in _async_callback
    result = args.result()
  File "/opt/conda/lib/python3.8/concurrent/futures/_base.py", line 437, in result
    return self.__get_result()
  File "/opt/conda/lib/python3.8/concurrent/futures/_base.py", line 389, in __get_result
    raise self._exception
  File "/opt/conda/lib/python3.8/concurrent/futures/_base.py", line 328, in _invoke_callbacks
    callback(self)
  File "/opt/conda/lib/python3.8/site-packages/nipype/pipeline/plugins/multiproc.py", line 159, in _async_callback
    result = args.result()
  File "/opt/conda/lib/python3.8/concurrent/futures/_base.py", line 437, in result
    return self.__get_result()
  File "/opt/conda/lib/python3.8/concurrent/futures/_base.py", line 389, in __get_result
    raise self._exception
  File "/opt/conda/lib/python3.8/concurrent/futures/_base.py", line 328, in _invoke_callbacks
    callback(self)
  File "/opt/conda/lib/python3.8/site-packages/nipype/pipeline/plugins/multiproc.py", line 159, in _async_callback
    result = args.result()
  File "/opt/conda/lib/python3.8/concurrent/futures/_base.py", line 437, in result
    return self.__get_result()
  File "/opt/conda/lib/python3.8/concurrent/futures/_base.py", line 389, in __get_result
    raise self._exception
  File "/opt/conda/lib/python3.8/concurrent/futures/_base.py", line 328, in _invoke_callbacks
    callback(self)
  File "/opt/conda/lib/python3.8/site-packages/nipype/pipeline/plugins/multiproc.py", line 159, in _async_callback
    result = args.result()
  File "/opt/conda/lib/python3.8/concurrent/futures/_base.py", line 437, in result
    return self.__get_result()
  File "/opt/conda/lib/python3.8/concurrent/futures/_base.py", line 389, in __get_result
    raise self._exception
  File "/opt/conda/lib/python3.8/concurrent/futures/_base.py", line 328, in _invoke_callbacks
    callback(self)
  File "/opt/conda/lib/python3.8/site-packages/nipype/pipeline/plugins/multiproc.py", line 159, in _async_callback
    result = args.result()
  File "/opt/conda/lib/python3.8/concurrent/futures/_base.py", line 437, in result
    return self.__get_result()
  File "/opt/conda/lib/python3.8/concurrent/futures/_base.py", line 389, in __get_result
    raise self._exception
  File "/opt/conda/lib/python3.8/concurrent/futures/_base.py", line 328, in _invoke_callbacks
    callback(self)
  File "/opt/conda/lib/python3.8/site-packages/nipype/pipeline/plugins/multiproc.py", line 159, in _async_callback
    result = args.result()
  File "/opt/conda/lib/python3.8/concurrent/futures/_base.py", line 437, in result
    return self.__get_result()
  File "/opt/conda/lib/python3.8/concurrent/futures/_base.py", line 389, in __get_result
    raise self._exception
  File "/opt/conda/lib/python3.8/concurrent/futures/_base.py", line 328, in _invoke_callbacks
    callback(self)
  File "/opt/conda/lib/python3.8/site-packages/nipype/pipeline/plugins/multiproc.py", line 159, in _async_callback
    result = args.result()
  File "/opt/conda/lib/python3.8/concurrent/futures/_base.py", line 437, in result
    return self.__get_result()
  File "/opt/conda/lib/python3.8/concurrent/futures/_base.py", line 389, in __get_result
    raise self._exception
  File "/opt/conda/lib/python3.8/concurrent/futures/_base.py", line 328, in _invoke_callbacks
    callback(self)
  File "/opt/conda/lib/python3.8/site-packages/nipype/pipeline/plugins/multiproc.py", line 159, in _async_callback
    result = args.result()
  File "/opt/conda/lib/python3.8/concurrent/futures/_base.py", line 437, in result
    return self.__get_result()
  File "/opt/conda/lib/python3.8/concurrent/futures/_base.py", line 389, in __get_result
    raise self._exception
  File "/opt/conda/lib/python3.8/concurrent/futures/_base.py", line 328, in _invoke_callbacks
    callback(self)
  File "/opt/conda/lib/python3.8/site-packages/nipype/pipeline/plugins/multiproc.py", line 159, in _async_callback
    result = args.result()
  File "/opt/conda/lib/python3.8/concurrent/futures/_base.py", line 437, in result
    return self.__get_result()
  File "/opt/conda/lib/python3.8/concurrent/futures/_base.py", line 389, in __get_result
    raise self._exception
  File "/opt/conda/lib/python3.8/concurrent/futures/_base.py", line 328, in _invoke_callbacks
    callback(self)
  File "/opt/conda/lib/python3.8/site-packages/nipype/pipeline/plugins/multiproc.py", line 159, in _async_callback
    result = args.result()
  File "/opt/conda/lib/python3.8/concurrent/futures/_base.py", line 437, in result
    return self.__get_result()
  File "/opt/conda/lib/python3.8/concurrent/futures/_base.py", line 389, in __get_result
    raise self._exception
concurrent.futures.process.BrokenProcessPool: A process in the process pool was terminated abruptly while the future was running or pending.
exception calling callback for <Future at 0x7fa01d003be0 state=finished raised BrokenProcessPool>
Traceback (most recent call last):
  File "/opt/conda/lib/python3.8/concurrent/futures/_base.py", line 328, in _invoke_callbacks
    callback(self)
  File "/opt/conda/lib/python3.8/site-packages/nipype/pipeline/plugins/multiproc.py", line 159, in _async_callback
    result = args.result()
  File "/opt/conda/lib/python3.8/concurrent/futures/_base.py", line 437, in result
    return self.__get_result()
  File "/opt/conda/lib/python3.8/concurrent/futures/_base.py", line 389, in __get_result
    raise self._exception
  File "/opt/conda/lib/python3.8/concurrent/futures/_base.py", line 328, in _invoke_callbacks
    callback(self)
  File "/opt/conda/lib/python3.8/site-packages/nipype/pipeline/plugins/multiproc.py", line 159, in _async_callback
    result = args.result()
  File "/opt/conda/lib/python3.8/concurrent/futures/_base.py", line 437, in result
    return self.__get_result()
  File "/opt/conda/lib/python3.8/concurrent/futures/_base.py", line 389, in __get_result
    raise self._exception
  File "/opt/conda/lib/python3.8/concurrent/futures/_base.py", line 328, in _invoke_callbacks
    callback(self)
  File "/opt/conda/lib/python3.8/site-packages/nipype/pipeline/plugins/multiproc.py", line 159, in _async_callback
    result = args.result()
  File "/opt/conda/lib/python3.8/concurrent/futures/_base.py", line 437, in result
    return self.__get_result()
  File "/opt/conda/lib/python3.8/concurrent/futures/_base.py", line 389, in __get_result
    raise self._exception
  File "/opt/conda/lib/python3.8/concurrent/futures/_base.py", line 328, in _invoke_callbacks
    callback(self)
  File "/opt/conda/lib/python3.8/site-packages/nipype/pipeline/plugins/multiproc.py", line 159, in _async_callback
    result = args.result()
  File "/opt/conda/lib/python3.8/concurrent/futures/_base.py", line 437, in result
    return self.__get_result()
  File "/opt/conda/lib/python3.8/concurrent/futures/_base.py", line 389, in __get_result
    raise self._exception
  File "/opt/conda/lib/python3.8/concurrent/futures/_base.py", line 328, in _invoke_callbacks
    callback(self)
  File "/opt/conda/lib/python3.8/site-packages/nipype/pipeline/plugins/multiproc.py", line 159, in _async_callback
    result = args.result()
  File "/opt/conda/lib/python3.8/concurrent/futures/_base.py", line 437, in result
    return self.__get_result()
  File "/opt/conda/lib/python3.8/concurrent/futures/_base.py", line 389, in __get_result
    raise self._exception
  File "/opt/conda/lib/python3.8/concurrent/futures/_base.py", line 328, in _invoke_callbacks
    callback(self)
  File "/opt/conda/lib/python3.8/site-packages/nipype/pipeline/plugins/multiproc.py", line 159, in _async_callback
    result = args.result()
  File "/opt/conda/lib/python3.8/concurrent/futures/_base.py", line 437, in result
    return self.__get_result()
  File "/opt/conda/lib/python3.8/concurrent/futures/_base.py", line 389, in __get_result
    raise self._exception
  File "/opt/conda/lib/python3.8/concurrent/futures/_base.py", line 328, in _invoke_callbacks
    callback(self)
  File "/opt/conda/lib/python3.8/site-packages/nipype/pipeline/plugins/multiproc.py", line 159, in _async_callback
    result = args.result()
  File "/opt/conda/lib/python3.8/concurrent/futures/_base.py", line 437, in result
    return self.__get_result()
  File "/opt/conda/lib/python3.8/concurrent/futures/_base.py", line 389, in __get_result
    raise self._exception
  File "/opt/conda/lib/python3.8/concurrent/futures/_base.py", line 328, in _invoke_callbacks
    callback(self)
  File "/opt/conda/lib/python3.8/site-packages/nipype/pipeline/plugins/multiproc.py", line 159, in _async_callback
    result = args.result()
  File "/opt/conda/lib/python3.8/concurrent/futures/_base.py", line 437, in result
    return self.__get_result()
  File "/opt/conda/lib/python3.8/concurrent/futures/_base.py", line 389, in __get_result
    raise self._exception
  File "/opt/conda/lib/python3.8/concurrent/futures/_base.py", line 328, in _invoke_callbacks
    callback(self)
  File "/opt/conda/lib/python3.8/site-packages/nipype/pipeline/plugins/multiproc.py", line 159, in _async_callback
    result = args.result()
  File "/opt/conda/lib/python3.8/concurrent/futures/_base.py", line 437, in result
    return self.__get_result()
  File "/opt/conda/lib/python3.8/concurrent/futures/_base.py", line 389, in __get_result
    raise self._exception
  File "/opt/conda/lib/python3.8/concurrent/futures/_base.py", line 328, in _invoke_callbacks
    callback(self)
  File "/opt/conda/lib/python3.8/site-packages/nipype/pipeline/plugins/multiproc.py", line 159, in _async_callback
    result = args.result()
  File "/opt/conda/lib/python3.8/concurrent/futures/_base.py", line 437, in result
    return self.__get_result()
  File "/opt/conda/lib/python3.8/concurrent/futures/_base.py", line 389, in __get_result
    raise self._exception
  File "/opt/conda/lib/python3.8/concurrent/futures/_base.py", line 328, in _invoke_callbacks
    callback(self)
  File "/opt/conda/lib/python3.8/site-packages/nipype/pipeline/plugins/multiproc.py", line 159, in _async_callback
    result = args.result()
  File "/opt/conda/lib/python3.8/concurrent/futures/_base.py", line 437, in result
    return self.__get_result()
  File "/opt/conda/lib/python3.8/concurrent/futures/_base.py", line 389, in __get_result
    raise self._exception
  File "/opt/conda/lib/python3.8/concurrent/futures/_base.py", line 328, in _invoke_callbacks
    callback(self)
  File "/opt/conda/lib/python3.8/site-packages/nipype/pipeline/plugins/multiproc.py", line 159, in _async_callback
    result = args.result()
  File "/opt/conda/lib/python3.8/concurrent/futures/_base.py", line 437, in result
    return self.__get_result()
  File "/opt/conda/lib/python3.8/concurrent/futures/_base.py", line 389, in __get_result
    raise self._exception
concurrent.futures.process.BrokenProcessPool: A process in the process pool was terminated abruptly while the future was running or pending.
exception calling callback for <Future at 0x7fa01cf22220 state=finished raised BrokenProcessPool>
Traceback (most recent call last):
  File "/opt/conda/lib/python3.8/concurrent/futures/_base.py", line 328, in _invoke_callbacks
    callback(self)
  File "/opt/conda/lib/python3.8/site-packages/nipype/pipeline/plugins/multiproc.py", line 159, in _async_callback
    result = args.result()
  File "/opt/conda/lib/python3.8/concurrent/futures/_base.py", line 437, in result
    return self.__get_result()
  File "/opt/conda/lib/python3.8/concurrent/futures/_base.py", line 389, in __get_result
    raise self._exception
  File "/opt/conda/lib/python3.8/concurrent/futures/_base.py", line 328, in _invoke_callbacks
    callback(self)
  File "/opt/conda/lib/python3.8/site-packages/nipype/pipeline/plugins/multiproc.py", line 159, in _async_callback
    result = args.result()
  File "/opt/conda/lib/python3.8/concurrent/futures/_base.py", line 437, in result
    return self.__get_result()
  File "/opt/conda/lib/python3.8/concurrent/futures/_base.py", line 389, in __get_result
    raise self._exception
  File "/opt/conda/lib/python3.8/concurrent/futures/_base.py", line 328, in _invoke_callbacks
    callback(self)
  File "/opt/conda/lib/python3.8/site-packages/nipype/pipeline/plugins/multiproc.py", line 159, in _async_callback
    result = args.result()
  File "/opt/conda/lib/python3.8/concurrent/futures/_base.py", line 437, in result
    return self.__get_result()
  File "/opt/conda/lib/python3.8/concurrent/futures/_base.py", line 389, in __get_result
    raise self._exception
  File "/opt/conda/lib/python3.8/concurrent/futures/_base.py", line 328, in _invoke_callbacks
    callback(self)
  File "/opt/conda/lib/python3.8/site-packages/nipype/pipeline/plugins/multiproc.py", line 159, in _async_callback
    result = args.result()
  File "/opt/conda/lib/python3.8/concurrent/futures/_base.py", line 437, in result
    return self.__get_result()
  File "/opt/conda/lib/python3.8/concurrent/futures/_base.py", line 389, in __get_result
    raise self._exception
  File "/opt/conda/lib/python3.8/concurrent/futures/_base.py", line 328, in _invoke_callbacks
    callback(self)
  File "/opt/conda/lib/python3.8/site-packages/nipype/pipeline/plugins/multiproc.py", line 159, in _async_callback
    result = args.result()
  File "/opt/conda/lib/python3.8/concurrent/futures/_base.py", line 437, in result
    return self.__get_result()
  File "/opt/conda/lib/python3.8/concurrent/futures/_base.py", line 389, in __get_result
    raise self._exception
  File "/opt/conda/lib/python3.8/concurrent/futures/_base.py", line 328, in _invoke_callbacks
    callback(self)
  File "/opt/conda/lib/python3.8/site-packages/nipype/pipeline/plugins/multiproc.py", line 159, in _async_callback
    result = args.result()
  File "/opt/conda/lib/python3.8/concurrent/futures/_base.py", line 437, in result
    return self.__get_result()
  File "/opt/conda/lib/python3.8/concurrent/futures/_base.py", line 389, in __get_result
    raise self._exception
  File "/opt/conda/lib/python3.8/concurrent/futures/_base.py", line 328, in _invoke_callbacks
    callback(self)
  File "/opt/conda/lib/python3.8/site-packages/nipype/pipeline/plugins/multiproc.py", line 159, in _async_callback
    result = args.result()
  File "/opt/conda/lib/python3.8/concurrent/futures/_base.py", line 437, in result
    return self.__get_result()
  File "/opt/conda/lib/python3.8/concurrent/futures/_base.py", line 389, in __get_result
    raise self._exception
  File "/opt/conda/lib/python3.8/concurrent/futures/_base.py", line 328, in _invoke_callbacks
    callback(self)
  File "/opt/conda/lib/python3.8/site-packages/nipype/pipeline/plugins/multiproc.py", line 159, in _async_callback
    result = args.result()
  File "/opt/conda/lib/python3.8/concurrent/futures/_base.py", line 437, in result
    return self.__get_result()
  File "/opt/conda/lib/python3.8/concurrent/futures/_base.py", line 389, in __get_result
    raise self._exception
  File "/opt/conda/lib/python3.8/concurrent/futures/_base.py", line 328, in _invoke_callbacks
    callback(self)
  File "/opt/conda/lib/python3.8/site-packages/nipype/pipeline/plugins/multiproc.py", line 159, in _async_callback
    result = args.result()
  File "/opt/conda/lib/python3.8/concurrent/futures/_base.py", line 437, in result
    return self.__get_result()
  File "/opt/conda/lib/python3.8/concurrent/futures/_base.py", line 389, in __get_result
    raise self._exception
  File "/opt/conda/lib/python3.8/concurrent/futures/_base.py", line 328, in _invoke_callbacks
    callback(self)
  File "/opt/conda/lib/python3.8/site-packages/nipype/pipeline/plugins/multiproc.py", line 159, in _async_callback
    result = args.result()
  File "/opt/conda/lib/python3.8/concurrent/futures/_base.py", line 437, in result
    return self.__get_result()
  File "/opt/conda/lib/python3.8/concurrent/futures/_base.py", line 389, in __get_result
    raise self._exception
  File "/opt/conda/lib/python3.8/concurrent/futures/_base.py", line 328, in _invoke_callbacks
    callback(self)
  File "/opt/conda/lib/python3.8/site-packages/nipype/pipeline/plugins/multiproc.py", line 159, in _async_callback
    result = args.result()
  File "/opt/conda/lib/python3.8/concurrent/futures/_base.py", line 437, in result
    return self.__get_result()
  File "/opt/conda/lib/python3.8/concurrent/futures/_base.py", line 389, in __get_result
    raise self._exception
  File "/opt/conda/lib/python3.8/concurrent/futures/_base.py", line 328, in _invoke_callbacks
    callback(self)
  File "/opt/conda/lib/python3.8/site-packages/nipype/pipeline/plugins/multiproc.py", line 159, in _async_callback
    result = args.result()
  File "/opt/conda/lib/python3.8/concurrent/futures/_base.py", line 437, in result
    return self.__get_result()
  File "/opt/conda/lib/python3.8/concurrent/futures/_base.py", line 389, in __get_result
    raise self._exception
  File "/opt/conda/lib/python3.8/concurrent/futures/_base.py", line 328, in _invoke_callbacks
    callback(self)
  File "/opt/conda/lib/python3.8/site-packages/nipype/pipeline/plugins/multiproc.py", line 159, in _async_callback
    result = args.result()
  File "/opt/conda/lib/python3.8/concurrent/futures/_base.py", line 437, in result
    return self.__get_result()
  File "/opt/conda/lib/python3.8/concurrent/futures/_base.py", line 389, in __get_result
    raise self._exception
concurrent.futures.process.BrokenProcessPool: A process in the process pool was terminated abruptly while the future was running or pending.
exception calling callback for <Future at 0x7fa01cf22130 state=finished raised BrokenProcessPool>
Traceback (most recent call last):
  File "/opt/conda/lib/python3.8/concurrent/futures/_base.py", line 328, in _invoke_callbacks
    callback(self)
  File "/opt/conda/lib/python3.8/site-packages/nipype/pipeline/plugins/multiproc.py", line 159, in _async_callback
    result = args.result()
  File "/opt/conda/lib/python3.8/concurrent/futures/_base.py", line 437, in result
    return self.__get_result()
  File "/opt/conda/lib/python3.8/concurrent/futures/_base.py", line 389, in __get_result
    raise self._exception
  File "/opt/conda/lib/python3.8/concurrent/futures/_base.py", line 328, in _invoke_callbacks
    callback(self)
  File "/opt/conda/lib/python3.8/site-packages/nipype/pipeline/plugins/multiproc.py", line 159, in _async_callback
    result = args.result()
  File "/opt/conda/lib/python3.8/concurrent/futures/_base.py", line 437, in result
    return self.__get_result()
  File "/opt/conda/lib/python3.8/concurrent/futures/_base.py", line 389, in __get_result
    raise self._exception
  File "/opt/conda/lib/python3.8/concurrent/futures/_base.py", line 328, in _invoke_callbacks
    callback(self)
  File "/opt/conda/lib/python3.8/site-packages/nipype/pipeline/plugins/multiproc.py", line 159, in _async_callback
    result = args.result()
  File "/opt/conda/lib/python3.8/concurrent/futures/_base.py", line 437, in result
    return self.__get_result()
  File "/opt/conda/lib/python3.8/concurrent/futures/_base.py", line 389, in __get_result
    raise self._exception
  File "/opt/conda/lib/python3.8/concurrent/futures/_base.py", line 328, in _invoke_callbacks
    callback(self)
  File "/opt/conda/lib/python3.8/site-packages/nipype/pipeline/plugins/multiproc.py", line 159, in _async_callback
    result = args.result()
  File "/opt/conda/lib/python3.8/concurrent/futures/_base.py", line 437, in result
    return self.__get_result()
  File "/opt/conda/lib/python3.8/concurrent/futures/_base.py", line 389, in __get_result
    raise self._exception
  File "/opt/conda/lib/python3.8/concurrent/futures/_base.py", line 328, in _invoke_callbacks
    callback(self)
  File "/opt/conda/lib/python3.8/site-packages/nipype/pipeline/plugins/multiproc.py", line 159, in _async_callback
    result = args.result()
  File "/opt/conda/lib/python3.8/concurrent/futures/_base.py", line 437, in result
    return self.__get_result()
  File "/opt/conda/lib/python3.8/concurrent/futures/_base.py", line 389, in __get_result
    raise self._exception
  File "/opt/conda/lib/python3.8/concurrent/futures/_base.py", line 328, in _invoke_callbacks
    callback(self)
  File "/opt/conda/lib/python3.8/site-packages/nipype/pipeline/plugins/multiproc.py", line 159, in _async_callback
    result = args.result()
  File "/opt/conda/lib/python3.8/concurrent/futures/_base.py", line 437, in result
    return self.__get_result()
  File "/opt/conda/lib/python3.8/concurrent/futures/_base.py", line 389, in __get_result
    raise self._exception
  File "/opt/conda/lib/python3.8/concurrent/futures/_base.py", line 328, in _invoke_callbacks
    callback(self)
  File "/opt/conda/lib/python3.8/site-packages/nipype/pipeline/plugins/multiproc.py", line 159, in _async_callback
    result = args.result()
  File "/opt/conda/lib/python3.8/concurrent/futures/_base.py", line 437, in result
    return self.__get_result()
  File "/opt/conda/lib/python3.8/concurrent/futures/_base.py", line 389, in __get_result
    raise self._exception
  File "/opt/conda/lib/python3.8/concurrent/futures/_base.py", line 328, in _invoke_callbacks
    callback(self)
  File "/opt/conda/lib/python3.8/site-packages/nipype/pipeline/plugins/multiproc.py", line 159, in _async_callback
    result = args.result()
  File "/opt/conda/lib/python3.8/concurrent/futures/_base.py", line 437, in result
    return self.__get_result()
  File "/opt/conda/lib/python3.8/concurrent/futures/_base.py", line 389, in __get_result
    raise self._exception
  File "/opt/conda/lib/python3.8/concurrent/futures/_base.py", line 328, in _invoke_callbacks
    callback(self)
  File "/opt/conda/lib/python3.8/site-packages/nipype/pipeline/plugins/multiproc.py", line 159, in _async_callback
    result = args.result()
  File "/opt/conda/lib/python3.8/concurrent/futures/_base.py", line 437, in result
    return self.__get_result()
  File "/opt/conda/lib/python3.8/concurrent/futures/_base.py", line 389, in __get_result
    raise self._exception
  File "/opt/conda/lib/python3.8/concurrent/futures/_base.py", line 328, in _invoke_callbacks
    callback(self)
  File "/opt/conda/lib/python3.8/site-packages/nipype/pipeline/plugins/multiproc.py", line 159, in _async_callback
    result = args.result()
  File "/opt/conda/lib/python3.8/concurrent/futures/_base.py", line 437, in result
    return self.__get_result()
  File "/opt/conda/lib/python3.8/concurrent/futures/_base.py", line 389, in __get_result
    raise self._exception
  File "/opt/conda/lib/python3.8/concurrent/futures/_base.py", line 328, in _invoke_callbacks
    callback(self)
  File "/opt/conda/lib/python3.8/site-packages/nipype/pipeline/plugins/multiproc.py", line 159, in _async_callback
    result = args.result()
  File "/opt/conda/lib/python3.8/concurrent/futures/_base.py", line 437, in result
    return self.__get_result()
  File "/opt/conda/lib/python3.8/concurrent/futures/_base.py", line 389, in __get_result
    raise self._exception
  File "/opt/conda/lib/python3.8/concurrent/futures/_base.py", line 328, in _invoke_callbacks
    callback(self)
  File "/opt/conda/lib/python3.8/site-packages/nipype/pipeline/plugins/multiproc.py", line 159, in _async_callback
    result = args.result()
  File "/opt/conda/lib/python3.8/concurrent/futures/_base.py", line 437, in result
    return self.__get_result()
  File "/opt/conda/lib/python3.8/concurrent/futures/_base.py", line 389, in __get_result
    raise self._exception
  File "/opt/conda/lib/python3.8/concurrent/futures/_base.py", line 328, in _invoke_callbacks
    callback(self)
  File "/opt/conda/lib/python3.8/site-packages/nipype/pipeline/plugins/multiproc.py", line 159, in _async_callback
    result = args.result()
  File "/opt/conda/lib/python3.8/concurrent/futures/_base.py", line 437, in result
    return self.__get_result()
  File "/opt/conda/lib/python3.8/concurrent/futures/_base.py", line 389, in __get_result
    raise self._exception
  File "/opt/conda/lib/python3.8/concurrent/futures/_base.py", line 328, in _invoke_callbacks
    callback(self)
  File "/opt/conda/lib/python3.8/site-packages/nipype/pipeline/plugins/multiproc.py", line 159, in _async_callback
    result = args.result()
  File "/opt/conda/lib/python3.8/concurrent/futures/_base.py", line 437, in result
    return self.__get_result()
  File "/opt/conda/lib/python3.8/concurrent/futures/_base.py", line 389, in __get_result
    raise self._exception
concurrent.futures.process.BrokenProcessPool: A process in the process pool was terminated abruptly while the future was running or pending.
exception calling callback for <Future at 0x7fa01ceb44f0 state=finished raised BrokenProcessPool>
Traceback (most recent call last):
  File "/opt/conda/lib/python3.8/concurrent/futures/_base.py", line 328, in _invoke_callbacks
    callback(self)
  File "/opt/conda/lib/python3.8/site-packages/nipype/pipeline/plugins/multiproc.py", line 159, in _async_callback
    result = args.result()
  File "/opt/conda/lib/python3.8/concurrent/futures/_base.py", line 437, in result
    return self.__get_result()
  File "/opt/conda/lib/python3.8/concurrent/futures/_base.py", line 389, in __get_result
    raise self._exception
  File "/opt/conda/lib/python3.8/concurrent/futures/_base.py", line 328, in _invoke_callbacks
    callback(self)
  File "/opt/conda/lib/python3.8/site-packages/nipype/pipeline/plugins/multiproc.py", line 159, in _async_callback
    result = args.result()
  File "/opt/conda/lib/python3.8/concurrent/futures/_base.py", line 437, in result
    return self.__get_result()
  File "/opt/conda/lib/python3.8/concurrent/futures/_base.py", line 389, in __get_result
    raise self._exception
  File "/opt/conda/lib/python3.8/concurrent/futures/_base.py", line 328, in _invoke_callbacks
    callback(self)
  File "/opt/conda/lib/python3.8/site-packages/nipype/pipeline/plugins/multiproc.py", line 159, in _async_callback
    result = args.result()
  File "/opt/conda/lib/python3.8/concurrent/futures/_base.py", line 437, in result
    return self.__get_result()
  File "/opt/conda/lib/python3.8/concurrent/futures/_base.py", line 389, in __get_result
    raise self._exception
  File "/opt/conda/lib/python3.8/concurrent/futures/_base.py", line 328, in _invoke_callbacks
    callback(self)
  File "/opt/conda/lib/python3.8/site-packages/nipype/pipeline/plugins/multiproc.py", line 159, in _async_callback
    result = args.result()
  File "/opt/conda/lib/python3.8/concurrent/futures/_base.py", line 437, in result
    return self.__get_result()
  File "/opt/conda/lib/python3.8/concurrent/futures/_base.py", line 389, in __get_result
    raise self._exception
  File "/opt/conda/lib/python3.8/concurrent/futures/_base.py", line 328, in _invoke_callbacks
    callback(self)
  File "/opt/conda/lib/python3.8/site-packages/nipype/pipeline/plugins/multiproc.py", line 159, in _async_callback
    result = args.result()
  File "/opt/conda/lib/python3.8/concurrent/futures/_base.py", line 437, in result
    return self.__get_result()
  File "/opt/conda/lib/python3.8/concurrent/futures/_base.py", line 389, in __get_result
    raise self._exception
  File "/opt/conda/lib/python3.8/concurrent/futures/_base.py", line 328, in _invoke_callbacks
    callback(self)
  File "/opt/conda/lib/python3.8/site-packages/nipype/pipeline/plugins/multiproc.py", line 159, in _async_callback
    result = args.result()
  File "/opt/conda/lib/python3.8/concurrent/futures/_base.py", line 437, in result
    return self.__get_result()
  File "/opt/conda/lib/python3.8/concurrent/futures/_base.py", line 389, in __get_result
    raise self._exception
  File "/opt/conda/lib/python3.8/concurrent/futures/_base.py", line 328, in _invoke_callbacks
    callback(self)
  File "/opt/conda/lib/python3.8/site-packages/nipype/pipeline/plugins/multiproc.py", line 159, in _async_callback
    result = args.result()
  File "/opt/conda/lib/python3.8/concurrent/futures/_base.py", line 437, in result
    return self.__get_result()
  File "/opt/conda/lib/python3.8/concurrent/futures/_base.py", line 389, in __get_result
    raise self._exception
  File "/opt/conda/lib/python3.8/concurrent/futures/_base.py", line 328, in _invoke_callbacks
    callback(self)
  File "/opt/conda/lib/python3.8/site-packages/nipype/pipeline/plugins/multiproc.py", line 159, in _async_callback
    result = args.result()
  File "/opt/conda/lib/python3.8/concurrent/futures/_base.py", line 437, in result
    return self.__get_result()
  File "/opt/conda/lib/python3.8/concurrent/futures/_base.py", line 389, in __get_result
    raise self._exception
  File "/opt/conda/lib/python3.8/concurrent/futures/_base.py", line 328, in _invoke_callbacks
    callback(self)
  File "/opt/conda/lib/python3.8/site-packages/nipype/pipeline/plugins/multiproc.py", line 159, in _async_callback
    result = args.result()
  File "/opt/conda/lib/python3.8/concurrent/futures/_base.py", line 437, in result
    return self.__get_result()
  File "/opt/conda/lib/python3.8/concurrent/futures/_base.py", line 389, in __get_result
    raise self._exception
  File "/opt/conda/lib/python3.8/concurrent/futures/_base.py", line 328, in _invoke_callbacks
    callback(self)
  File "/opt/conda/lib/python3.8/site-packages/nipype/pipeline/plugins/multiproc.py", line 159, in _async_callback
    result = args.result()
  File "/opt/conda/lib/python3.8/concurrent/futures/_base.py", line 437, in result
    return self.__get_result()
  File "/opt/conda/lib/python3.8/concurrent/futures/_base.py", line 389, in __get_result
    raise self._exception
  File "/opt/conda/lib/python3.8/concurrent/futures/_base.py", line 328, in _invoke_callbacks
    callback(self)
  File "/opt/conda/lib/python3.8/site-packages/nipype/pipeline/plugins/multiproc.py", line 159, in _async_callback
    result = args.result()
  File "/opt/conda/lib/python3.8/concurrent/futures/_base.py", line 437, in result
    return self.__get_result()
  File "/opt/conda/lib/python3.8/concurrent/futures/_base.py", line 389, in __get_result
    raise self._exception
  File "/opt/conda/lib/python3.8/concurrent/futures/_base.py", line 328, in _invoke_callbacks
    callback(self)
  File "/opt/conda/lib/python3.8/site-packages/nipype/pipeline/plugins/multiproc.py", line 159, in _async_callback
    result = args.result()
  File "/opt/conda/lib/python3.8/concurrent/futures/_base.py", line 437, in result
    return self.__get_result()
  File "/opt/conda/lib/python3.8/concurrent/futures/_base.py", line 389, in __get_result
    raise self._exception
  File "/opt/conda/lib/python3.8/concurrent/futures/_base.py", line 328, in _invoke_callbacks
    callback(self)
  File "/opt/conda/lib/python3.8/site-packages/nipype/pipeline/plugins/multiproc.py", line 159, in _async_callback
    result = args.result()
  File "/opt/conda/lib/python3.8/concurrent/futures/_base.py", line 437, in result
    return self.__get_result()
  File "/opt/conda/lib/python3.8/concurrent/futures/_base.py", line 389, in __get_result
    raise self._exception
  File "/opt/conda/lib/python3.8/concurrent/futures/_base.py", line 328, in _invoke_callbacks
    callback(self)
  File "/opt/conda/lib/python3.8/site-packages/nipype/pipeline/plugins/multiproc.py", line 159, in _async_callback
    result = args.result()
  File "/opt/conda/lib/python3.8/concurrent/futures/_base.py", line 437, in result
    return self.__get_result()
  File "/opt/conda/lib/python3.8/concurrent/futures/_base.py", line 389, in __get_result
    raise self._exception
  File "/opt/conda/lib/python3.8/concurrent/futures/_base.py", line 328, in _invoke_callbacks
    callback(self)
  File "/opt/conda/lib/python3.8/site-packages/nipype/pipeline/plugins/multiproc.py", line 159, in _async_callback
    result = args.result()
  File "/opt/conda/lib/python3.8/concurrent/futures/_base.py", line 437, in result
    return self.__get_result()
  File "/opt/conda/lib/python3.8/concurrent/futures/_base.py", line 389, in __get_result
    raise self._exception
concurrent.futures.process.BrokenProcessPool: A process in the process pool was terminated abruptly while the future was running or pending.
exception calling callback for <Future at 0x7fa01ce8f220 state=finished raised BrokenProcessPool>
Traceback (most recent call last):
  File "/opt/conda/lib/python3.8/concurrent/futures/_base.py", line 328, in _invoke_callbacks
    callback(self)
  File "/opt/conda/lib/python3.8/site-packages/nipype/pipeline/plugins/multiproc.py", line 159, in _async_callback
    result = args.result()
  File "/opt/conda/lib/python3.8/concurrent/futures/_base.py", line 437, in result
    return self.__get_result()
  File "/opt/conda/lib/python3.8/concurrent/futures/_base.py", line 389, in __get_result
    raise self._exception
  File "/opt/conda/lib/python3.8/concurrent/futures/_base.py", line 328, in _invoke_callbacks
    callback(self)
  File "/opt/conda/lib/python3.8/site-packages/nipype/pipeline/plugins/multiproc.py", line 159, in _async_callback
    result = args.result()
  File "/opt/conda/lib/python3.8/concurrent/futures/_base.py", line 437, in result
    return self.__get_result()
  File "/opt/conda/lib/python3.8/concurrent/futures/_base.py", line 389, in __get_result
    raise self._exception
  File "/opt/conda/lib/python3.8/concurrent/futures/_base.py", line 328, in _invoke_callbacks
    callback(self)
  File "/opt/conda/lib/python3.8/site-packages/nipype/pipeline/plugins/multiproc.py", line 159, in _async_callback
    result = args.result()
  File "/opt/conda/lib/python3.8/concurrent/futures/_base.py", line 437, in result
    return self.__get_result()
  File "/opt/conda/lib/python3.8/concurrent/futures/_base.py", line 389, in __get_result
    raise self._exception
  File "/opt/conda/lib/python3.8/concurrent/futures/_base.py", line 328, in _invoke_callbacks
    callback(self)
  File "/opt/conda/lib/python3.8/site-packages/nipype/pipeline/plugins/multiproc.py", line 159, in _async_callback
    result = args.result()
  File "/opt/conda/lib/python3.8/concurrent/futures/_base.py", line 437, in result
    return self.__get_result()
  File "/opt/conda/lib/python3.8/concurrent/futures/_base.py", line 389, in __get_result
    raise self._exception
  File "/opt/conda/lib/python3.8/concurrent/futures/_base.py", line 328, in _invoke_callbacks
    callback(self)
  File "/opt/conda/lib/python3.8/site-packages/nipype/pipeline/plugins/multiproc.py", line 159, in _async_callback
    result = args.result()
  File "/opt/conda/lib/python3.8/concurrent/futures/_base.py", line 437, in result
    return self.__get_result()
  File "/opt/conda/lib/python3.8/concurrent/futures/_base.py", line 389, in __get_result
    raise self._exception
  File "/opt/conda/lib/python3.8/concurrent/futures/_base.py", line 328, in _invoke_callbacks
    callback(self)
  File "/opt/conda/lib/python3.8/site-packages/nipype/pipeline/plugins/multiproc.py", line 159, in _async_callback
    result = args.result()
  File "/opt/conda/lib/python3.8/concurrent/futures/_base.py", line 437, in result
    return self.__get_result()
  File "/opt/conda/lib/python3.8/concurrent/futures/_base.py", line 389, in __get_result
    raise self._exception
  File "/opt/conda/lib/python3.8/concurrent/futures/_base.py", line 328, in _invoke_callbacks
    callback(self)
  File "/opt/conda/lib/python3.8/site-packages/nipype/pipeline/plugins/multiproc.py", line 159, in _async_callback
    result = args.result()
  File "/opt/conda/lib/python3.8/concurrent/futures/_base.py", line 437, in result
    return self.__get_result()
  File "/opt/conda/lib/python3.8/concurrent/futures/_base.py", line 389, in __get_result
    raise self._exception
  File "/opt/conda/lib/python3.8/concurrent/futures/_base.py", line 328, in _invoke_callbacks
    callback(self)
  File "/opt/conda/lib/python3.8/site-packages/nipype/pipeline/plugins/multiproc.py", line 159, in _async_callback
    result = args.result()
  File "/opt/conda/lib/python3.8/concurrent/futures/_base.py", line 437, in result
    return self.__get_result()
  File "/opt/conda/lib/python3.8/concurrent/futures/_base.py", line 389, in __get_result
    raise self._exception
  File "/opt/conda/lib/python3.8/concurrent/futures/_base.py", line 328, in _invoke_callbacks
    callback(self)
  File "/opt/conda/lib/python3.8/site-packages/nipype/pipeline/plugins/multiproc.py", line 159, in _async_callback
    result = args.result()
  File "/opt/conda/lib/python3.8/concurrent/futures/_base.py", line 437, in result
    return self.__get_result()
  File "/opt/conda/lib/python3.8/concurrent/futures/_base.py", line 389, in __get_result
    raise self._exception
  File "/opt/conda/lib/python3.8/concurrent/futures/_base.py", line 328, in _invoke_callbacks
    callback(self)
  File "/opt/conda/lib/python3.8/site-packages/nipype/pipeline/plugins/multiproc.py", line 159, in _async_callback
    result = args.result()
  File "/opt/conda/lib/python3.8/concurrent/futures/_base.py", line 437, in result
    return self.__get_result()
  File "/opt/conda/lib/python3.8/concurrent/futures/_base.py", line 389, in __get_result
    raise self._exception
  File "/opt/conda/lib/python3.8/concurrent/futures/_base.py", line 328, in _invoke_callbacks
    callback(self)
  File "/opt/conda/lib/python3.8/site-packages/nipype/pipeline/plugins/multiproc.py", line 159, in _async_callback
    result = args.result()
  File "/opt/conda/lib/python3.8/concurrent/futures/_base.py", line 437, in result
    return self.__get_result()
  File "/opt/conda/lib/python3.8/concurrent/futures/_base.py", line 389, in __get_result
    raise self._exception
  File "/opt/conda/lib/python3.8/concurrent/futures/_base.py", line 328, in _invoke_callbacks
    callback(self)
  File "/opt/conda/lib/python3.8/site-packages/nipype/pipeline/plugins/multiproc.py", line 159, in _async_callback
    result = args.result()
  File "/opt/conda/lib/python3.8/concurrent/futures/_base.py", line 437, in result
    return self.__get_result()
  File "/opt/conda/lib/python3.8/concurrent/futures/_base.py", line 389, in __get_result
    raise self._exception
  File "/opt/conda/lib/python3.8/concurrent/futures/_base.py", line 328, in _invoke_callbacks
    callback(self)
  File "/opt/conda/lib/python3.8/site-packages/nipype/pipeline/plugins/multiproc.py", line 159, in _async_callback
    result = args.result()
  File "/opt/conda/lib/python3.8/concurrent/futures/_base.py", line 437, in result
    return self.__get_result()
  File "/opt/conda/lib/python3.8/concurrent/futures/_base.py", line 389, in __get_result
    raise self._exception
  File "/opt/conda/lib/python3.8/concurrent/futures/_base.py", line 328, in _invoke_callbacks
    callback(self)
  File "/opt/conda/lib/python3.8/site-packages/nipype/pipeline/plugins/multiproc.py", line 159, in _async_callback
    result = args.result()
  File "/opt/conda/lib/python3.8/concurrent/futures/_base.py", line 437, in result
    return self.__get_result()
  File "/opt/conda/lib/python3.8/concurrent/futures/_base.py", line 389, in __get_result
    raise self._exception
  File "/opt/conda/lib/python3.8/concurrent/futures/_base.py", line 328, in _invoke_callbacks
    callback(self)
  File "/opt/conda/lib/python3.8/site-packages/nipype/pipeline/plugins/multiproc.py", line 159, in _async_callback
    result = args.result()
  File "/opt/conda/lib/python3.8/concurrent/futures/_base.py", line 437, in result
    return self.__get_result()
  File "/opt/conda/lib/python3.8/concurrent/futures/_base.py", line 389, in __get_result
    raise self._exception
  File "/opt/conda/lib/python3.8/concurrent/futures/_base.py", line 328, in _invoke_callbacks
    callback(self)
  File "/opt/conda/lib/python3.8/site-packages/nipype/pipeline/plugins/multiproc.py", line 159, in _async_callback
    result = args.result()
  File "/opt/conda/lib/python3.8/concurrent/futures/_base.py", line 437, in result
    return self.__get_result()
  File "/opt/conda/lib/python3.8/concurrent/futures/_base.py", line 389, in __get_result
    raise self._exception
concurrent.futures.process.BrokenProcessPool: A process in the process pool was terminated abruptly while the future was running or pending.
exception calling callback for <Future at 0x7fa01ce24e50 state=finished raised BrokenProcessPool>
Traceback (most recent call last):
  File "/opt/conda/lib/python3.8/concurrent/futures/_base.py", line 328, in _invoke_callbacks
    callback(self)
  File "/opt/conda/lib/python3.8/site-packages/nipype/pipeline/plugins/multiproc.py", line 159, in _async_callback
    result = args.result()
  File "/opt/conda/lib/python3.8/concurrent/futures/_base.py", line 437, in result
    return self.__get_result()
  File "/opt/conda/lib/python3.8/concurrent/futures/_base.py", line 389, in __get_result
    raise self._exception
  File "/opt/conda/lib/python3.8/concurrent/futures/_base.py", line 328, in _invoke_callbacks
    callback(self)
  File "/opt/conda/lib/python3.8/site-packages/nipype/pipeline/plugins/multiproc.py", line 159, in _async_callback
    result = args.result()
  File "/opt/conda/lib/python3.8/concurrent/futures/_base.py", line 437, in result
    return self.__get_result()
  File "/opt/conda/lib/python3.8/concurrent/futures/_base.py", line 389, in __get_result
    raise self._exception
  File "/opt/conda/lib/python3.8/concurrent/futures/_base.py", line 328, in _invoke_callbacks
    callback(self)
  File "/opt/conda/lib/python3.8/site-packages/nipype/pipeline/plugins/multiproc.py", line 159, in _async_callback
    result = args.result()
  File "/opt/conda/lib/python3.8/concurrent/futures/_base.py", line 437, in result
    return self.__get_result()
  File "/opt/conda/lib/python3.8/concurrent/futures/_base.py", line 389, in __get_result
    raise self._exception
  File "/opt/conda/lib/python3.8/concurrent/futures/_base.py", line 328, in _invoke_callbacks
    callback(self)
  File "/opt/conda/lib/python3.8/site-packages/nipype/pipeline/plugins/multiproc.py", line 159, in _async_callback
    result = args.result()
  File "/opt/conda/lib/python3.8/concurrent/futures/_base.py", line 437, in result
    return self.__get_result()
  File "/opt/conda/lib/python3.8/concurrent/futures/_base.py", line 389, in __get_result
    raise self._exception
  File "/opt/conda/lib/python3.8/concurrent/futures/_base.py", line 328, in _invoke_callbacks
    callback(self)
  File "/opt/conda/lib/python3.8/site-packages/nipype/pipeline/plugins/multiproc.py", line 159, in _async_callback
    result = args.result()
  File "/opt/conda/lib/python3.8/concurrent/futures/_base.py", line 437, in result
    return self.__get_result()
  File "/opt/conda/lib/python3.8/concurrent/futures/_base.py", line 389, in __get_result
    raise self._exception
  File "/opt/conda/lib/python3.8/concurrent/futures/_base.py", line 328, in _invoke_callbacks
    callback(self)
  File "/opt/conda/lib/python3.8/site-packages/nipype/pipeline/plugins/multiproc.py", line 159, in _async_callback
    result = args.result()
  File "/opt/conda/lib/python3.8/concurrent/futures/_base.py", line 437, in result
    return self.__get_result()
  File "/opt/conda/lib/python3.8/concurrent/futures/_base.py", line 389, in __get_result
    raise self._exception
  File "/opt/conda/lib/python3.8/concurrent/futures/_base.py", line 328, in _invoke_callbacks
    callback(self)
  File "/opt/conda/lib/python3.8/site-packages/nipype/pipeline/plugins/multiproc.py", line 159, in _async_callback
    result = args.result()
  File "/opt/conda/lib/python3.8/concurrent/futures/_base.py", line 437, in result
    return self.__get_result()
  File "/opt/conda/lib/python3.8/concurrent/futures/_base.py", line 389, in __get_result
    raise self._exception
  File "/opt/conda/lib/python3.8/concurrent/futures/_base.py", line 328, in _invoke_callbacks
    callback(self)
  File "/opt/conda/lib/python3.8/site-packages/nipype/pipeline/plugins/multiproc.py", line 159, in _async_callback
    result = args.result()
  File "/opt/conda/lib/python3.8/concurrent/futures/_base.py", line 437, in result
    return self.__get_result()
  File "/opt/conda/lib/python3.8/concurrent/futures/_base.py", line 389, in __get_result
    raise self._exception
  File "/opt/conda/lib/python3.8/concurrent/futures/_base.py", line 328, in _invoke_callbacks
    callback(self)
  File "/opt/conda/lib/python3.8/site-packages/nipype/pipeline/plugins/multiproc.py", line 159, in _async_callback
    result = args.result()
  File "/opt/conda/lib/python3.8/concurrent/futures/_base.py", line 437, in result
    return self.__get_result()
  File "/opt/conda/lib/python3.8/concurrent/futures/_base.py", line 389, in __get_result
    raise self._exception
  File "/opt/conda/lib/python3.8/concurrent/futures/_base.py", line 328, in _invoke_callbacks
    callback(self)
  File "/opt/conda/lib/python3.8/site-packages/nipype/pipeline/plugins/multiproc.py", line 159, in _async_callback
    result = args.result()
  File "/opt/conda/lib/python3.8/concurrent/futures/_base.py", line 437, in result
    return self.__get_result()
  File "/opt/conda/lib/python3.8/concurrent/futures/_base.py", line 389, in __get_result
    raise self._exception
  File "/opt/conda/lib/python3.8/concurrent/futures/_base.py", line 328, in _invoke_callbacks
    callback(self)
  File "/opt/conda/lib/python3.8/site-packages/nipype/pipeline/plugins/multiproc.py", line 159, in _async_callback
    result = args.result()
  File "/opt/conda/lib/python3.8/concurrent/futures/_base.py", line 437, in result
    return self.__get_result()
  File "/opt/conda/lib/python3.8/concurrent/futures/_base.py", line 389, in __get_result
    raise self._exception
  File "/opt/conda/lib/python3.8/concurrent/futures/_base.py", line 328, in _invoke_callbacks
    callback(self)
  File "/opt/conda/lib/python3.8/site-packages/nipype/pipeline/plugins/multiproc.py", line 159, in _async_callback
    result = args.result()
  File "/opt/conda/lib/python3.8/concurrent/futures/_base.py", line 437, in result
    return self.__get_result()
  File "/opt/conda/lib/python3.8/concurrent/futures/_base.py", line 389, in __get_result
    raise self._exception
  File "/opt/conda/lib/python3.8/concurrent/futures/_base.py", line 328, in _invoke_callbacks
    callback(self)
  File "/opt/conda/lib/python3.8/site-packages/nipype/pipeline/plugins/multiproc.py", line 159, in _async_callback
    result = args.result()
  File "/opt/conda/lib/python3.8/concurrent/futures/_base.py", line 437, in result
    return self.__get_result()
  File "/opt/conda/lib/python3.8/concurrent/futures/_base.py", line 389, in __get_result
    raise self._exception
  File "/opt/conda/lib/python3.8/concurrent/futures/_base.py", line 328, in _invoke_callbacks
    callback(self)
  File "/opt/conda/lib/python3.8/site-packages/nipype/pipeline/plugins/multiproc.py", line 159, in _async_callback
    result = args.result()
  File "/opt/conda/lib/python3.8/concurrent/futures/_base.py", line 437, in result
    return self.__get_result()
  File "/opt/conda/lib/python3.8/concurrent/futures/_base.py", line 389, in __get_result
    raise self._exception
  File "/opt/conda/lib/python3.8/concurrent/futures/_base.py", line 328, in _invoke_callbacks
    callback(self)
  File "/opt/conda/lib/python3.8/site-packages/nipype/pipeline/plugins/multiproc.py", line 159, in _async_callback
    result = args.result()
  File "/opt/conda/lib/python3.8/concurrent/futures/_base.py", line 437, in result
    return self.__get_result()
  File "/opt/conda/lib/python3.8/concurrent/futures/_base.py", line 389, in __get_result
    raise self._exception
  File "/opt/conda/lib/python3.8/concurrent/futures/_base.py", line 328, in _invoke_callbacks
    callback(self)
  File "/opt/conda/lib/python3.8/site-packages/nipype/pipeline/plugins/multiproc.py", line 159, in _async_callback
    result = args.result()
  File "/opt/conda/lib/python3.8/concurrent/futures/_base.py", line 437, in result
    return self.__get_result()
  File "/opt/conda/lib/python3.8/concurrent/futures/_base.py", line 389, in __get_result
    raise self._exception
  File "/opt/conda/lib/python3.8/concurrent/futures/_base.py", line 328, in _invoke_callbacks
    callback(self)
  File "/opt/conda/lib/python3.8/site-packages/nipype/pipeline/plugins/multiproc.py", line 159, in _async_callback
    result = args.result()
  File "/opt/conda/lib/python3.8/concurrent/futures/_base.py", line 437, in result
    return self.__get_result()
  File "/opt/conda/lib/python3.8/concurrent/futures/_base.py", line 389, in __get_result
    raise self._exception
concurrent.futures.process.BrokenProcessPool: A process in the process pool was terminated abruptly while the future was running or pending.
221125-15:11:49,260 nipype.workflow CRITICAL:
	 fMRIPrep failed: A child process terminated abruptly, the process pool is not usable anymore
